Workbook

Sheet raw_co2_excLUC
A1: year | B1: annex2_OWID | C1: annex1_OWID | D1: nona1_OWID | E1: annex2_PRIMAP | F1: annex1_PRIMAP | G1: nona1_PRIMAP | H1: annex2_GCP_fossil | I1: annex1_GCP_fossil | J1: nona1_GCP_fossil | K1: annex2_GCP_BLUE | L1: annex1_GCP_BLUE | M1: nona1_GCP_BLUE | N1: annex2_GCP_OSCAR | O1: annex1_GCP_OSCAR | P1: nona1_GCP_OSCAR | Q1: annex2_GCP_LUCE | R1: annex1_GCP_LUCE | S1: nona1_GCP_LUCE | T1: annex2_EDGAR | U1: annex1_EDGAR | V1: nona1_EDGAR | W1: annex2_ClimateWatch | X1: annex1_ClimateWatch | Y1: nona1_ClimateWatch
A2: 1750 | B2: 9.306 | C2: 9.306 | D2: 0 | E2: 0.337 | F2: 0.337 | G2: 0.005
A3: 1751 | B3: 9.407 | C3: 9.407 | D3: 0 | E3: 9.471 | F3: 9.471 | G3: 0.005
A4: 1752 | B4: 9.505 | C4: 9.505 | D4: 0 | E4: 9.475 | F4: 9.475 | G4: 0.005
A5: 1753 | B5: 9.61 | C5: 9.61 | D5: 0 | E5: 9.475 | F5: 9.475 | G5: 0.005
A6: 1754 | B6: 9.734 | C6: 9.734 | D6: 0 | E6: 9.479 | F6: 9.479 | G6: 0.005
A7: 1755 | B7: 9.793 | C7: 9.793 | D7: 0 | E7: 9.483 | F7: 9.483 | G7: 0.005
A8: 1756 | B8: 9.91 | C8: 9.91 | D8: 0 | E8: 10.133 | F8: 10.133 | G8: 0.005
A9: 1757 | B9: 10.094 | C9: 10.094 | D9: 0 | E9: 10.137 | F9: 10.137 | G9: 0.005
A10: 1758 | B10: 10.216 | C10: 10.216 | D10: 0 | E10: 10.141 | F10: 10.141 | G10: 0.005
A11: 1759 | B11: 10.339 | C11: 10.339 | D11: 0 | E11: 10.145 | F11: 10.145 | G11: 0.005
A12: 1760 | B12: 10.514 | C12: 10.514 | D12: 0 | E12: 10.145 | F12: 10.145 | G12: 0.005
A13: 1761 | B13: 10.748 | C13: 10.748 | D13: 0 | E13: 11.109 | F13: 11.109 | G13: 0.005
... A101: 1849 | B101: 181.928 | C101: 184.932 | D101: 0.116 | E101: 186.668 | F101: 189.83 | G101: 0.039
A102: 1850 | B102: 193.438 | C102: 196.738 | D102: 0.11 | E102: 200.258 | F102: 203.641 | G102: 0.043 | H102: 193.438 | I102: 196.738 | J102: 0.11
A103: 1851 | B103: 194.934 | C103: 198.668 | D103: 0.11 | E103: 202.587 | F103: 206.493 | G103: 0.045 | H103: 194.934 | I103: 198.668 | J103: 0.11
A104: 1852 | B104: 202.94 | C104: 207.414 | D104: 0.181 | E104: 211.279 | F104: 215.97 | G104: 0.051 | H104: 202.94 | I104: 207.414 | J104: 0.181
A105: 1853 | B105: 212.46 | C105: 217.12 | D105: 0.117 | E105: 221.481 | F105: 226.41 | G105: 0.06 | H105: 212.46 | I105: 217.12 | J105: 0.117
A106: 1854 | B106: 249.819 | C106: 255.033 | D106: 0.005 | E106: 260.357 | F106: 265.89 | G106: 0.071 | H106: 249.819 | I106: 255.033 | J106: 0.005
A107: 1855 | B107: 253.69 | C107: 260.061 | D107: 0.199 | E107: 264.881 | F107: 271.364 | G107: 0.08 | H107: 253.69 | I107: 260.061 | J107: 0.199
A108: 1856 | B108: 270.503 | C108: 277.296 | D108: 0.949 | E108: 282.54 | F108: 289.769 | G108: 0.087 | H108: 270.503 | I108: 277.296 | J108: 0.949
A109: 1857 | B109: 272.67 | C109: 279.932 | D109: 1.249 | E109: 285.185 | F109: 292.927 | G109: 0.094 | H109: 272.67 | I109: 279.932 | J109: 1.249
A110: 1858 | B110: 275.263 | C110: 283.77 | D110: 1.779 | E110: 288.359 | F110: 297.039 | G110: 0.525 | H110: 275.263 | I110: 283.77 | J110: 1.779
A111: 1859 | B111: 292.454 | C111: 300.78 | D111: 1.792 | E111: 305.761 | F111: 314.214 | G111: 0.79 | H111: 292.454 | I111: 300.78 | J111: 1.792
A112: 1860 | B112: 320.98 | C112: 330.225 | D112: 2.073 | E112: 335.122 | F112: 344.525 | G112: 0.825 | H112: 320.98 | I112: 330.225 | J112: 2.073
A113: 1861 | B113: 336.912 | C113: 347.169 | D113: 2.022 | E113: 352.731 | F113: 363.216 | G113: 0.699 | H113: 336.912 | I113: 347.169 | J113: 2.022
... A221: 1969 | B221: 8240.805 | C221: 10937.124 | D221: 2412.172 | E221: 8855.033 | F221: 11918.591 | G221: 2693.091 | H221: 8240.805 | I221: 10937.124 | J221: 2412.04
A222: 1970 | B222: 8822.985 | C222: 11675.703 | D222: 2788.864 | E222: 9418.856 | F222: 12641.286 | G222: 3106.626 | H222: 8822.985 | I222: 11675.703 | J222: 2788.659 | T222: 9355.11 | U222: 12119.234 | V222: 3107.749
A223: 1971 | B223: 8964.181 | C223: 11974.58 | D223: 3070.225 | E223: 9534.476 | F223: 12880.087 | G223: 3380.548 | H223: 8964.181 | I223: 11974.58 | J223: 3069.976 | T223: 9223.236 | U223: 12003.829 | V223: 3154.984
A224: 1972 | B224: 9356.378 | C224: 12511.488 | D224: 3223.373 | E224: 9953.949 | F224: 13471.792 | G224: 3532.251 | H224: 9356.378 | I224: 12511.488 | J224: 3223.116 | T224: 9656.431 | U224: 12570.457 | V224: 3358.119
A225: 1973 | B225: 9790.086 | C225: 13076.36 | D225: 3477.151 | E225: 10428.007 | F225: 14095.019 | G225: 3791.261 | H225: 9790.086 | I225: 13076.36 | J225: 3476.905 | T225: 10171.718 | U225: 13253.684 | V225: 3628.71
A226: 1974 | B226: 9531.698 | C226: 12931.427 | D226: 3580.11 | E226: 10127.853 | F226: 13882.817 | G226: 3890.522 | H226: 9531.698 | I226: 12931.428 | J226: 3579.792 | T226: 9897.556 | U226: 13096.399 | V226: 3755.226
A227: 1975 | B227: 9162.324 | C227: 12745.973 | D227: 3797.467 | E227: 9672.868 | F227: 13600.438 | G227: 4110.669 | H227: 9162.324 | I227: 12745.973 | J227: 3797.137 | T227: 9464.107 | U227: 12833.872 | V227: 3978.222
A228: 1976 | B228: 9630.535 | C228: 13372.009 | D228: 4054.327 | E228: 10199.027 | F228: 14295.599 | G228: 4350.27 | H228: 9630.535 | I228: 13372.009 | J228: 4054.089 | T228: 10029.513 | U228: 13543.544 | V228: 4245.248
A229: 1977 | B229: 9735.972 | C229: 13612.131 | D229: 4299.796 | E229: 10281.288 | F229: 14501.748 | G229: 4586.226 | H229: 9735.972 | I229: 13612.132 | J229: 4299.522 | T229: 10190.61 | U229: 13810.288 | V229: 4517.321
A230: 1978 | B230: 9951.562 | C230: 13962.568 | D230: 4608.953 | E230: 10528.059 | F230: 14887.385 | G230: 4876.45 | H230: 9951.562 | I230: 13962.568 | J230: 4608.751 | T230: 10256.908 | U230: 14102.87 | V230: 4825.512
A231: 1979 | B231: 10184.583 | C231: 14222.119 | D231: 4831.613 | E231: 10793.317 | F231: 15190.695 | G231: 5105.354 | H231: 10184.583 | I231: 14222.119 | J231: 4831.39 | T231: 10495.479 | U231: 14400.572 | V231: 5049.22
A232: 1980 | B232: 9880.075 | C232: 14055.347 | D232: 4910.131 | E232: 10426.483 | F232: 14950.561 | G232: 5157.337 | H232: 9880.075 | I232: 14055.347 | J232: 4909.874 | T232: 10099.422 | U232: 14102.256 | V232: 5110.34
A233: 1981 | B233: 9488.013 | C233: 13559.878 | D233: 4909.71 | E233: 10031.494 | F233: 14438.317 | G233: 5178.885 | H233: 9488.012 | I233: 13559.878 | J233: 4909.45 | T233: 9826.948 | U233: 13773.478 | V233: 5094.365
... A241: 1989 | B241: 10056.172 | C241: 14556.763 | D241: 7079.498 | E241: 10583.755 | F241: 15407.316 | G241: 7398.466 | H241: 10056.172 | I241: 14556.763 | J241: 7079.264 | T241: 10346.592 | U241: 14748.978 | V241: 6965.191
...

Sheet raw_co2_incLUC
A1: year | B1: annex2_OWID | C1: annex1_OWID | D1: nona1_OWID | E1: annex2_PRIMAP | F1: annex1_PRIMAP | G1: nona1_PRIMAP | H1: annex2_GCP_fossil | I1: annex1_GCP_fossil | J1: nona1_GCP_fossil | K1: annex2_GCP_BLUE | L1: annex1_GCP_BLUE | M1: nona1_GCP_BLUE | N1: annex2_GCP_OSCAR | O1: annex1_GCP_OSCAR | P1: nona1_GCP_OSCAR | Q1: annex2_GCP_LUCE | R1: annex1_GCP_LUCE | S1: nona1_GCP_LUCE | T1: annex2_EDGAR | U1: annex1_EDGAR | V1: nona1_EDGAR | W1: annex2_ClimateWatch | X1: annex1_ClimateWatch | Y1: nona1_ClimateWatch
A2: 1750 | B2: 9.306 | C2: 9.306 | D2: 0 | E2: 0.337 | F2: 0.337 | G2: 0.005
A3: 1751 | B3: 9.407 | C3: 9.407 | D3: 0 | E3: 18.817 | F3: 22.042 | G3: 7.477
A4: 1752 | B4: 9.505 | C4: 9.505 | D4: 0 | E4: 28.167 | F4: 34.616 | G4: 14.95
A5: 1753 | B5: 9.61 | C5: 9.61 | D5: 0 | E5: 37.514 | F5: 47.187 | G5: 22.423
A6: 1754 | B6: 9.734 | C6: 9.734 | D6: 0 | E6: 46.864 | F6: 59.762 | G6: 29.895
A7: 1755 | B7: 9.793 | C7: 9.793 | D7: 0 | E7: 56.214 | F7: 72.336 | G7: 37.368
A8: 1756 | B8: 9.91 | C8: 9.91 | D8: 0 | E8: 66.211 | F8: 85.557 | G8: 44.84
A9: 1757 | B9: 10.094 | C9: 10.094 | D9: 0 | E9: 75.561 | F9: 98.132 | G9: 52.313
A10: 1758 | B10: 10.216 | C10: 10.216 | D10: 0 | E10: 84.911 | F10: 110.706 | G10: 59.786
A11: 1759 | B11: 10.339 | C11: 10.339 | D11: 0 | E11: 94.262 | F11: 123.281 | G11: 67.258
A12: 1760 | B12: 10.514 | C12: 10.514 | D12: 0 | E12: 103.608 | F12: 135.852 | G12: 74.731
A13: 1761 | B13: 10.748 | C13: 10.748 | D13: 0 | E13: 113.918 | F13: 149.387 | G13: 82.204
... A101: 1849 | B101: 181.928 | C101: 184.932 | D101: 0.116 | E101: 1111.952 | F101: 1434.324 | G101: 739.827
A102: 1850 | B102: 1290.936 | C102: 2094.882 | D102: 1537.861 | E102: 891.93 | F102: 1211.493 | G102: 823.429 | K102: 1290.936 | L102: 2094.882 | M102: 1537.861 | N102: 1053.273 | O102: 1399.061 | P102: 945.557 | Q102: 1082.766 | R102: 1667.537 | S102: 1085.541
A103: 1851 | B103: 1347.784 | C103: 2157.601 | D103: 1626.338 | E103: 899.51 | F103: 1219.531 | G103: 789.239 | K103: 1347.784 | L103: 2157.601 | M103: 1626.338 | N103: 1086.404 | O103: 1423.289 | P103: 980.535 | Q103: 1130.623 | R103: 1715.913 | S103: 1152.666
A104: 1852 | B104: 1380.203 | C104: 2230.345 | D104: 1683.59 | E104: 1146.19 | F104: 1468.051 | G104: 754.79 | K104: 1380.203 | L104: 2230.345 | M104: 1683.59 | N104: 1103.114 | O104: 1471.461 | P104: 1004.504 | Q104: 1160.199 | R104: 1785.526 | S104: 1197.063
A105: 1853 | B105: 1433.029 | C105: 2259.173 | D105: 1710.368 | E105: 1184.999 | F105: 1508.209 | G105: 718.593 | K105: 1433.029 | L105: 2259.173 | M105: 1710.368 | N105: 1143.791 | O105: 1481.32 | P105: 1002.07 | Q105: 1206.795 | R105: 1807.514 | S105: 1195.314
A106: 1854 | B106: 1499.014 | C106: 2352.142 | D106: 1705.869 | E106: 1251.85 | F106: 1576.832 | G106: 681.931 | K106: 1499.014 | L106: 2352.142 | M106: 1705.869 | N106: 1200.051 | O106: 1558.938 | P106: 1006.056 | Q106: 1268.359 | R106: 1895.974 | S106: 1170.146
A107: 1855 | B107: 1518.949 | C107: 2377.324 | D107: 1754.3 | E107: 1283.286 | F107: 1610.443 | G107: 643.801 | K107: 1518.949 | L107: 2377.324 | M107: 1754.3 | N107: 1212.195 | O107: 1571.616 | P107: 1020.76 | Q107: 1283.658 | R107: 1917.454 | S107: 1219.917
A108: 1856 | B108: 1546.951 | C108: 2411.286 | D108: 1762.129 | E108: 1326.327 | F108: 1655.482 | G108: 637.612 | K108: 1546.95 | L108: 2411.286 | M108: 1762.129 | N108: 1234.154 | O108: 1595.778 | P108: 1034.424 | Q108: 1308.492 | R108: 1951.07 | S108: 1208.561
A109: 1857 | B109: 1571.184 | C109: 2446.174 | D109: 1776.948 | E109: 1353.469 | F109: 1684.382 | G109: 632.513 | K109: 1571.184 | L109: 2446.174 | M109: 1776.948 | N109: 1253.733 | O109: 1622.81 | P109: 1054.564 | Q109: 1330.442 | R109: 1986.576 | S109: 1227.966
A110: 1858 | B110: 1600.233 | C110: 2476.819 | D110: 1775.571 | E110: 1379.76 | F110: 1712.848 | G110: 628.012 | K110: 1600.233 | L110: 2476.819 | M110: 1775.571 | N110: 1279.577 | O110: 1647.578 | P110: 1043.049 | Q110: 1358.016 | R110: 2018.727 | S110: 1228.508
A111: 1859 | B111: 1645.326 | C111: 2527.726 | D111: 1787.971 | E111: 1419.536 | F111: 1753.622 | G111: 624.224 | K111: 1645.326 | L111: 2527.726 | M111: 1787.971 | N111: 1322.812 | O111: 1694.498 | P111: 1049.738 | Q111: 1402.238 | R111: 2071.874 | S111: 1239.755
A112: 1860 | B112: 1582.327 | C112: 2419.76 | D112: 1497.178 | E112: 1470.527 | F112: 1806.778 | G112: 619.519 | K112: 1582.327 | L112: 2419.761 | M112: 1497.178 | N112: 1362.587 | O112: 1713.343 | P112: 1027.021 | Q112: 1331.795 | R112: 1969.532 | S112: 1053.759
A113: 1861 | B113: 1522.367 | C113: 2358.99 | D113: 1386.92 | E113: 1506.66 | F113: 1858.106 | G113: 625.604 | K113: 1522.367 | L113: 2358.99 | M113: 1386.92 | N113: 1322.922 | O113: 1678 | P113: 989.235 | Q113: 1279.825 | R113: 1920.965 | S113: 1008.568
... A241: 1989 | B241: 10485.145 | C241: 15365.202 | D241: 12905.727 | E241: 10553.686 | F241: 15425.792 | G241: 13335.348 | K241: 10485.145 | L241: 15365.202 | M241: 12905.492 | N241: 10301.276 | O241: 14914.56 | P241: 12256.137 | Q241: 10671.631 | R241: 15785.907 | S241: 11557.949
A242: 1990 | B242: 10981.573 | C242: 15927.812 | D242: 12594.893 | E242: 9397.622 | F242: 12959.11 | G242: 10170.048 | K242: 10981.573 | L242: 15927.812 | M242: 12594.648 | N242: 10789.064 | O242: 15453.284 | P242: 12198.921 | Q242: 11238.538 | R242: 16421.628 | S242: 11371.203 | T242: 9885.763 | U242: 13180.699 | V242: 9248.037 | W242: 8943.763 | X242: 12002.762 | Y242: 10506.991
A243: 1991 | B243: 10858.024 | C243: 15504.479 | D243: 13220.904 | E243: 9250.839 | F243: 12303.793 | G243: 10904.05 | K243: 10858.024 | L243: 15504.48 | M243: 12742.731 | N243: 10781.518 | O243: 15162.603 | P243: 12450.308 | Q243: 11179.098 | R243: 16081.83 | S243: 11710.441 | T243: 9771.094 | U243: 12960.663 | V243: 9563.849 | W243: 8961.491 | X243: 11879.74 | Y243: 10768.137
A244: 1992 | B244: 10956.936 | C244: 14925.174 | D244: 13536.34 | E244: 9266.222 | F244: 11713.015 | G244: 10950.7 | K244: 10956.936 | L244: 14925.173 | M244: 13536.326 | N244: 10822.409 | O244: 14648.13 | P244: 12777.706 | Q244: 11164.067 | R244: 15352.724 | S244: 12508.956 | T244: 9778.27 | U244: 12569.541 | V244: 9917.897 | W244: 9002.721 | X244: 11574.175 | Y244: 10974.221
A245: 1993 | B245: 10995.789 | C245: 14710.124 | D245: 13640.2 | E245: 9281.247 | F245: 11374.438 | G245: 11316.329 | K245: 10995.79 | L245: 14710.125 | M245: 13640.185 | N245: 10855.551 | O245: 14421.8 | P245: 13212.008 | Q245: 11132.562 | R245: 15082.481 | S245: 12665.693 | T245: 10217.572 | U245: 12497.234 | V245: 10412.322 | W245: 9054.071 | X245: 11369.408 | Y245: 11316.841
A246: 1994 | B246: 11168.339 | C246: 14494.375 | D246: 15300.683 | E246: 9428.132 | F246: 10972.144 | G246: 9316.495 | K246: 11168.339 | L246: 14494.375 | M246: 15300.669 | N246: 10995.644 | O246: 14179.436 | P246: 13995.554 | Q246: 11211.177 | R246: 14734.988 | S246: 14429.866 | T246: 10195.432 | U246: 12329.625 | V246: 10718.128 | W246: 9205.915 | X246: 11207.747 | Y246: 11595.774
A247: 1995 | B247: 11407.597 | C247: 14570.962 | D247: 15278.038 | E247: 9572.407 | F247: 10976.775 | G247: 10351.936 | K247: 11407.597 | L247: 14570.962 | M247: 15278.034 | N247: 11153.099 | O247: 14259.955 | P247: 14467.625 | Q247: 11355.15 | R247: 14750.8 | S247: 14172.923 | T247: 10381.851 | U247: 12502.533 | V247: 11423.029 | W247: 9328.191 | X247: 11275.523 | Y247: 12119.438
A248: 1996 | B248: 11706.003 | C248: 15255.588 | D248: 15480.728 | E248: 9797.502 | F248: 11422.411 | G248: 10071.846 | K248: 11706.003 | L248: 15255.588 | M248: 15480.724 | N248: 11462.053 | O248: 14845.733 | P248: 14852.705 | Q248: 11657.725 | R248: 15446.263 | S248: 14399.246 | T248: 10285.813 | U248: 12178.822 | V248: 11595.697 | W248: 9616.542 | X248: 11521.385 | Y248: 12203.966
A249: 1997 | B249: 11658.313 | C249: 14660.718 | D249: 17669.135 | E249: 9841.358 | F249: 11082.128 | G249: 9906.036 | K249: 11658.314 | L249: 14660.718 | M249: 17669.131 | N249: 11423.117 | O249: 14368.463 | P249: 16944.629 | Q249: 11591.508 | R249: 14808.377 | S249: 16608.513 | T249: 10383.617 | U249: 12028.672 | V249: 11506.026 | W249: 9833.729 | X249: 11591.062 | Y249: 13203.422
A250: 1998 | B250: 11848.843 | C250: 14813.4 | D250: 16396.271 | E250: 9890.472 | F250: 11336.443 | G250: 10133.646 | K250: 11848.843 | L250: 14813.401 | M250: 16396.268 | N250: 11512.926 | O250: 14433.524 | P250: 15161.127 | Q250: 11723.873 | R250: 14876.336 | S250: 15319.905 | T250: 10943.612 | U250: 12160.59 | V250: 12403.598 | W250: 9911.352 | X250: 11597.17 | Y250: 12760.15
A251: 1999 | B251: 11942.659 | C251: 14870.102 | D251: 16502.556 | E251: 10058.393 | F251: 11078.224 | G251: 10405.805 | K251: 11942.66 | L251: 14870.102 | M251: 16502.553 | N251: 11643.313 | O251: 14538.201 | P251: 15730.087 | Q251: 11813.824 | R251: 14931.415 | S251: 15284.225 | T251: 10939.378 | U251: 12584.115 | V251: 12558.882 | W251: 9969.176 | X251: 11643.959 | Y251: 12732.144
A252: 2000 | B252: 12319.548 | C252: 15096.38 | D252: 16497.562 | E252: 10382.907 | F252: 11508.969 | G252: 10100.652 | K252: 12319.548 | L252: 15096.38 | M252: 16497.559 | N252: 12015.544 | O252: 14833.565 | P252: 15790.503 | Q252: 12137.601 | R252: 15106.065 | S252: 15265.676 | T252: 11468.819 | U252: 13431.88 | V252: 13410.22 | W252: 10196.715 | X252: 11917.983 | Y252: 13077.561
A253: 2001 | B253: 12037.284 | C253: 14813.49 | D253: 16043.732 | E253: 10259.415 | F253: 11346.347 | G253: 10453.655 | K253: 12037.284 | L253: 14813.49 | M253: 16043.729 | N253: 11922.31 | O253: 14778.803 | P253: 15691.511 | Q253: 11822.851 | R253: 14849.128 | S253: 14884.197 | T253: 11359.529 | U253: 12887.646 | V253: 13838.169 | W253: 10301.424 | X253: 11847.31 | Y253: 11684.766
... A275: 2023 | B275: 9434.886 | C275: 12768.114 | D275: 29531.821 | E275: 7840.368 | F275: 9384.297 | G275: 25061.781 | K275: 9434.886 | L275: 12768.114 | M275: 29531.821 | N275: 9170.793 | O275: 12313.034 | P275: 29136.108 | Q275: 9582.806 | R275: 13287.958 | S275: 28272.627 | T275: 9195.01 | U275: 10630.899 | V275: 28491.461 | W275: 8381.995 | X275: 10126.852 | Y275: 25077.419
...

Sheet raw_ghg_excLUC
A1: year | B1: annex2_OWID | C1: annex1_OWID | D1: nona1_OWID | E1: annex2_PRIMAP | F1: annex1_PRIMAP | G1: nona1_PRIMAP | H1: annex2_GCP_fossil | I1: annex1_GCP_fossil | J1: nona1_GCP_fossil | K1: annex2_GCP_BLUE | L1: annex1_GCP_BLUE | M1: nona1_GCP_BLUE | N1: annex2_GCP_OSCAR | O1: annex1_GCP_OSCAR | P1: nona1_GCP_OSCAR | Q1: annex2_GCP_LUCE | R1: annex1_GCP_LUCE | S1: nona1_GCP_LUCE | T1: annex2_EDGAR | U1: annex1_EDGAR | V1: nona1_EDGAR | W1: annex2_ClimateWatch | X1: annex1_ClimateWatch | Y1: nona1_ClimateWatch
A2: 1750 | E2: 160.02 | F2: 265.9 | G2: 517.951
A3: 1751 | E3: 169.908 | F3: 276.301 | G3: 519.233
A4: 1752 | E4: 170.64 | F4: 277.546 | G4: 520.515
A5: 1753 | E5: 171.365 | F5: 278.785 | G5: 521.797
A6: 1754 | E6: 172.094 | F6: 280.027 | G6: 523.079
A7: 1755 | E7: 172.822 | F7: 281.267 | G7: 524.36
A8: 1756 | E8: 174.313 | F8: 283.272 | G8: 525.642
A9: 1757 | E9: 175.039 | F9: 284.511 | G9: 526.924
A10: 1758 | E10: 175.763 | F10: 285.748 | G10: 528.205
A11: 1759 | E11: 176.486 | F11: 286.984 | G11: 529.486
A12: 1760 | E12: 177.204 | F12: 288.215 | G12: 530.768
A13: 1761 | E13: 179.103 | F13: 290.652 | G13: 531.822
... A101: 1849 | E101: 586.658 | F101: 779.899 | G101: 752.725
A102: 1850 | B102: 375.324 | C102: 451.719 | D102: 230.605 | E102: 608.538 | F102: 805.61 | G102: 757.79
A103: 1851 | B103: 377.222 | C103: 454.879 | D103: 230.577 | E103: 614.065 | F103: 813.995 | G103: 759.213
A104: 1852 | B104: 387.491 | C104: 466.759 | D104: 230.704 | E104: 627.68 | F104: 830.761 | G104: 760.709
A105: 1853 | B105: 400.152 | C105: 480.441 | D105: 230.707 | E105: 643.593 | F105: 849.23 | G105: 762.197
A106: 1854 | B106: 445.605 | C106: 527.311 | D106: 230.666 | E106: 692.777 | F106: 901.346 | G106: 763.664
A107: 1855 | B107: 451.437 | C107: 535.244 | D107: 230.934 | E107: 701.781 | F107: 913.68 | G107: 765.098
A108: 1856 | B108: 472.505 | C108: 557.571 | D108: 231.735 | E108: 725.99 | F108: 940.886 | G108: 766.465
A109: 1857 | B109: 476.111 | C109: 562.515 | D109: 232.112 | E109: 732.441 | F109: 950.099 | G109: 767.81
A110: 1858 | B110: 479.735 | C110: 568.363 | D110: 232.806 | E110: 738.925 | F110: 959.834 | G110: 769.603
A111: 1859 | B111: 501.616 | C111: 590.795 | D111: 232.95 | E111: 762.946 | F111: 985.666 | G111: 771.134
A112: 1860 | B112: 536.458 | C112: 627.41 | D112: 233.314 | E112: 800.308 | F112: 1026.084 | G112: 772.319
A113: 1861 | B113: 555.284 | C113: 648.157 | D113: 233.668 | E113: 822.72 | F113: 1051.491 | G113: 774.237
... A221: 1969 | B221: 9806.168 | C221: 13018.927 | D221: 3925.062 | E221: 11606.642 | F221: 15640.609 | G221: 6159.526
A222: 1970 | B222: 10352.019 | C222: 13720.338 | D222: 4400.266 | E222: 12144.936 | F222: 16354.745 | G222: 6724.421 | T222: 11936.206 | U222: 15682.132 | V222: 6998.036
A223: 1971 | B223: 10493.988 | C223: 14029.147 | D223: 4705.308 | E223: 12286.099 | F223: 16642.457 | G223: 6970.823 | T223: 11815.459 | U223: 15605.096 | V223: 7108.741
A224: 1972 | B224: 10894.134 | C224: 14589.731 | D224: 4929.128 | E224: 12739.251 | F224: 17297.102 | G224: 7187.077 | T224: 12269.551 | U224: 16221.078 | V224: 7403.53
A225: 1973 | B225: 11351.976 | C225: 15201.677 | D225: 5292.569 | E225: 13274.075 | F225: 18017.206 | G225: 7568.917 | T225: 12828.771 | U225: 16985.102 | V225: 7831.676
A226: 1974 | B226: 11065.645 | C226: 15045.9 | D226: 5398.539 | E226: 12997.178 | F226: 17857.445 | G226: 7662.747 | T226: 12553.738 | U226: 16860.289 | V226: 7991.189
A227: 1975 | B227: 10668.25 | C227: 14849.101 | D227: 5634.344 | E227: 12567.922 | F227: 17635.179 | G227: 8027.605 | T227: 12109.99 | U227: 16617.985 | V227: 8286.249
A228: 1976 | B228: 11153.432 | C228: 15510.22 | D228: 5932.557 | E228: 13130.168 | F228: 18392.126 | G228: 8313.81 | T228: 12695.356 | U228: 17371.934 | V228: 8660.654
A229: 1977 | B229: 11257.169 | C229: 15761.662 | D229: 6239.649 | E229: 13200.678 | F229: 18608.023 | G229: 8669.339 | T229: 12854.841 | U229: 17657.766 | V229: 9045.277
A230: 1978 | B230: 11475.918 | C230: 16133.583 | D230: 6585.754 | E230: 13448.47 | F230: 19025.561 | G230: 9039.843 | T230: 12932.419 | U230: 17994.053 | V230: 9424.752
A231: 1979 | B231: 11743.637 | C231: 16437.35 | D231: 6882.277 | E231: 13756.335 | F231: 19385.358 | G231: 9406.889 | T231: 13215.229 | U231: 18351.504 | V231: 9764.5
A232: 1980 | B232: 11421.004 | C232: 16249.745 | D232: 6874.362 | E232: 13384.493 | F232: 19154.857 | G232: 9472.928 | T232: 12814.18 | U232: 18049.305 | V232: 9803.482
A233: 1981 | B233: 11008.27 | C233: 15717.598 | D233: 6746.115 | E233: 12978.811 | F233: 18634.061 | G233: 9413.678 | T233: 12525.641 | U233: 17689.197 | V233: 9689.776
... A241: 1989 | B241: 11531.85 | C241: 16695.624 | D241: 9459.592 | E241: 13437.741 | F241: 19605.875 | G241: 12385.934 | T241: 13034.78 | U241: 18724.88 | V241: 12540.932
...

Sheet raw_ghg_incLUC
A1: year | B1: annex2_OWID | C1: annex1_OWID | D1: nona1_OWID | E1: annex2_PRIMAP | F1: annex1_PRIMAP | G1: nona1_PRIMAP | H1: annex2_GCP_fossil | I1: annex1_GCP_fossil | J1: nona1_GCP_fossil | K1: annex2_GCP_BLUE | L1: annex1_GCP_BLUE | M1: nona1_GCP_BLUE | N1: annex2_GCP_OSCAR | O1: annex1_GCP_OSCAR | P1: nona1_GCP_OSCAR | Q1: annex2_GCP_LUCE | R1: annex1_GCP_LUCE | S1: nona1_GCP_LUCE | T1: annex2_EDGAR | U1: annex1_EDGAR | V1: nona1_EDGAR | W1: annex2_ClimateWatch | X1: annex1_ClimateWatch | Y1: nona1_ClimateWatch
A2: 1750 | E2: 160.02 | F2: 265.9 | G2: 517.951
A3: 1751 | E3: 181.77 | F3: 291.583 | G3: 527.406
A4: 1752 | E4: 194.363 | F4: 308.109 | G4: 536.862
A5: 1753 | E5: 206.951 | F5: 324.629 | G5: 546.317
A6: 1754 | E6: 219.542 | F6: 341.153 | G6: 555.772
A7: 1755 | E7: 232.131 | F7: 357.676 | G7: 565.227
A8: 1756 | E8: 245.485 | F8: 374.962 | G8: 574.682
A9: 1757 | E9: 258.072 | F9: 391.482 | G9: 584.137
A10: 1758 | E10: 270.658 | F10: 408.001 | G10: 593.592
A11: 1759 | E11: 283.243 | F11: 424.519 | G11: 603.047
A12: 1760 | E12: 295.823 | F12: 441.031 | G12: 612.501
A13: 1761 | E13: 309.584 | F13: 458.75 | G13: 621.729
... A101: 1849 | E101: 1760.988 | F101: 2292.781 | G101: 1561.888
A102: 1850 | B102: 1550.641 | C102: 2325.845 | D102: 1967.466 | E102: 1549.27 | F102: 2081.865 | G102: 1650.774
A103: 1851 | B103: 1599.614 | C103: 2376.348 | D103: 2032.821 | E103: 1560.063 | F103: 2095.452 | G103: 1618.228
A104: 1852 | B104: 1630.719 | C104: 2447.128 | D104: 2076.583 | E104: 1811.682 | F104: 2351.276 | G104: 1585.489
A105: 1853 | B105: 1683.136 | C105: 2475.421 | D105: 2085.978 | E105: 1856.217 | F105: 2399.478 | G105: 1550.994
A106: 1854 | B106: 1755.03 | C106: 2574.758 | D106: 2079.231 | E106: 1933.391 | F106: 2480.753 | G106: 1516.01
A107: 1855 | B107: 1775.259 | C107: 2601.394 | D107: 2118.618 | E107: 1969.323 | F107: 2521.239 | G107: 1479.527
A108: 1856 | B108: 1806.851 | C108: 2640.92 | D108: 2123.642 | E108: 2018.929 | F108: 2575.095 | G108: 1474.922
A109: 1857 | B109: 1832.535 | C109: 2679.446 | D109: 2143.342 | E109: 2049.892 | F109: 2610.066 | G109: 1471.382
A110: 1858 | B110: 1863.287 | C110: 2714.254 | D110: 2140.78 | E110: 2079.509 | F110: 2644.17 | G110: 1468.466
A111: 1859 | B111: 1914.287 | C111: 2773.463 | D111: 2152.288 | E111: 2125.918 | F111: 2693.616 | G111: 1466.165
A112: 1860 | B112: 1891.387 | C112: 2720.11 | D112: 1986.999 | E112: 2184.927 | F112: 2756.895 | G112: 1462.833
A113: 1861 | B113: 1845.785 | C113: 2678.775 | D113: 1924.65 | E113: 2225.877 | F113: 2814.954 | G113: 1471.184
... A241: 1989 | B241: 13065.592 | C241: 19183.046 | D241: 17926.701 | E241: 13533.435 | F241: 19784.856 | G241: 18507.54
A242: 1990 | B242: 13567.904 | C242: 19712.12 | D242: 17852.914 | E242: 12359.764 | F242: 17237.502 | G242: 15440.382 | T242: 12677.704 | U242: 17381.157 | V242: 15878.309 | W242: 11492.984 | X242: 16048.887 | Y242: 16919.403
A243: 1991 | B243: 13491.061 | C243: 19277.761 | D243: 18603.04 | E243: 12198.771 | F243: 16499.663 | G243: 16181.271 | T243: 12564.093 | U243: 17090.047 | V243: 16159.589 | W243: 11501.469 | X243: 15827.013 | Y243: 17264.48
A244: 1992 | B244: 13522.205 | C244: 18589.396 | D244: 18858.056 | E244: 12202.289 | F244: 15824.74 | G244: 16275.292 | T244: 12571.454 | U244: 16623.476 | V244: 16718.546 | W244: 11536.107 | X244: 15415.936 | Y244: 17572.505
A245: 1993 | B245: 13522.06 | C245: 18278.926 | D245: 19139.017 | E245: 12223.611 | F245: 15433.86 | G245: 16683.197 | T245: 13038.341 | U245: 16492.651 | V245: 17492.782 | W245: 11579.905 | X245: 15129.56 | Y245: 18035.221
A246: 1994 | B246: 13674.412 | C246: 17965.23 | D246: 20691.273 | E246: 12394.957 | F246: 14986.862 | G246: 14755.968 | T246: 13069.006 | U246: 16351.016 | V246: 17613.059 | W246: 11779.353 | X246: 14946.58 | Y246: 18458.994
A247: 1995 | B247: 13839.908 | C247: 17977.053 | D247: 20947.26 | E247: 12565.604 | F247: 14976.334 | G247: 16035.243 | T247: 13287.949 | U247: 16518.199 | V247: 18504.829 | W247: 11936.018 | X247: 15002.054 | Y247: 19166.555
A248: 1996 | B248: 14139.195 | C248: 18597.606 | D248: 21390.793 | E248: 12825.447 | F248: 15432.814 | G248: 15886.051 | T248: 13179.138 | U248: 16113.56 | V248: 18908.149 | W248: 12247.002 | X248: 15237.612 | Y248: 19296.193
A249: 1997 | B249: 14059.181 | C249: 17971.185 | D249: 23539.389 | E249: 12841.267 | F249: 15041.124 | G249: 15774.951 | T249: 13241.811 | U249: 15891.883 | V249: 18297.174 | W249: 12450.306 | X249: 15252.83 | Y249: 20620.839
A250: 1998 | B250: 14144.731 | C250: 17979.267 | D250: 22144.786 | E250: 12865.704 | F250: 15244.956 | G250: 16165.741 | T250: 13862.612 | U250: 15990.967 | V250: 19706.054 | W250: 12507.052 | X250: 15223.754 | Y250: 20106.31
A251: 1999 | B251: 14247.845 | C251: 18043.091 | D251: 22401.091 | E251: 12956.491 | F251: 14902.096 | G251: 16551.744 | T251: 13778.123 | U251: 16395.072 | V251: 19888.217 | W251: 12519.106 | X251: 15207.758 | Y251: 20058.136
A252: 2000 | B252: 14590.567 | C252: 18264.278 | D252: 22515.535 | E252: 13262.195 | F252: 15297.981 | G252: 16364.483 | T252: 14301.141 | U252: 17278.166 | V252: 21094.417 | W252: 12734.759 | X252: 15483.083 | Y252: 20400.023
A253: 2001 | B253: 14331.77 | C253: 18038.996 | D253: 22204.716 | E253: 13092.569 | F253: 15079.125 | G253: 16773.487 | T253: 14158.627 | U253: 16597.361 | V253: 21366.234 | W253: 12802.608 | X253: 15370.415 | Y253: 19017.439
... A275: 2023 | B275: 11483.51 | C275: 15874.977 | D275: 38197.728 | E275: 10210.924 | F275: 12545.828 | G275: 34525.696 | T275: 11890.499 | U275: 14360.017 | V275: 39108.7 | W275: 10938.942 | X275: 13714.425 | Y275: 35484.977
...

Sheet gmst
A1: year | B1: annex2_co2_excLUC | C1: annex1_co2_excLUC | D1: world_co2_excLUC | E1: annex2_co2_incLUC | F1: annex1_co2_incLUC | G1: world_co2_incLUC | H1: annex2_ghg_excLUC | I1: annex1_ghg_excLUC | J1: world_ghg_excLUC | K1: annex2_ghg_incLUC | L1: annex1_ghg_incLUC | M1: world_ghg_incLUC
A2: 1851 | B2: 8.8e-05 | C2: 8.9e-05 | D2: 9e-05 | E2: 0.000535 | F2: 0.000795 | G2: 0.001359 | H2: 0.000199 | I2: 0.000234 | J2: 0.00029 | K2: 0.000742 | L2: 0.00109 | M2: 0.001874
A3: 1852 | B3: 0.000179 | C3: 0.000183 | D3: 0.000183 | E3: 0.001082 | F3: 0.001619 | G3: 0.002766 | H3: 0.000403 | I3: 0.000473 | J3: 0.000584 | K3: 0.001498 | L3: 0.002211 | M3: 0.003795
A4: 1853 | B4: 0.000275 | C4: 0.000281 | D4: 0.000281 | E4: 0.00165 | F4: 0.002452 | G4: 0.004186 | H4: 0.000613 | I4: 0.00072 | J4: 0.000884 | K4: 0.002278 | L4: 0.003345 | M4: 0.00573
A5: 1854 | B5: 0.000387 | C5: 0.000395 | D5: 0.000396 | E5: 0.002246 | F5: 0.003323 | G5: 0.00564 | H5: 0.000853 | I5: 0.000996 | J5: 0.001212 | K5: 0.003099 | L5: 0.004533 | M5: 0.007712
A6: 1855 | B6: 0.000502 | C6: 0.000513 | D6: 0.000513 | E6: 0.002848 | F6: 0.004204 | G6: 0.00712 | H6: 0.001096 | I6: 0.001276 | J6: 0.001543 | K6: 0.003929 | L6: 0.005731 | M6: 0.009718
A7: 1856 | B7: 0.000623 | C7: 0.000637 | D7: 0.000638 | E7: 0.003462 | F7: 0.005098 | G7: 0.008616 | H7: 0.001346 | I7: 0.001564 | J7: 0.001881 | K7: 0.004771 | L7: 0.006946 | M7: 0.011739
A8: 1857 | B8: 0.000746 | C8: 0.000764 | D8: 0.000765 | E8: 0.004086 | F8: 0.006007 | G8: 0.010134 | H8: 0.001598 | I8: 0.001854 | J8: 0.002219 | K8: 0.005623 | L8: 0.008177 | M8: 0.013782
A9: 1858 | B9: 0.00087 | C9: 0.000891 | D9: 0.000893 | E9: 0.004722 | F9: 0.006929 | G9: 0.011664 | H9: 0.001848 | I9: 0.002144 | J9: 0.002558 | K9: 0.006487 | L9: 0.009421 | M9: 0.015833
A10: 1859 | B10: 0.001002 | C10: 0.001027 | D10: 0.00103 | E10: 0.005378 | F10: 0.007874 | G10: 0.013221 | H10: 0.002113 | I10: 0.002448 | J10: 0.002908 | K10: 0.007377 | L10: 0.010694 | M10: 0.017915
A11: 1860 | B11: 0.001146 | C11: 0.001175 | D11: 0.001179 | E11: 0.00602 | F11: 0.00879 | G11: 0.014674 | H11: 0.002398 | I11: 0.002773 | J11: 0.00328 | K11: 0.008262 | L11: 0.011948 | M11: 0.019899
A12: 1861 | B12: 0.001298 | C12: 0.001332 | D12: 0.001337 | E12: 0.006639 | F12: 0.009685 | G12: 0.016076 | H12: 0.002693 | I12: 0.003109 | J12: 0.003661 | K12: 0.009128 | L12: 0.013186 | M12: 0.021837
A13: 1862 | B13: 0.001452 | C13: 0.001491 | D13: 0.001497 | E13: 0.007261 | F13: 0.010578 | G13: 0.017448 | H13: 0.002987 | I13: 0.003446 | J13: 0.004043 | K13: 0.009995 | L13: 0.014424 | M13: 0.023744
... A175: 2024 | B175: 0.393743 | C175: 0.502849 | D175: 0.809546 | E175: 0.475714 | F175: 0.636608 | G175: 1.216066 | H175: 0.449633 | I175: 0.587178 | J175: 1.050284 | K175: 0.575498 | L175: 0.778234 | M175: 1.678059

Sheet Data
A1: ="Emissions shares and contribution to increase in GMST ("&TEXT(Chart!$V$1,"0")&"–"&TEXT(Chart!$V$2,"0")&")" -> Emissions shares and contribution to increase in GMST (1850–2024)
A2: Y_pos | B2: Category label | C2: OWID | D2: PRIMAP | E2: GCP fossil | F2: GCP BLUE | G2: GCP OSCAR | H2: GCP LUCE | I2: EDGAR | J2: Climate Watch | K2: GMST | L2: [ConnX_1] | M2: [ConnX_2] | N2: [ConnY_1] | O2: [ConnY_2]
A3: 1 | B3: CO2 excl. LULUCF — Annex I | C3: =IFERROR(SUMIFS(raw_co2_excLUC!$C:$C,raw_co2_excLUC!$A:$A,">="&Chart!$V$1,raw_co2_excLUC!$A:$A,"<="&Chart!$V$2)/(SUMIFS(raw_co2_excLUC!$C:$C,raw_co2_excLUC!$A:$A,">="&Chart!$V$1,raw_co2_excLUC!$A:$A,"<="&Chart!$V$2)+SUMIFS(raw_co2_excLUC!$D:$D,raw_co2_excLUC!$A:$A,">="&Chart!$V$1,raw_co2_excLUC!$A:$A,"<="&Chart!$V$2))*100,NA()) -> 62.091743 | D3: =IFERROR(SUMIFS(raw_co2_excLUC!$F:$F,raw_co2_excLUC!$A:$A,">="&Chart!$V$1,raw_co2_excLUC!$A:$A,"<="&Chart!$V$2)/(SUMIFS(raw_co2_excLUC!$F:$F,raw_co2_excLUC!$A:$A,">="&Chart!$V$1,raw_co2_excLUC!$A:$A,"<="&Chart!$V$2)+SUMIFS(raw_co2_excLUC!$G:$G,raw_co2_excLUC!$A:$A,">="&Chart!$V$1,raw_co2_excLUC!$A:$A,"<="&Chart!$V$2))*100,NA()) -> 62.17253 | E3: =IFERROR(SUMIFS(raw_co2_excLUC!$I:$I,raw_co2_excLUC!$A:$A,">="&Chart!$V$1,raw_co2_excLUC!$A:$A,"<="&Chart!$V$2)/(SUMIFS(raw_co2_excLUC!$I:$I,raw_co2_excLUC!$A:$A,">="&Chart!$V$1,raw_co2_excLUC!$A:$A,"<="&Chart!$V$2)+SUMIFS(raw_co2_excLUC!$J:$J,raw_co2_excLUC!$A:$A,">="&Chart!$V$1,raw_co2_excLUC!$A:$A,"<="&Chart!$V$2))*100,NA()) -> 62.10845 | F3: =IFERROR(SUMIFS(raw_co2_excLUC!$L:$L,raw_co2_excLUC!$A:$A,">="&Chart!$V$1,raw_co2_excLUC!$A:$A,"<="&Chart!$V$2)/(SUMIFS(raw_co2_excLUC!$L:$L,raw_co2_excLUC!$A:$A,">="&Chart!$V$1,raw_co2_excLUC!$A:$A,"<="&Chart!$V$2)+SUMIFS(raw_co2_excLUC!$M:$M,raw_co2_excLUC!$A:$A,">="&Chart!$V$1,raw_co2_excLUC!$A:$A,"<="&Chart!$V$2))*100,NA()) -> #N/A | G3: =IFERROR(SUMIFS(raw_co2_excLUC!$O:$O,raw_co2_excLUC!$A:$A,">="&Chart!$V$1,raw_co2_excLUC!$A:$A,"<="&Chart!$V$2)/(SUMIFS(raw_co2_excLUC!$O:$O,raw_co2_excLUC!$A:$A,">="&Chart!$V$1,raw_co2_excLUC!$A:$A,"<="&Chart!$V$2)+SUMIFS(raw_co2_excLUC!$P:$P,raw_co2_excLUC!$A:$A,">="&Chart!$V$1,raw_co2_excLUC!$A:$A,"<="&Chart!$V$2))*100,NA()) -> #N/A | H3: =IFERROR(SUMIFS(raw_co2_excLUC!$R:$R,raw_co2_excLUC!$A:$A,">="&Chart!$V$1,raw_co2_excLUC!$A:$A,"<="&Chart!$V$2)/(SUMIFS(raw_co2_excLUC!$R:$R,raw_co2_excLUC!$A:$A,">="&Chart!$V$1,raw_co2_excLUC!$A:$A,"<="&Chart!$V$2)+SUMIFS(raw_co2_excLUC!$S:$S,raw_co2_excLUC!$A:$A,">="&Chart!$V$1,raw_co2_excLUC!$A:$A,"<="&Chart!$V$2))*100,NA()) -> #N/A | I3: =IF(Chart!$V$1<1970,NA(),IFERROR(SUMIFS(raw_co2_excLUC!$U:$U,raw_co2_excLUC!$A:$A,">="&Chart!$V$1,raw_co2_excLUC!$A:$A,"<="&Chart!$V$2)/(SUMIFS(raw_co2_excLUC!$U:$U,raw_co2_excLUC!$A:$A,">="&Chart!$V$1,raw_co2_excLUC!$A:$A,"<="&Chart!$V$2)+SUMIFS(raw_co2_excLUC!$V:$V,raw_co2_excLUC!$A:$A,">="&Chart!$V$1,raw_co2_excLUC!$A:$A,"<="&Chart!$V$2))*100,NA())) -> #N/A | J3: =IF(Chart!$V$1<1990,NA(),IFERROR(SUMIFS(raw_co2_excLUC!$X:$X,raw_co2_excLUC!$A:$A,">="&Chart!$V$1,raw_co2_excLUC!$A:$A,"<="&Chart!$V$2)/(SUMIFS(raw_co2_excLUC!$X:$X,raw_co2_excLUC!$A:$A,">="&Chart!$V$1,raw_co2_excLUC!$A:$A,"<="&Chart!$V$2)+SUMIFS(raw_co2_excLUC!$Y:$Y,raw_co2_excLUC!$A:$A,">="&Chart!$V$1,raw_co2_excLUC!$A:$A,"<="&Chart!$V$2))*100,NA())) -> #N/A | K3: =IFERROR((VLOOKUP(Chart!$V$2,gmst!$A:$G,3,0)-IF(Chart!$V$1<=1851,0,VLOOKUP(Chart!$V$1-1,gmst!$A:$G,3,0)))/(VLOOKUP(Chart!$V$2,gmst!$A:$G,4,0)-IF(Chart!$V$1<=1851,0,VLOOKUP(Chart!$V$1-1,gmst!$A:$G,4,0)))*100,NA()) -> 62.114938 | L3: =IF(COUNT(C3:J3)<=1,NA(),_xlfn.AGGREGATE(5,6,C3:J3)) -> 62.091743 | M3: =IF(COUNT(C3:J3)<=1,0,_xlfn.AGGREGATE(4,6,C3:J3)-_xlfn.AGGREGATE(5,6,C3:J3)) -> 0.08078634 | N3: 0 | O3: =IF(ISNA(L3),NA(),L3+M3) -> 62.17253 | P3: =IF(ISNA(L3),NA(),L3) -> 62.091743 | Q3: =IF(ISNA(L3),NA(),O3) -> 62.17253 | R3: =IF(ISNA(L3),NA(),A3) -> 1 | S3: =R3 -> 1
A4: 2 | B4: CO2 excl. LULUCF — Annex II | C4: =IFERROR(SUMIFS(raw_co2_excLUC!$B:$B,raw_co2_excLUC!$A:$A,">="&Chart!$V$1,raw_co2_excLUC!$A:$A,"<="&Chart!$V$2)/(SUMIFS(raw_co2_excLUC!$C:$C,raw_co2_excLUC!$A:$A,">="&Chart!$V$1,raw_co2_excLUC!$A:$A,"<="&Chart!$V$2)+SUMIFS(raw_co2_excLUC!$D:$D,raw_co2_excLUC!$A:$A,">="&Chart!$V$1,raw_co2_excLUC!$A:$A,"<="&Chart!$V$2))*100,NA()) -> 48.621447 | D4: =IFERROR(SUMIFS(raw_co2_excLUC!$E:$E,raw_co2_excLUC!$A:$A,">="&Chart!$V$1,raw_co2_excLUC!$A:$A,"<="&Chart!$V$2)/(SUMIFS(raw_co2_excLUC!$F:$F,raw_co2_excLUC!$A:$A,">="&Chart!$V$1,raw_co2_excLUC!$A:$A,"<="&Chart!$V$2)+SUMIFS(raw_co2_excLUC!$G:$G,raw_co2_excLUC!$A:$A,">="&Chart!$V$1,raw_co2_excLUC!$A:$A,"<="&Chart!$V$2))*100,NA()) -> 48.501612 | E4: =IFERROR(SUMIFS(raw_co2_excLUC!$H:$H,raw_co2_excLUC!$A:$A,">="&Chart!$V$1,raw_co2_excLUC!$A:$A,"<="&Chart!$V$2)/(SUMIFS(raw_co2_excLUC!$I:$I,raw_co2_excLUC!$A:$A,">="&Chart!$V$1,raw_co2_excLUC!$A:$A,"<="&Chart!$V$2)+SUMIFS(raw_co2_excLUC!$J:$J,raw_co2_excLUC!$A:$A,">="&Chart!$V$1,raw_co2_excLUC!$A:$A,"<="&Chart!$V$2))*100,NA()) -> 48.63453 | F4: =IFERROR(SUMIFS(raw_co2_excLUC!$K:$K,raw_co2_excLUC!$A:$A,">="&Chart!$V$1,raw_co2_excLUC!$A:$A,"<="&Chart!$V$2)/(SUMIFS(raw_co2_excLUC!$L:$L,raw_co2_excLUC!$A:$A,">="&Chart!$V$1,raw_co2_excLUC!$A:$A,"<="&Chart!$V$2)+SUMIFS(raw_co2_excLUC!$M:$M,raw_co2_excLUC!$A:$A,">="&Chart!$V$1,raw_co2_excLUC!$A:$A,"<="&Chart!$V$2))*100,NA()) -> #N/A | G4: =IFERROR(SUMIFS(raw_co2_excLUC!$N:$N,raw_co2_excLUC!$A:$A,">="&Chart!$V$1,raw_co2_excLUC!$A:$A,"<="&Chart!$V$2)/(SUMIFS(raw_co2_excLUC!$O:$O,raw_co2_excLUC!$A:$A,">="&Chart!$V$1,raw_co2_excLUC!$A:$A,"<="&Chart!$V$2)+SUMIFS(raw_co2_excLUC!$P:$P,raw_co2_excLUC!$A:$A,">="&Chart!$V$1,raw_co2_excLUC!$A:$A,"<="&Chart!$V$2))*100,NA()) -> #N/A | H4: =IFERROR(SUMIFS(raw_co2_excLUC!$Q:$Q,raw_co2_excLUC!$A:$A,">="&Chart!$V$1,raw_co2_excLUC!$A:$A,"<="&Chart!$V$2)/(SUMIFS(raw_co2_excLUC!$R:$R,raw_co2_excLUC!$A:$A,">="&Chart!$V$1,raw_co2_excLUC!$A:$A,"<="&Chart!$V$2)+SUMIFS(raw_co2_excLUC!$S:$S,raw_co2_excLUC!$A:$A,">="&Chart!$V$1,raw_co2_excLUC!$A:$A,"<="&Chart!$V$2))*100,NA()) -> #N/A | I4: =IF(Chart!$V$1<1970,NA(),IFERROR(SUMIFS(raw_co2_excLUC!$T:$T,raw_co2_excLUC!$A:$A,">="&Chart!$V$1,raw_co2_excLUC!$A:$A,"<="&Chart!$V$2)/(SUMIFS(raw_co2_excLUC!$U:$U,raw_co2_excLUC!$A:$A,">="&Chart!$V$1,raw_co2_excLUC!$A:$A,"<="&Chart!$V$2)+SUMIFS(raw_co2_excLUC!$V:$V,raw_co2_excLUC!$A:$A,">="&Chart!$V$1,raw_co2_excLUC!$A:$A,"<="&Chart!$V$2))*100,NA())) -> #N/A | J4: =IF(Chart!$V$1<1990,NA(),IFERROR(SUMIFS(raw_co2_excLUC!$W:$W,raw_co2_excLUC!$A:$A,">="&Chart!$V$1,raw_co2_excLUC!$A:$A,"<="&Chart!$V$2)/(SUMIFS(raw_co2_excLUC!$X:$X,raw_co2_excLUC!$A:$A,">="&Chart!$V$1,raw_co2_excLUC!$A:$A,"<="&Chart!$V$2)+SUMIFS(raw_co2_excLUC!$Y:$Y,raw_co2_excLUC!$A:$A,">="&Chart!$V$1,raw_co2_excLUC!$A:$A,"<="&Chart!$V$2))*100,NA())) -> #N/A | K4: =IFERROR((VLOOKUP(Chart!$V$2,gmst!$A:$G,2,0)-IF(Chart!$V$1<=1851,0,VLOOKUP(Chart!$V$1-1,gmst!$A:$G,2,0)))/(VLOOKUP(Chart!$V$2,gmst!$A:$G,4,0)-IF(Chart!$V$1<=1851,0,VLOOKUP(Chart!$V$1-1,gmst!$A:$G,4,0)))*100,NA()) -> 48.637508 | L4: =IF(COUNT(C4:J4)<=1,NA(),_xlfn.AGGREGATE(5,6,C4:J4)) -> 48.501612 | M4: =IF(COUNT(C4:J4)<=1,0,_xlfn.AGGREGATE(4,6,C4:J4)-_xlfn.AGGREGATE(5,6,C4:J4)) -> 0.13291764 | N4: 0 | O4: =IF(ISNA(L4),NA(),L4+M4) -> 48.63453 | P4: =IF(ISNA(L4),NA(),L4) -> 48.501612 | Q4: =IF(ISNA(L4),NA(),O4) -> 48.63453 | R4: =IF(ISNA(L4),NA(),A4) -> 2 | S4: =R4 -> 2
L5: =IF(COUNT(C5:J5)<=1,NA(),_xlfn.AGGREGATE(5,6,C5:J5)) -> #N/A | M5: =IF(COUNT(C5:J5)<=1,0,_xlfn.AGGREGATE(4,6,C5:J5)-_xlfn.AGGREGATE(5,6,C5:J5)) -> 0 | N5: 0 | O5: =IF(ISNA(L5),NA(),L5+M5) -> #N/A | P5: =IF(ISNA(L5),NA(),L5) -> #N/A | Q5: =IF(ISNA(L5),NA(),O5) -> #N/A | R5: =IF(ISNA(L5),NA(),A5) -> #N/A | S5: =R5 -> #N/A
A6: 4 | B6: All GHG excl. LULUCF — Annex I | C6: =IFERROR(SUMIFS(raw_ghg_excLUC!$C:$C,raw_ghg_excLUC!$A:$A,">="&Chart!$V$1,raw_ghg_excLUC!$A:$A,"<="&Chart!$V$2)/(SUMIFS(raw_ghg_excLUC!$C:$C,raw_ghg_excLUC!$A:$A,">="&Chart!$V$1,raw_ghg_excLUC!$A:$A,"<="&Chart!$V$2)+SUMIFS(raw_ghg_excLUC!$D:$D,raw_ghg_excLUC!$A:$A,">="&Chart!$V$1,raw_ghg_excLUC!$A:$A,"<="&Chart!$V$2))*100,NA()) -> 59.4021 | D6: =IFERROR(SUMIFS(raw_ghg_excLUC!$F:$F,raw_ghg_excLUC!$A:$A,">="&Chart!$V$1,raw_ghg_excLUC!$A:$A,"<="&Chart!$V$2)/(SUMIFS(raw_ghg_excLUC!$F:$F,raw_ghg_excLUC!$A:$A,">="&Chart!$V$1,raw_ghg_excLUC!$A:$A,"<="&Chart!$V$2)+SUMIFS(raw_ghg_excLUC!$G:$G,raw_ghg_excLUC!$A:$A,">="&Chart!$V$1,raw_ghg_excLUC!$A:$A,"<="&Chart!$V$2))*100,NA()) -> 56.150528 | E6: =IFERROR(SUMIFS(raw_ghg_excLUC!$I:$I,raw_ghg_excLUC!$A:$A,">="&Chart!$V$1,raw_ghg_excLUC!$A:$A,"<="&Chart!$V$2)/(SUMIFS(raw_ghg_excLUC!$I:$I,raw_ghg_excLUC!$A:$A,">="&Chart!$V$1,raw_ghg_excLUC!$A:$A,"<="&Chart!$V$2)+SUMIFS(raw_ghg_excLUC!$J:$J,raw_ghg_excLUC!$A:$A,">="&Chart!$V$1,raw_ghg_excLUC!$A:$A,"<="&Chart!$V$2))*100,NA()) -> #N/A | F6: =IFERROR(SUMIFS(raw_ghg_excLUC!$L:$L,raw_ghg_excLUC!$A:$A,">="&Chart!$V$1,raw_ghg_excLUC!$A:$A,"<="&Chart!$V$2)/(SUMIFS(raw_ghg_excLUC!$L:$L,raw_ghg_excLUC!$A:$A,">="&Chart!$V$1,raw_ghg_excLUC!$A:$A,"<="&Chart!$V$2)+SUMIFS(raw_ghg_excLUC!$M:$M,raw_ghg_excLUC!$A:$A,">="&Chart!$V$1,raw_ghg_excLUC!$A:$A,"<="&Chart!$V$2))*100,NA()) -> #N/A | G6: =IFERROR(SUMIFS(raw_ghg_excLUC!$O:$O,raw_ghg_excLUC!$A:$A,">="&Chart!$V$1,raw_ghg_excLUC!$A:$A,"<="&Chart!$V$2)/(SUMIFS(raw_ghg_excLUC!$O:$O,raw_ghg_excLUC!$A:$A,">="&Chart!$V$1,raw_ghg_excLUC!$A:$A,"<="&Chart!$V$2)+SUMIFS(raw_ghg_excLUC!$P:$P,raw_ghg_excLUC!$A:$A,">="&Chart!$V$1,raw_ghg_excLUC!$A:$A,"<="&Chart!$V$2))*100,NA()) -> #N/A | H6: =IFERROR(SUMIFS(raw_ghg_excLUC!$R:$R,raw_ghg_excLUC!$A:$A,">="&Chart!$V$1,raw_ghg_excLUC!$A:$A,"<="&Chart!$V$2)/(SUMIFS(raw_ghg_excLUC!$R:$R,raw_ghg_excLUC!$A:$A,">="&Chart!$V$1,raw_ghg_excLUC!$A:$A,"<="&Chart!$V$2)+SUMIFS(raw_ghg_excLUC!$S:$S,raw_ghg_excLUC!$A:$A,">="&Chart!$V$1,raw_ghg_excLUC!$A:$A,"<="&Chart!$V$2))*100,NA()) -> #N/A | I6: =IF(Chart!$V$1<1970,NA(),IFERROR(SUMIFS(raw_ghg_excLUC!$U:$U,raw_ghg_excLUC!$A:$A,">="&Chart!$V$1,raw_ghg_excLUC!$A:$A,"<="&Chart!$V$2)/(SUMIFS(raw_ghg_excLUC!$U:$U,raw_ghg_excLUC!$A:$A,">="&Chart!$V$1,raw_ghg_excLUC!$A:$A,"<="&Chart!$V$2)+SUMIFS(raw_ghg_excLUC!$V:$V,raw_ghg_excLUC!$A:$A,">="&Chart!$V$1,raw_ghg_excLUC!$A:$A,"<="&Chart!$V$2))*100,NA())) -> #N/A | J6: =IF(Chart!$V$1<1990,NA(),IFERROR(SUMIFS(raw_ghg_excLUC!$X:$X,raw_ghg_excLUC!$A:$A,">="&Chart!$V$1,raw_ghg_excLUC!$A:$A,"<="&Chart!$V$2)/(SUMIFS(raw_ghg_excLUC!$X:$X,raw_ghg_excLUC!$A:$A,">="&Chart!$V$1,raw_ghg_excLUC!$A:$A,"<="&Chart!$V$2)+SUMIFS(raw_ghg_excLUC!$Y:$Y,raw_ghg_excLUC!$A:$A,">="&Chart!$V$1,raw_ghg_excLUC!$A:$A,"<="&Chart!$V$2))*100,NA())) -> #N/A | K6: =IFERROR((VLOOKUP(Chart!$V$2,gmst!$A:$M,9,0)-IF(Chart!$V$1<=1851,0,VLOOKUP(Chart!$V$1-1,gmst!$A:$M,9,0)))/(VLOOKUP(Chart!$V$2,gmst!$A:$M,10,0)-IF(Chart!$V$1<=1851,0,VLOOKUP(Chart!$V$1-1,gmst!$A:$M,10,0)))*100,NA()) -> 55.906593 | L6: =IF(COUNT(C6:J6)<=1,NA(),_xlfn.AGGREGATE(5,6,C6:J6)) -> 56.150528 | M6: =IF(COUNT(C6:J6)<=1,0,_xlfn.AGGREGATE(4,6,C6:J6)-_xlfn.AGGREGATE(5,6,C6:J6)) -> 3.2515724 | N6: 0 | O6: =IF(ISNA(L6),NA(),L6+M6) -> 59.4021 | P6: =IF(ISNA(L6),NA(),L6) -> 56.150528 | Q6: =IF(ISNA(L6),NA(),O6) -> 59.4021 | R6: =IF(ISNA(L6),NA(),A6) -> 4 | S6: =R6 -> 4
A7: 5 | B7: All GHG excl. LULUCF — Annex II | C7: =IFERROR(SUMIFS(raw_ghg_excLUC!$B:$B,raw_ghg_excLUC!$A:$A,">="&Chart!$V$1,raw_ghg_excLUC!$A:$A,"<="&Chart!$V$2)/(SUMIFS(raw_ghg_excLUC!$C:$C,raw_ghg_excLUC!$A:$A,">="&Chart!$V$1,raw_ghg_excLUC!$A:$A,"<="&Chart!$V$2)+SUMIFS(raw_ghg_excLUC!$D:$D,raw_ghg_excLUC!$A:$A,">="&Chart!$V$1,raw_ghg_excLUC!$A:$A,"<="&Chart!$V$2))*100,NA()) -> 45.862869 | D7: =IFERROR(SUMIFS(raw_ghg_excLUC!$E:$E,raw_ghg_excLUC!$A:$A,">="&Chart!$V$1,raw_ghg_excLUC!$A:$A,"<="&Chart!$V$2)/(SUMIFS(raw_ghg_excLUC!$F:$F,raw_ghg_excLUC!$A:$A,">="&Chart!$V$1,raw_ghg_excLUC!$A:$A,"<="&Chart!$V$2)+SUMIFS(raw_ghg_excLUC!$G:$G,raw_ghg_excLUC!$A:$A,">="&Chart!$V$1,raw_ghg_excLUC!$A:$A,"<="&Chart!$V$2))*100,NA()) -> 42.963096 | E7: =IFERROR(SUMIFS(raw_ghg_excLUC!$H:$H,raw_ghg_excLUC!$A:$A,">="&Chart!$V$1,raw_ghg_excLUC!$A:$A,"<="&Chart!$V$2)/(SUMIFS(raw_ghg_excLUC!$I:$I,raw_ghg_excLUC!$A:$A,">="&Chart!$V$1,raw_ghg_excLUC!$A:$A,"<="&Chart!$V$2)+SUMIFS(raw_ghg_excLUC!$J:$J,raw_ghg_excLUC!$A:$A,">="&Chart!$V$1,raw_ghg_excLUC!$A:$A,"<="&Chart!$V$2))*100,NA()) -> #N/A | F7: =IFERROR(SUMIFS(raw_ghg_excLUC!$K:$K,raw_ghg_excLUC!$A:$A,">="&Chart!$V$1,raw_ghg_excLUC!$A:$A,"<="&Chart!$V$2)/(SUMIFS(raw_ghg_excLUC!$L:$L,raw_ghg_excLUC!$A:$A,">="&Chart!$V$1,raw_ghg_excLUC!$A:$A,"<="&Chart!$V$2)+SUMIFS(raw_ghg_excLUC!$M:$M,raw_ghg_excLUC!$A:$A,">="&Chart!$V$1,raw_ghg_excLUC!$A:$A,"<="&Chart!$V$2))*100,NA()) -> #N/A | G7: =IFERROR(SUMIFS(raw_ghg_excLUC!$N:$N,raw_ghg_excLUC!$A:$A,">="&Chart!$V$1,raw_ghg_excLUC!$A:$A,"<="&Chart!$V$2)/(SUMIFS(raw_ghg_excLUC!$O:$O,raw_ghg_excLUC!$A:$A,">="&Chart!$V$1,raw_ghg_excLUC!$A:$A,"<="&Chart!$V$2)+SUMIFS(raw_ghg_excLUC!$P:$P,raw_ghg_excLUC!$A:$A,">="&Chart!$V$1,raw_ghg_excLUC!$A:$A,"<="&Chart!$V$2))*100,NA()) -> #N/A | H7: =IFERROR(SUMIFS(raw_ghg_excLUC!$Q:$Q,raw_ghg_excLUC!$A:$A,">="&Chart!$V$1,raw_ghg_excLUC!$A:$A,"<="&Chart!$V$2)/(SUMIFS(raw_ghg_excLUC!$R:$R,raw_ghg_excLUC!$A:$A,">="&Chart!$V$1,raw_ghg_excLUC!$A:$A,"<="&Chart!$V$2)+SUMIFS(raw_ghg_excLUC!$S:$S,raw_ghg_excLUC!$A:$A,">="&Chart!$V$1,raw_ghg_excLUC!$A:$A,"<="&Chart!$V$2))*100,NA()) -> #N/A | I7: =IF(Chart!$V$1<1970,NA(),IFERROR(SUMIFS(raw_ghg_excLUC!$T:$T,raw_ghg_excLUC!$A:$A,">="&Chart!$V$1,raw_ghg_excLUC!$A:$A,"<="&Chart!$V$2)/(SUMIFS(raw_ghg_excLUC!$U:$U,raw_ghg_excLUC!$A:$A,">="&Chart!$V$1,raw_ghg_excLUC!$A:$A,"<="&Chart!$V$2)+SUMIFS(raw_ghg_excLUC!$V:$V,raw_ghg_excLUC!$A:$A,">="&Chart!$V$1,raw_ghg_excLUC!$A:$A,"<="&Chart!$V$2))*100,NA())) -> #N/A | J7: =IF(Chart!$V$1<1990,NA(),IFERROR(SUMIFS(raw_ghg_excLUC!$W:$W,raw_ghg_excLUC!$A:$A,">="&Chart!$V$1,raw_ghg_excLUC!$A:$A,"<="&Chart!$V$2)/(SUMIFS(raw_ghg_excLUC!$X:$X,raw_ghg_excLUC!$A:$A,">="&Chart!$V$1,raw_ghg_excLUC!$A:$A,"<="&Chart!$V$2)+SUMIFS(raw_ghg_excLUC!$Y:$Y,raw_ghg_excLUC!$A:$A,">="&Chart!$V$1,raw_ghg_excLUC!$A:$A,"<="&Chart!$V$2))*100,NA())) -> #N/A | K7: =IFERROR((VLOOKUP(Chart!$V$2,gmst!$A:$M,8,0)-IF(Chart!$V$1<=1851,0,VLOOKUP(Chart!$V$1-1,gmst!$A:$M,8,0)))/(VLOOKUP(Chart!$V$2,gmst!$A:$M,10,0)-IF(Chart!$V$1<=1851,0,VLOOKUP(Chart!$V$1-1,gmst!$A:$M,10,0)))*100,NA()) -> 42.810611 | L7: =IF(COUNT(C7:J7)<=1,NA(),_xlfn.AGGREGATE(5,6,C7:J7)) -> 42.963096 | M7: =IF(COUNT(C7:J7)<=1,0,_xlfn.AGGREGATE(4,6,C7:J7)-_xlfn.AGGREGATE(5,6,C7:J7)) -> 2.8997722 | N7: 0 | O7: =IF(ISNA(L7),NA(),L7+M7) -> 45.862869 | P7: =IF(ISNA(L7),NA(),L7) -> 42.963096 | Q7: =IF(ISNA(L7),NA(),O7) -> 45.862869 | R7: =IF(ISNA(L7),NA(),A7) -> 5 | S7: =R7 -> 5
L8: =IF(COUNT(C8:J8)<=1,NA(),_xlfn.AGGREGATE(5,6,C8:J8)) -> #N/A | M8: =IF(COUNT(C8:J8)<=1,0,_xlfn.AGGREGATE(4,6,C8:J8)-_xlfn.AGGREGATE(5,6,C8:J8)) -> 0 | N8: 0 | O8: =IF(ISNA(L8),NA(),L8+M8) -> #N/A | P8: =IF(ISNA(L8),NA(),L8) -> #N/A | Q8: =IF(ISNA(L8),NA(),O8) -> #N/A | R8: =IF(ISNA(L8),NA(),A8) -> #N/A | S8: =R8 -> #N/A
A9: 7 | B9: CO2 incl. LULUCF — Annex I | C9: =IFERROR(SUMIFS(raw_co2_incLUC!$C:$C,raw_co2_incLUC!$A:$A,">="&Chart!$V$1,raw_co2_incLUC!$A:$A,"<="&Chart!$V$2)/(SUMIFS(raw_co2_incLUC!$C:$C,raw_co2_incLUC!$A:$A,">="&Chart!$V$1,raw_co2_incLUC!$A:$A,"<="&Chart!$V$2)+SUMIFS(raw_co2_incLUC!$D:$D,raw_co2_incLUC!$A:$A,">="&Chart!$V$1,raw_co2_incLUC!$A:$A,"<="&Chart!$V$2))*100,NA()) -> 51.211261 | D9: =IFERROR(SUMIFS(raw_co2_incLUC!$F:$F,raw_co2_incLUC!$A:$A,">="&Chart!$V$1,raw_co2_incLUC!$A:$A,"<="&Chart!$V$2)/(SUMIFS(raw_co2_incLUC!$F:$F,raw_co2_incLUC!$A:$A,">="&Chart!$V$1,raw_co2_incLUC!$A:$A,"<="&Chart!$V$2)+SUMIFS(raw_co2_incLUC!$G:$G,raw_co2_incLUC!$A:$A,">="&Chart!$V$1,raw_co2_incLUC!$A:$A,"<="&Chart!$V$2))*100,NA()) -> 53.670886 | E9: =IFERROR(SUMIFS(raw_co2_incLUC!$I:$I,raw_co2_incLUC!$A:$A,">="&Chart!$V$1,raw_co2_incLUC!$A:$A,"<="&Chart!$V$2)/(SUMIFS(raw_co2_incLUC!$I:$I,raw_co2_incLUC!$A:$A,">="&Chart!$V$1,raw_co2_incLUC!$A:$A,"<="&Chart!$V$2)+SUMIFS(raw_co2_incLUC!$J:$J,raw_co2_incLUC!$A:$A,">="&Chart!$V$1,raw_co2_incLUC!$A:$A,"<="&Chart!$V$2))*100,NA()) -> #N/A | F9: =IFERROR(SUMIFS(raw_co2_incLUC!$L:$L,raw_co2_incLUC!$A:$A,">="&Chart!$V$1,raw_co2_incLUC!$A:$A,"<="&Chart!$V$2)/(SUMIFS(raw_co2_incLUC!$L:$L,raw_co2_incLUC!$A:$A,">="&Chart!$V$1,raw_co2_incLUC!$A:$A,"<="&Chart!$V$2)+SUMIFS(raw_co2_incLUC!$M:$M,raw_co2_incLUC!$A:$A,">="&Chart!$V$1,raw_co2_incLUC!$A:$A,"<="&Chart!$V$2))*100,NA()) -> 51.219936 | G9: =IFERROR(SUMIFS(raw_co2_incLUC!$O:$O,raw_co2_incLUC!$A:$A,">="&Chart!$V$1,raw_co2_incLUC!$A:$A,"<="&Chart!$V$2)/(SUMIFS(raw_co2_incLUC!$O:$O,raw_co2_incLUC!$A:$A,">="&Chart!$V$1,raw_co2_incLUC!$A:$A,"<="&Chart!$V$2)+SUMIFS(raw_co2_incLUC!$P:$P,raw_co2_incLUC!$A:$A,">="&Chart!$V$1,raw_co2_incLUC!$A:$A,"<="&Chart!$V$2))*100,NA()) -> 52.009177 | H9: =IFERROR(SUMIFS(raw_co2_incLUC!$R:$R,raw_co2_incLUC!$A:$A,">="&Chart!$V$1,raw_co2_incLUC!$A:$A,"<="&Chart!$V$2)/(SUMIFS(raw_co2_incLUC!$R:$R,raw_co2_incLUC!$A:$A,">="&Chart!$V$1,raw_co2_incLUC!$A:$A,"<="&Chart!$V$2)+SUMIFS(raw_co2_incLUC!$S:$S,raw_co2_incLUC!$A:$A,">="&Chart!$V$1,raw_co2_incLUC!$A:$A,"<="&Chart!$V$2))*100,NA()) -> 53.884482 | I9: =IF(Chart!$V$1<1970,NA(),IFERROR(SUMIFS(raw_co2_incLUC!$U:$U,raw_co2_incLUC!$A:$A,">="&Chart!$V$1,raw_co2_incLUC!$A:$A,"<="&Chart!$V$2)/(SUMIFS(raw_co2_incLUC!$U:$U,raw_co2_incLUC!$A:$A,">="&Chart!$V$1,raw_co2_incLUC!$A:$A,"<="&Chart!$V$2)+SUMIFS(raw_co2_incLUC!$V:$V,raw_co2_incLUC!$A:$A,">="&Chart!$V$1,raw_co2_incLUC!$A:$A,"<="&Chart!$V$2))*100,NA())) -> #N/A | J9: =IF(Chart!$V$1<1990,NA(),IFERROR(SUMIFS(raw_co2_incLUC!$X:$X,raw_co2_incLUC!$A:$A,">="&Chart!$V$1,raw_co2_incLUC!$A:$A,"<="&Chart!$V$2)/(SUMIFS(raw_co2_incLUC!$X:$X,raw_co2_incLUC!$A:$A,">="&Chart!$V$1,raw_co2_incLUC!$A:$A,"<="&Chart!$V$2)+SUMIFS(raw_co2_incLUC!$Y:$Y,raw_co2_incLUC!$A:$A,">="&Chart!$V$1,raw_co2_incLUC!$A:$A,"<="&Chart!$V$2))*100,NA())) -> #N/A | K9: =IFERROR((VLOOKUP(Chart!$V$2,gmst!$A:$J,6,0)-IF(Chart!$V$1<=1851,0,VLOOKUP(Chart!$V$1-1,gmst!$A:$J,6,0)))/(VLOOKUP(Chart!$V$2,gmst!$A:$J,7,0)-IF(Chart!$V$1<=1851,0,VLOOKUP(Chart!$V$1-1,gmst!$A:$J,7,0)))*100,NA()) -> 52.34979 | L9: =IF(COUNT(C9:J9)<=1,NA(),_xlfn.AGGREGATE(5,6,C9:J9)) -> 51.211261 | M9: =IF(COUNT(C9:J9)<=1,0,_xlfn.AGGREGATE(4,6,C9:J9)-_xlfn.AGGREGATE(5,6,C9:J9)) -> 2.673221 | N9: 0 | O9: =IF(ISNA(L9),NA(),L9+M9) -> 53.884482 | P9: =IF(ISNA(L9),NA(),L9) -> 51.211261 | Q9: =IF(ISNA(L9),NA(),O9) -> 53.884482 | R9: =IF(ISNA(L9),NA(),A9) -> 7 | S9: =R9 -> 7
A10: 8 | B10: CO2 incl. LULUCF — Annex II | C10: =IFERROR(SUMIFS(raw_co2_incLUC!$B:$B,raw_co2_incLUC!$A:$A,">="&Chart!$V$1,raw_co2_incLUC!$A:$A,"<="&Chart!$V$2)/(SUMIFS(raw_co2_incLUC!$C:$C,raw_co2_incLUC!$A:$A,">="&Chart!$V$1,raw_co2_incLUC!$A:$A,"<="&Chart!$V$2)+SUMIFS(raw_co2_incLUC!$D:$D,raw_co2_incLUC!$A:$A,">="&Chart!$V$1,raw_co2_incLUC!$A:$A,"<="&Chart!$V$2))*100,NA()) -> 37.734536 | D10: =IFERROR(SUMIFS(raw_co2_incLUC!$E:$E,raw_co2_incLUC!$A:$A,">="&Chart!$V$1,raw_co2_incLUC!$A:$A,"<="&Chart!$V$2)/(SUMIFS(raw_co2_incLUC!$F:$F,raw_co2_incLUC!$A:$A,">="&Chart!$V$1,raw_co2_incLUC!$A:$A,"<="&Chart!$V$2)+SUMIFS(raw_co2_incLUC!$G:$G,raw_co2_incLUC!$A:$A,">="&Chart!$V$1,raw_co2_incLUC!$A:$A,"<="&Chart!$V$2))*100,NA()) -> 42.300436 | E10: =IFERROR(SUMIFS(raw_co2_incLUC!$H:$H,raw_co2_incLUC!$A:$A,">="&Chart!$V$1,raw_co2_incLUC!$A:$A,"<="&Chart!$V$2)/(SUMIFS(raw_co2_incLUC!$I:$I,raw_co2_incLUC!$A:$A,">="&Chart!$V$1,raw_co2_incLUC!$A:$A,"<="&Chart!$V$2)+SUMIFS(raw_co2_incLUC!$J:$J,raw_co2_incLUC!$A:$A,">="&Chart!$V$1,raw_co2_incLUC!$A:$A,"<="&Chart!$V$2))*100,NA()) -> #N/A | F10: =IFERROR(SUMIFS(raw_co2_incLUC!$K:$K,raw_co2_incLUC!$A:$A,">="&Chart!$V$1,raw_co2_incLUC!$A:$A,"<="&Chart!$V$2)/(SUMIFS(raw_co2_incLUC!$L:$L,raw_co2_incLUC!$A:$A,">="&Chart!$V$1,raw_co2_incLUC!$A:$A,"<="&Chart!$V$2)+SUMIFS(raw_co2_incLUC!$M:$M,raw_co2_incLUC!$A:$A,">="&Chart!$V$1,raw_co2_incLUC!$A:$A,"<="&Chart!$V$2))*100,NA()) -> 37.740928 | G10: =IFERROR(SUMIFS(raw_co2_incLUC!$N:$N,raw_co2_incLUC!$A:$A,">="&Chart!$V$1,raw_co2_incLUC!$A:$A,"<="&Chart!$V$2)/(SUMIFS(raw_co2_incLUC!$O:$O,raw_co2_incLUC!$A:$A,">="&Chart!$V$1,raw_co2_incLUC!$A:$A,"<="&Chart!$V$2)+SUMIFS(raw_co2_incLUC!$P:$P,raw_co2_incLUC!$A:$A,">="&Chart!$V$1,raw_co2_incLUC!$A:$A,"<="&Chart!$V$2))*100,NA()) -> 40.194727 | H10: =IFERROR(SUMIFS(raw_co2_incLUC!$Q:$Q,raw_co2_incLUC!$A:$A,">="&Chart!$V$1,raw_co2_incLUC!$A:$A,"<="&Chart!$V$2)/(SUMIFS(raw_co2_incLUC!$R:$R,raw_co2_incLUC!$A:$A,">="&Chart!$V$1,raw_co2_incLUC!$A:$A,"<="&Chart!$V$2)+SUMIFS(raw_co2_incLUC!$S:$S,raw_co2_incLUC!$A:$A,">="&Chart!$V$1,raw_co2_incLUC!$A:$A,"<="&Chart!$V$2))*100,NA()) -> 39.541654 | I10: =IF(Chart!$V$1<1970,NA(),IFERROR(SUMIFS(raw_co2_incLUC!$T:$T,raw_co2_incLUC!$A:$A,">="&Chart!$V$1,raw_co2_incLUC!$A:$A,"<="&Chart!$V$2)/(SUMIFS(raw_co2_incLUC!$U:$U,raw_co2_incLUC!$A:$A,">="&Chart!$V$1,raw_co2_incLUC!$A:$A,"<="&Chart!$V$2)+SUMIFS(raw_co2_incLUC!$V:$V,raw_co2_incLUC!$A:$A,">="&Chart!$V$1,raw_co2_incLUC!$A:$A,"<="&Chart!$V$2))*100,NA())) -> #N/A | J10: =IF(Chart!$V$1<1990,NA(),IFERROR(SUMIFS(raw_co2_incLUC!$W:$W,raw_co2_incLUC!$A:$A,">="&Chart!$V$1,raw_co2_incLUC!$A:$A,"<="&Chart!$V$2)/(SUMIFS(raw_co2_incLUC!$X:$X,raw_co2_incLUC!$A:$A,">="&Chart!$V$1,raw_co2_incLUC!$A:$A,"<="&Chart!$V$2)+SUMIFS(raw_co2_incLUC!$Y:$Y,raw_co2_incLUC!$A:$A,">="&Chart!$V$1,raw_co2_incLUC!$A:$A,"<="&Chart!$V$2))*100,NA())) -> #N/A | K10: =IFERROR((VLOOKUP(Chart!$V$2,gmst!$A:$J,5,0)-IF(Chart!$V$1<=1851,0,VLOOKUP(Chart!$V$1-1,gmst!$A:$J,5,0)))/(VLOOKUP(Chart!$V$2,gmst!$A:$J,7,0)-IF(Chart!$V$1<=1851,0,VLOOKUP(Chart!$V$1-1,gmst!$A:$J,7,0)))*100,NA()) -> 39.119094 | L10: =IF(COUNT(C10:J10)<=1,NA(),_xlfn.AGGREGATE(5,6,C10:J10)) -> 37.734536 | M10: =IF(COUNT(C10:J10)<=1,0,_xlfn.AGGREGATE(4,6,C10:J10)-_xlfn.AGGREGATE(5,6,C10:J10)) -> 4.5659 | N10: 0 | O10: =IF(ISNA(L10),NA(),L10+M10) -> 42.300436 | P10: =IF(ISNA(L10),NA(),L10) -> 37.734536 | Q10: =IF(ISNA(L10),NA(),O10) -> 42.300436 | R10: =IF(ISNA(L10),NA(),A10) -> 8 | S10: =R10 -> 8
L11: =IF(COUNT(C11:J11)<=1,NA(),_xlfn.AGGREGATE(5,6,C11:J11)) -> #N/A | M11: =IF(COUNT(C11:J11)<=1,0,_xlfn.AGGREGATE(4,6,C11:J11)-_xlfn.AGGREGATE(5,6,C11:J11)) -> 0 | N11: 0 | O11: =IF(ISNA(L11),NA(),L11+M11) -> #N/A | P11: =IF(ISNA(L11),NA(),L11) -> #N/A | Q11: =IF(ISNA(L11),NA(),O11) -> #N/A | R11: =IF(ISNA(L11),NA(),A11) -> #N/A | S11: =R11 -> #N/A
A12: 10 | B12: All GHG incl. LULUCF — Annex I | C12: =IFERROR(SUMIFS(raw_ghg_incLUC!$C:$C,raw_ghg_incLUC!$A:$A,">="&Chart!$V$1,raw_ghg_incLUC!$A:$A,"<="&Chart!$V$2)/(SUMIFS(raw_ghg_incLUC!$C:$C,raw_ghg_incLUC!$A:$A,">="&Chart!$V$1,raw_ghg_incLUC!$A:$A,"<="&Chart!$V$2)+SUMIFS(raw_ghg_incLUC!$D:$D,raw_ghg_incLUC!$A:$A,">="&Chart!$V$1,raw_ghg_incLUC!$A:$A,"<="&Chart!$V$2))*100,NA()) -> 49.389956 | D12: =IFERROR(SUMIFS(raw_ghg_incLUC!$F:$F,raw_ghg_incLUC!$A:$A,">="&Chart!$V$1,raw_ghg_incLUC!$A:$A,"<="&Chart!$V$2)/(SUMIFS(raw_ghg_incLUC!$F:$F,raw_ghg_incLUC!$A:$A,">="&Chart!$V$1,raw_ghg_incLUC!$A:$A,"<="&Chart!$V$2)+SUMIFS(raw_ghg_incLUC!$G:$G,raw_ghg_incLUC!$A:$A,">="&Chart!$V$1,raw_ghg_incLUC!$A:$A,"<="&Chart!$V$2))*100,NA()) -> 50.956621 | E12: =IFERROR(SUMIFS(raw_ghg_incLUC!$I:$I,raw_ghg_incLUC!$A:$A,">="&Chart!$V$1,raw_ghg_incLUC!$A:$A,"<="&Chart!$V$2)/(SUMIFS(raw_ghg_incLUC!$I:$I,raw_ghg_incLUC!$A:$A,">="&Chart!$V$1,raw_ghg_incLUC!$A:$A,"<="&Chart!$V$2)+SUMIFS(raw_ghg_incLUC!$J:$J,raw_ghg_incLUC!$A:$A,">="&Chart!$V$1,raw_ghg_incLUC!$A:$A,"<="&Chart!$V$2))*100,NA()) -> #N/A | F12: =IFERROR(SUMIFS(raw_ghg_incLUC!$L:$L,raw_ghg_incLUC!$A:$A,">="&Chart!$V$1,raw_ghg_incLUC!$A:$A,"<="&Chart!$V$2)/(SUMIFS(raw_ghg_incLUC!$L:$L,raw_ghg_incLUC!$A:$A,">="&Chart!$V$1,raw_ghg_incLUC!$A:$A,"<="&Chart!$V$2)+SUMIFS(raw_ghg_incLUC!$M:$M,raw_ghg_incLUC!$A:$A,">="&Chart!$V$1,raw_ghg_incLUC!$A:$A,"<="&Chart!$V$2))*100,NA()) -> #N/A | G12: =IFERROR(SUMIFS(raw_ghg_incLUC!$O:$O,raw_ghg_incLUC!$A:$A,">="&Chart!$V$1,raw_ghg_incLUC!$A:$A,"<="&Chart!$V$2)/(SUMIFS(raw_ghg_incLUC!$O:$O,raw_ghg_incLUC!$A:$A,">="&Chart!$V$1,raw_ghg_incLUC!$A:$A,"<="&Chart!$V$2)+SUMIFS(raw_ghg_incLUC!$P:$P,raw_ghg_incLUC!$A:$A,">="&Chart!$V$1,raw_ghg_incLUC!$A:$A,"<="&Chart!$V$2))*100,NA()) -> #N/A | H12: =IFERROR(SUMIFS(raw_ghg_incLUC!$R:$R,raw_ghg_incLUC!$A:$A,">="&Chart!$V$1,raw_ghg_incLUC!$A:$A,"<="&Chart!$V$2)/(SUMIFS(raw_ghg_incLUC!$R:$R,raw_ghg_incLUC!$A:$A,">="&Chart!$V$1,raw_ghg_incLUC!$A:$A,"<="&Chart!$V$2)+SUMIFS(raw_ghg_incLUC!$S:$S,raw_ghg_incLUC!$A:$A,">="&Chart!$V$1,raw_ghg_incLUC!$A:$A,"<="&Chart!$V$2))*100,NA()) -> #N/A | I12: =IF(Chart!$V$1<1970,NA(),IFERROR(SUMIFS(raw_ghg_incLUC!$U:$U,raw_ghg_incLUC!$A:$A,">="&Chart!$V$1,raw_ghg_incLUC!$A:$A,"<="&Chart!$V$2)/(SUMIFS(raw_ghg_incLUC!$U:$U,raw_ghg_incLUC!$A:$A,">="&Chart!$V$1,raw_ghg_incLUC!$A:$A,"<="&Chart!$V$2)+SUMIFS(raw_ghg_incLUC!$V:$V,raw_ghg_incLUC!$A:$A,">="&Chart!$V$1,raw_ghg_incLUC!$A:$A,"<="&Chart!$V$2))*100,NA())) -> #N/A | J12: =IF(Chart!$V$1<1990,NA(),IFERROR(SUMIFS(raw_ghg_incLUC!$X:$X,raw_ghg_incLUC!$A:$A,">="&Chart!$V$1,raw_ghg_incLUC!$A:$A,"<="&Chart!$V$2)/(SUMIFS(raw_ghg_incLUC!$X:$X,raw_ghg_incLUC!$A:$A,">="&Chart!$V$1,raw_ghg_incLUC!$A:$A,"<="&Chart!$V$2)+SUMIFS(raw_ghg_incLUC!$Y:$Y,raw_ghg_incLUC!$A:$A,">="&Chart!$V$1,raw_ghg_incLUC!$A:$A,"<="&Chart!$V$2))*100,NA())) -> #N/A | K12: =IFERROR((VLOOKUP(Chart!$V$2,gmst!$A:$P,12,0)-IF(Chart!$V$1<=1851,0,VLOOKUP(Chart!$V$1-1,gmst!$A:$P,12,0)))/(VLOOKUP(Chart!$V$2,gmst!$A:$P,13,0)-IF(Chart!$V$1<=1851,0,VLOOKUP(Chart!$V$1-1,gmst!$A:$P,13,0)))*100,NA()) -> 46.377034 | L12: =IF(COUNT(C12:J12)<=1,NA(),_xlfn.AGGREGATE(5,6,C12:J12)) -> 49.389956 | M12: =IF(COUNT(C12:J12)<=1,0,_xlfn.AGGREGATE(4,6,C12:J12)-_xlfn.AGGREGATE(5,6,C12:J12)) -> 1.5666652 | N12: 0 | O12: =IF(ISNA(L12),NA(),L12+M12) -> 50.956621 | P12: =IF(ISNA(L12),NA(),L12) -> 49.389956 | Q12: =IF(ISNA(L12),NA(),O12) -> 50.956621 | R12: =IF(ISNA(L12),NA(),A12) -> 10 | S12: =R12 -> 10
A13: 11 | B13: All GHG incl. LULUCF — Annex II | C13: =IFERROR(SUMIFS(raw_ghg_incLUC!$B:$B,raw_ghg_incLUC!$A:$A,">="&Chart!$V$1,raw_ghg_incLUC!$A:$A,"<="&Chart!$V$2)/(SUMIFS(raw_ghg_incLUC!$C:$C,raw_ghg_incLUC!$A:$A,">="&Chart!$V$1,raw_ghg_incLUC!$A:$A,"<="&Chart!$V$2)+SUMIFS(raw_ghg_incLUC!$D:$D,raw_ghg_incLUC!$A:$A,">="&Chart!$V$1,raw_ghg_incLUC!$A:$A,"<="&Chart!$V$2))*100,NA()) -> 36.435552 | D13: =IFERROR(SUMIFS(raw_ghg_incLUC!$E:$E,raw_ghg_incLUC!$A:$A,">="&Chart!$V$1,raw_ghg_incLUC!$A:$A,"<="&Chart!$V$2)/(SUMIFS(raw_ghg_incLUC!$F:$F,raw_ghg_incLUC!$A:$A,">="&Chart!$V$1,raw_ghg_incLUC!$A:$A,"<="&Chart!$V$2)+SUMIFS(raw_ghg_incLUC!$G:$G,raw_ghg_incLUC!$A:$A,">="&Chart!$V$1,raw_ghg_incLUC!$A:$A,"<="&Chart!$V$2))*100,NA()) -> 39.454285 | E13: =IFERROR(SUMIFS(raw_ghg_incLUC!$H:$H,raw_ghg_incLUC!$A:$A,">="&Chart!$V$1,raw_ghg_incLUC!$A:$A,"<="&Chart!$V$2)/(SUMIFS(raw_ghg_incLUC!$I:$I,raw_ghg_incLUC!$A:$A,">="&Chart!$V$1,raw_ghg_incLUC!$A:$A,"<="&Chart!$V$2)+SUMIFS(raw_ghg_incLUC!$J:$J,raw_ghg_incLUC!$A:$A,">="&Chart!$V$1,raw_ghg_incLUC!$A:$A,"<="&Chart!$V$2))*100,NA()) -> #N/A | F13: =IFERROR(SUMIFS(raw_ghg_incLUC!$K:$K,raw_ghg_incLUC!$A:$A,">="&Chart!$V$1,raw_ghg_incLUC!$A:$A,"<="&Chart!$V$2)/(SUMIFS(raw_ghg_incLUC!$L:$L,raw_ghg_incLUC!$A:$A,">="&Chart!$V$1,raw_ghg_incLUC!$A:$A,"<="&Chart!$V$2)+SUMIFS(raw_ghg_incLUC!$M:$M,raw_ghg_incLUC!$A:$A,">="&Chart!$V$1,raw_ghg_incLUC!$A:$A,"<="&Chart!$V$2))*100,NA()) -> #N/A | G13: =IFERROR(SUMIFS(raw_ghg_incLUC!$N:$N,raw_ghg_incLUC!$A:$A,">="&Chart!$V$1,raw_ghg_incLUC!$A:$A,"<="&Chart!$V$2)/(SUMIFS(raw_ghg_incLUC!$O:$O,raw_ghg_incLUC!$A:$A,">="&Chart!$V$1,raw_ghg_incLUC!$A:$A,"<="&Chart!$V$2)+SUMIFS(raw_ghg_incLUC!$P:$P,raw_ghg_incLUC!$A:$A,">="&Chart!$V$1,raw_ghg_incLUC!$A:$A,"<="&Chart!$V$2))*100,NA()) -> #N/A | H13: =IFERROR(SUMIFS(raw_ghg_incLUC!$Q:$Q,raw_ghg_incLUC!$A:$A,">="&Chart!$V$1,raw_ghg_incLUC!$A:$A,"<="&Chart!$V$2)/(SUMIFS(raw_ghg_incLUC!$R:$R,raw_ghg_incLUC!$A:$A,">="&Chart!$V$1,raw_ghg_incLUC!$A:$A,"<="&Chart!$V$2)+SUMIFS(raw_ghg_incLUC!$S:$S,raw_ghg_incLUC!$A:$A,">="&Chart!$V$1,raw_ghg_incLUC!$A:$A,"<="&Chart!$V$2))*100,NA()) -> #N/A | I13: =IF(Chart!$V$1<1970,NA(),IFERROR(SUMIFS(raw_ghg_incLUC!$T:$T,raw_ghg_incLUC!$A:$A,">="&Chart!$V$1,raw_ghg_incLUC!$A:$A,"<="&Chart!$V$2)/(SUMIFS(raw_ghg_incLUC!$U:$U,raw_ghg_incLUC!$A:$A,">="&Chart!$V$1,raw_ghg_incLUC!$A:$A,"<="&Chart!$V$2)+SUMIFS(raw_ghg_incLUC!$V:$V,raw_ghg_incLUC!$A:$A,">="&Chart!$V$1,raw_ghg_incLUC!$A:$A,"<="&Chart!$V$2))*100,NA())) -> #N/A | J13: =IF(Chart!$V$1<1990,NA(),IFERROR(SUMIFS(raw_ghg_incLUC!$W:$W,raw_ghg_incLUC!$A:$A,">="&Chart!$V$1,raw_ghg_incLUC!$A:$A,"<="&Chart!$V$2)/(SUMIFS(raw_ghg_incLUC!$X:$X,raw_ghg_incLUC!$A:$A,">="&Chart!$V$1,raw_ghg_incLUC!$A:$A,"<="&Chart!$V$2)+SUMIFS(raw_ghg_incLUC!$Y:$Y,raw_ghg_incLUC!$A:$A,">="&Chart!$V$1,raw_ghg_incLUC!$A:$A,"<="&Chart!$V$2))*100,NA())) -> #N/A | K13: =IFERROR((VLOOKUP(Chart!$V$2,gmst!$A:$P,11,0)-IF(Chart!$V$1<=1851,0,VLOOKUP(Chart!$V$1-1,gmst!$A:$P,11,0)))/(VLOOKUP(Chart!$V$2,gmst!$A:$P,13,0)-IF(Chart!$V$1<=1851,0,VLOOKUP(Chart!$V$1-1,gmst!$A:$P,13,0)))*100,NA()) -> 34.295457 | L13: =IF(COUNT(C13:J13)<=1,NA(),_xlfn.AGGREGATE(5,6,C13:J13)) -> 36.435552 | M13: =IF(COUNT(C13:J13)<=1,0,_xlfn.AGGREGATE(4,6,C13:J13)-_xlfn.AGGREGATE(5,6,C13:J13)) -> 3.0187333 | N13: 0 | O13: =IF(ISNA(L13),NA(),L13+M13) -> 39.454285 | P13: =IF(ISNA(L13),NA(),L13) -> 36.435552 | Q13: =IF(ISNA(L13),NA(),O13) -> 39.454285 | R13: =IF(ISNA(L13),NA(),A13) -> 11 | S13: =R13 -> 11

Sheet Chart
U1: Start year | V1: 1850
U2: End year | V2: 2024
