Workbook

Sheet vals_ghg_incLUC
A2: Year | B2: annex2_OWID | C2: annex1_OWID | D2: non_annex1_OWID | E2: annex2_PRIMAP | F2: annex1_PRIMAP | G2: non_annex1_PRIMAP | H2: annex2_EDGAR | I2: annex1_EDGAR | J2: non_annex1_EDGAR | N2: cum_annex2_OWID | O2: cum_annex1_OWID | P2: cum_non_ann1_OWID | Q2: cum_world_OWID | R2: pct_annex2_OWID | S2: pct_annex1_OWID | T2: cum_annex2_PRIMAP | U2: cum_annex1_PRIMAP | V2: cum_non_ann1_PRIMAP | W2: cum_world_PRIMAP | X2: pct_annex2_PRIMAP | Y2: pct_annex1_PRIMAP | Z2: cum_annex2_EDGAR | AA2: cum_annex1_EDGAR | AB2: cum_non_ann1_EDGAR | AC2: cum_world_EDGAR | AD2: pct_annex2_EDGAR | AE2: pct_annex1_EDGAR
A3: 1850 | B3: 1550.641 | C3: 2325.845 | D3: 1967.466 | E3: 1549.27 | F3: 2081.865 | G3: 1650.774 | N3: =IF(ISBLANK($B3),NA(),IFERROR(SUM($B3:$B$177),NA())) -> 1314684.8 | O3: =IF(ISBLANK($C3),NA(),IFERROR(SUM($C3:$C$177),NA())) -> 1782111.7 | P3: =IF(ISBLANK($D3),NA(),IFERROR(SUM($D3:$D$177),NA())) -> 1826135.5 | Q3: =IFERROR(O3+P3,"") -> 3608247.3 | R3: =IFERROR(N3/Q3*100,NA()) -> 36.435552 | S3: =IFERROR(O3/Q3*100,NA()) -> 49.389956 | T3: =IF(ISBLANK($E3),NA(),IFERROR(SUM($E3:$E$177),NA())) -> 1252707.5 | U3: =IF(ISBLANK($F3),NA(),IFERROR(SUM($F3:$F$177),NA())) -> 1617916.6 | V3: =IF(ISBLANK($G3),NA(),IFERROR(SUM($G3:$G$177),NA())) -> 1557169.5 | W3: =IFERROR(U3+V3,"") -> 3175086.2 | X3: =IFERROR(T3/W3*100,NA()) -> 39.454285 | Y3: =IFERROR(U3/W3*100,NA()) -> 50.956621 | Z3: =IF(ISBLANK($H3),NA(),IFERROR(SUM($H3:$H$177),NA())) -> #N/A | AA3: =IF(ISBLANK($I3),NA(),IFERROR(SUM($I3:$I$177),NA())) -> #N/A | AB3: =IF(ISBLANK($J3),NA(),IFERROR(SUM($J3:$J$177),NA())) -> #N/A | AC3: =IFERROR(AA3+AB3,"") | AD3: =IFERROR(Z3/AC3*100,NA()) -> #N/A | AE3: =IFERROR(AA3/AC3*100,NA()) -> #N/A
A4: 1851 | B4: 1599.614 | C4: 2376.348 | D4: 2032.821 | E4: 1560.063 | F4: 2095.452 | G4: 1618.228 | N4: =IF(ISBLANK($B4),NA(),IFERROR(SUM($B4:$B$177),NA())) -> 1313134.2 | O4: =IF(ISBLANK($C4),NA(),IFERROR(SUM($C4:$C$177),NA())) -> 1779785.9 | P4: =IF(ISBLANK($D4),NA(),IFERROR(SUM($D4:$D$177),NA())) -> 1824168.1 | Q4: =IFERROR(O4+P4,"") -> 3603954 | R4: =IFERROR(N4/Q4*100,NA()) -> 36.43593 | S4: =IFERROR(O4/Q4*100,NA()) -> 49.384257 | T4: =IF(ISBLANK($E4),NA(),IFERROR(SUM($E4:$E$177),NA())) -> 1251158.3 | U4: =IF(ISBLANK($F4),NA(),IFERROR(SUM($F4:$F$177),NA())) -> 1615834.8 | V4: =IF(ISBLANK($G4),NA(),IFERROR(SUM($G4:$G$177),NA())) -> 1555518.8 | W4: =IFERROR(U4+V4,"") -> 3171353.5 | X4: =IFERROR(T4/W4*100,NA()) -> 39.45187 | Y4: =IFERROR(U4/W4*100,NA()) -> 50.95095 | Z4: =IF(ISBLANK($H4),NA(),IFERROR(SUM($H4:$H$177),NA())) -> #N/A | AA4: =IF(ISBLANK($I4),NA(),IFERROR(SUM($I4:$I$177),NA())) -> #N/A | AB4: =IF(ISBLANK($J4),NA(),IFERROR(SUM($J4:$J$177),NA())) -> #N/A | AC4: =IFERROR(AA4+AB4,"") | AD4: =IFERROR(Z4/AC4*100,NA()) -> #N/A | AE4: =IFERROR(AA4/AC4*100,NA()) -> #N/A
A5: 1852 | B5: 1630.719 | C5: 2447.128 | D5: 2076.583 | E5: 1811.682 | F5: 2351.276 | G5: 1585.489 | N5: =IF(ISBLANK($B5),NA(),IFERROR(SUM($B5:$B$177),NA())) -> 1311534.5 | O5: =IF(ISBLANK($C5),NA(),IFERROR(SUM($C5:$C$177),NA())) -> 1777409.5 | P5: =IF(ISBLANK($D5),NA(),IFERROR(SUM($D5:$D$177),NA())) -> 1822135.3 | Q5: =IFERROR(O5+P5,"") -> 3599544.8 | R5: =IFERROR(N5/Q5*100,NA()) -> 36.436122 | S5: =IFERROR(O5/Q5*100,NA()) -> 49.378731 | T5: =IF(ISBLANK($E5),NA(),IFERROR(SUM($E5:$E$177),NA())) -> 1249598.2 | U5: =IF(ISBLANK($F5),NA(),IFERROR(SUM($F5:$F$177),NA())) -> 1613739.3 | V5: =IF(ISBLANK($G5),NA(),IFERROR(SUM($G5:$G$177),NA())) -> 1553900.5 | W5: =IFERROR(U5+V5,"") -> 3167639.8 | X5: =IFERROR(T5/W5*100,NA()) -> 39.448873 | Y5: =IFERROR(U5/W5*100,NA()) -> 50.944532 | Z5: =IF(ISBLANK($H5),NA(),IFERROR(SUM($H5:$H$177),NA())) -> #N/A | AA5: =IF(ISBLANK($I5),NA(),IFERROR(SUM($I5:$I$177),NA())) -> #N/A | AB5: =IF(ISBLANK($J5),NA(),IFERROR(SUM($J5:$J$177),NA())) -> #N/A | AC5: =IFERROR(AA5+AB5,"") | AD5: =IFERROR(Z5/AC5*100,NA()) -> #N/A | AE5: =IFERROR(AA5/AC5*100,NA()) -> #N/A
A6: 1853 | B6: 1683.136 | C6: 2475.421 | D6: 2085.978 | E6: 1856.217 | F6: 2399.478 | G6: 1550.994 | N6: =IF(ISBLANK($B6),NA(),IFERROR(SUM($B6:$B$177),NA())) -> 1309903.8 | O6: =IF(ISBLANK($C6),NA(),IFERROR(SUM($C6:$C$177),NA())) -> 1774962.4 | P6: =IF(ISBLANK($D6),NA(),IFERROR(SUM($D6:$D$177),NA())) -> 1820058.7 | Q6: =IFERROR(O6+P6,"") -> 3595021.1 | R6: =IFERROR(N6/Q6*100,NA()) -> 36.43661 | S6: =IFERROR(O6/Q6*100,NA()) -> 49.372795 | T6: =IF(ISBLANK($E6),NA(),IFERROR(SUM($E6:$E$177),NA())) -> 1247786.5 | U6: =IF(ISBLANK($F6),NA(),IFERROR(SUM($F6:$F$177),NA())) -> 1611388 | V6: =IF(ISBLANK($G6),NA(),IFERROR(SUM($G6:$G$177),NA())) -> 1552315.1 | W6: =IFERROR(U6+V6,"") -> 3163703.1 | X6: =IFERROR(T6/W6*100,NA()) -> 39.440696 | Y6: =IFERROR(U6/W6*100,NA()) -> 50.933605 | Z6: =IF(ISBLANK($H6),NA(),IFERROR(SUM($H6:$H$177),NA())) -> #N/A | AA6: =IF(ISBLANK($I6),NA(),IFERROR(SUM($I6:$I$177),NA())) -> #N/A | AB6: =IF(ISBLANK($J6),NA(),IFERROR(SUM($J6:$J$177),NA())) -> #N/A | AC6: =IFERROR(AA6+AB6,"") | AD6: =IFERROR(Z6/AC6*100,NA()) -> #N/A | AE6: =IFERROR(AA6/AC6*100,NA()) -> #N/A
A7: 1854 | B7: 1755.03 | C7: 2574.758 | D7: 2079.231 | E7: 1933.391 | F7: 2480.753 | G7: 1516.01 | N7: =IF(ISBLANK($B7),NA(),IFERROR(SUM($B7:$B$177),NA())) -> 1308220.7 | O7: =IF(ISBLANK($C7),NA(),IFERROR(SUM($C7:$C$177),NA())) -> 1772487 | P7: =IF(ISBLANK($D7),NA(),IFERROR(SUM($D7:$D$177),NA())) -> 1817972.7 | Q7: =IFERROR(O7+P7,"") -> 3590459.7 | R7: =IFERROR(N7/Q7*100,NA()) -> 36.436022 | S7: =IFERROR(O7/Q7*100,NA()) -> 49.366575 | T7: =IF(ISBLANK($E7),NA(),IFERROR(SUM($E7:$E$177),NA())) -> 1245930.3 | U7: =IF(ISBLANK($F7),NA(),IFERROR(SUM($F7:$F$177),NA())) -> 1608988.5 | V7: =IF(ISBLANK($G7),NA(),IFERROR(SUM($G7:$G$177),NA())) -> 1550764.1 | W7: =IFERROR(U7+V7,"") -> 3159752.6 | X7: =IFERROR(T7/W7*100,NA()) -> 39.431261 | Y7: =IFERROR(U7/W7*100,NA()) -> 50.921346 | Z7: =IF(ISBLANK($H7),NA(),IFERROR(SUM($H7:$H$177),NA())) -> #N/A | AA7: =IF(ISBLANK($I7),NA(),IFERROR(SUM($I7:$I$177),NA())) -> #N/A | AB7: =IF(ISBLANK($J7),NA(),IFERROR(SUM($J7:$J$177),NA())) -> #N/A | AC7: =IFERROR(AA7+AB7,"") | AD7: =IFERROR(Z7/AC7*100,NA()) -> #N/A | AE7: =IFERROR(AA7/AC7*100,NA()) -> #N/A
A8: 1855 | B8: 1775.259 | C8: 2601.394 | D8: 2118.618 | E8: 1969.323 | F8: 2521.239 | G8: 1479.527 | N8: =IF(ISBLANK($B8),NA(),IFERROR(SUM($B8:$B$177),NA())) -> 1306465.7 | O8: =IF(ISBLANK($C8),NA(),IFERROR(SUM($C8:$C$177),NA())) -> 1769912.2 | P8: =IF(ISBLANK($D8),NA(),IFERROR(SUM($D8:$D$177),NA())) -> 1815893.5 | Q8: =IFERROR(O8+P8,"") -> 3585805.7 | R8: =IFERROR(N8/Q8*100,NA()) -> 36.434369 | S8: =IFERROR(O8/Q8*100,NA()) -> 49.358844 | T8: =IF(ISBLANK($E8),NA(),IFERROR(SUM($E8:$E$177),NA())) -> 1243996.9 | U8: =IF(ISBLANK($F8),NA(),IFERROR(SUM($F8:$F$177),NA())) -> 1606507.8 | V8: =IF(ISBLANK($G8),NA(),IFERROR(SUM($G8:$G$177),NA())) -> 1549248 | W8: =IFERROR(U8+V8,"") -> 3155755.8 | X8: =IFERROR(T8/W8*100,NA()) -> 39.419936 | Y8: =IFERROR(U8/W8*100,NA()) -> 50.907227 | Z8: =IF(ISBLANK($H8),NA(),IFERROR(SUM($H8:$H$177),NA())) -> #N/A | AA8: =IF(ISBLANK($I8),NA(),IFERROR(SUM($I8:$I$177),NA())) -> #N/A | AB8: =IF(ISBLANK($J8),NA(),IFERROR(SUM($J8:$J$177),NA())) -> #N/A | AC8: =IFERROR(AA8+AB8,"") | AD8: =IFERROR(Z8/AC8*100,NA()) -> #N/A | AE8: =IFERROR(AA8/AC8*100,NA()) -> #N/A
A9: 1856 | B9: 1806.851 | C9: 2640.92 | D9: 2123.642 | E9: 2018.929 | F9: 2575.095 | G9: 1474.922 | N9: =IF(ISBLANK($B9),NA(),IFERROR(SUM($B9:$B$177),NA())) -> 1304690.4 | O9: =IF(ISBLANK($C9),NA(),IFERROR(SUM($C9:$C$177),NA())) -> 1767310.8 | P9: =IF(ISBLANK($D9),NA(),IFERROR(SUM($D9:$D$177),NA())) -> 1813774.8 | Q9: =IFERROR(O9+P9,"") -> 3581085.7 | R9: =IFERROR(N9/Q9*100,NA()) -> 36.432817 | S9: =IFERROR(O9/Q9*100,NA()) -> 49.351258 | T9: =IF(ISBLANK($E9),NA(),IFERROR(SUM($E9:$E$177),NA())) -> 1242027.6 | U9: =IF(ISBLANK($F9),NA(),IFERROR(SUM($F9:$F$177),NA())) -> 1603986.6 | V9: =IF(ISBLANK($G9),NA(),IFERROR(SUM($G9:$G$177),NA())) -> 1547768.5 | W9: =IFERROR(U9+V9,"") -> 3151755.1 | X9: =IFERROR(T9/W9*100,NA()) -> 39.407491 | Y9: =IFERROR(U9/W9*100,NA()) -> 50.891853 | Z9: =IF(ISBLANK($H9),NA(),IFERROR(SUM($H9:$H$177),NA())) -> #N/A | AA9: =IF(ISBLANK($I9),NA(),IFERROR(SUM($I9:$I$177),NA())) -> #N/A | AB9: =IF(ISBLANK($J9),NA(),IFERROR(SUM($J9:$J$177),NA())) -> #N/A | AC9: =IFERROR(AA9+AB9,"") | AD9: =IFERROR(Z9/AC9*100,NA()) -> #N/A | AE9: =IFERROR(AA9/AC9*100,NA()) -> #N/A
A10: 1857 | B10: 1832.535 | C10: 2679.446 | D10: 2143.342 | E10: 2049.892 | F10: 2610.066 | G10: 1471.382 | N10: =IF(ISBLANK($B10),NA(),IFERROR(SUM($B10:$B$177),NA())) -> 1302883.5 | O10: =IF(ISBLANK($C10),NA(),IFERROR(SUM($C10:$C$177),NA())) -> 1764669.9 | P10: =IF(ISBLANK($D10),NA(),IFERROR(SUM($D10:$D$177),NA())) -> 1811651.2 | Q10: =IFERROR(O10+P10,"") -> 3576321.1 | R10: =IFERROR(N10/Q10*100,NA()) -> 36.430832 | S10: =IFERROR(O10/Q10*100,NA()) -> 49.343162 | T10: =IF(ISBLANK($E10),NA(),IFERROR(SUM($E10:$E$177),NA())) -> 1240008.7 | U10: =IF(ISBLANK($F10),NA(),IFERROR(SUM($F10:$F$177),NA())) -> 1601411.5 | V10: =IF(ISBLANK($G10),NA(),IFERROR(SUM($G10:$G$177),NA())) -> 1546293.6 | W10: =IFERROR(U10+V10,"") -> 3147705.1 | X10: =IFERROR(T10/W10*100,NA()) -> 39.394055 | Y10: =IFERROR(U10/W10*100,NA()) -> 50.875525 | Z10: =IF(ISBLANK($H10),NA(),IFERROR(SUM($H10:$H$177),NA())) -> #N/A | AA10: =IF(ISBLANK($I10),NA(),IFERROR(SUM($I10:$I$177),NA())) -> #N/A | AB10: =IF(ISBLANK($J10),NA(),IFERROR(SUM($J10:$J$177),NA())) -> #N/A | AC10: =IFERROR(AA10+AB10,"") | AD10: =IFERROR(Z10/AC10*100,NA()) -> #N/A | AE10: =IFERROR(AA10/AC10*100,NA()) -> #N/A
A11: 1858 | B11: 1863.287 | C11: 2714.254 | D11: 2140.78 | E11: 2079.509 | F11: 2644.17 | G11: 1468.466 | N11: =IF(ISBLANK($B11),NA(),IFERROR(SUM($B11:$B$177),NA())) -> 1301051 | O11: =IF(ISBLANK($C11),NA(),IFERROR(SUM($C11:$C$177),NA())) -> 1761990.5 | P11: =IF(ISBLANK($D11),NA(),IFERROR(SUM($D11:$D$177),NA())) -> 1809507.9 | Q11: =IFERROR(O11+P11,"") -> 3571498.3 | R11: =IFERROR(N11/Q11*100,NA()) -> 36.428717 | S11: =IFERROR(O11/Q11*100,NA()) -> 49.334769 | T11: =IF(ISBLANK($E11),NA(),IFERROR(SUM($E11:$E$177),NA())) -> 1237958.8 | U11: =IF(ISBLANK($F11),NA(),IFERROR(SUM($F11:$F$177),NA())) -> 1598801.4 | V11: =IF(ISBLANK($G11),NA(),IFERROR(SUM($G11:$G$177),NA())) -> 1544822.2 | W11: =IFERROR(U11+V11,"") -> 3143623.6 | X11: =IFERROR(T11/W11*100,NA()) -> 39.379994 | Y11: =IFERROR(U11/W11*100,NA()) -> 50.85855 | Z11: =IF(ISBLANK($H11),NA(),IFERROR(SUM($H11:$H$177),NA())) -> #N/A | AA11: =IF(ISBLANK($I11),NA(),IFERROR(SUM($I11:$I$177),NA())) -> #N/A | AB11: =IF(ISBLANK($J11),NA(),IFERROR(SUM($J11:$J$177),NA())) -> #N/A | AC11: =IFERROR(AA11+AB11,"") | AD11: =IFERROR(Z11/AC11*100,NA()) -> #N/A | AE11: =IFERROR(AA11/AC11*100,NA()) -> #N/A
A12: 1859 | B12: 1914.287 | C12: 2773.463 | D12: 2152.288 | E12: 2125.918 | F12: 2693.616 | G12: 1466.165 | N12: =IF(ISBLANK($B12),NA(),IFERROR(SUM($B12:$B$177),NA())) -> 1299187.7 | O12: =IF(ISBLANK($C12),NA(),IFERROR(SUM($C12:$C$177),NA())) -> 1759276.2 | P12: =IF(ISBLANK($D12),NA(),IFERROR(SUM($D12:$D$177),NA())) -> 1807367.1 | Q12: =IFERROR(O12+P12,"") -> 3566643.3 | R12: =IFERROR(N12/Q12*100,NA()) -> 36.426063 | S12: =IFERROR(O12/Q12*100,NA()) -> 49.325824 | T12: =IF(ISBLANK($E12),NA(),IFERROR(SUM($E12:$E$177),NA())) -> 1235879.3 | U12: =IF(ISBLANK($F12),NA(),IFERROR(SUM($F12:$F$177),NA())) -> 1596157.2 | V12: =IF(ISBLANK($G12),NA(),IFERROR(SUM($G12:$G$177),NA())) -> 1543353.8 | W12: =IFERROR(U12+V12,"") -> 3139511 | X12: =IFERROR(T12/W12*100,NA()) -> 39.365343 | Y12: =IFERROR(U12/W12*100,NA()) -> 50.840951 | Z12: =IF(ISBLANK($H12),NA(),IFERROR(SUM($H12:$H$177),NA())) -> #N/A | AA12: =IF(ISBLANK($I12),NA(),IFERROR(SUM($I12:$I$177),NA())) -> #N/A | AB12: =IF(ISBLANK($J12),NA(),IFERROR(SUM($J12:$J$177),NA())) -> #N/A | AC12: =IFERROR(AA12+AB12,"") | AD12: =IFERROR(Z12/AC12*100,NA()) -> #N/A | AE12: =IFERROR(AA12/AC12*100,NA()) -> #N/A
A13: 1860 | B13: 1891.387 | C13: 2720.11 | D13: 1986.999 | E13: 2184.927 | F13: 2756.895 | G13: 1462.833 | N13: =IF(ISBLANK($B13),NA(),IFERROR(SUM($B13:$B$177),NA())) -> 1297273.4 | O13: =IF(ISBLANK($C13),NA(),IFERROR(SUM($C13:$C$177),NA())) -> 1756502.7 | P13: =IF(ISBLANK($D13),NA(),IFERROR(SUM($D13:$D$177),NA())) -> 1805214.8 | Q13: =IFERROR(O13+P13,"") -> 3561717.5 | R13: =IFERROR(N13/Q13*100,NA()) -> 36.422693 | S13: =IFERROR(O13/Q13*100,NA()) -> 49.316172 | T13: =IF(ISBLANK($E13),NA(),IFERROR(SUM($E13:$E$177),NA())) -> 1233753.4 | U13: =IF(ISBLANK($F13),NA(),IFERROR(SUM($F13:$F$177),NA())) -> 1593463.6 | V13: =IF(ISBLANK($G13),NA(),IFERROR(SUM($G13:$G$177),NA())) -> 1541887.6 | W13: =IFERROR(U13+V13,"") -> 3135351.2 | X13: =IFERROR(T13/W13*100,NA()) -> 39.349766 | Y13: =IFERROR(U13/W13*100,NA()) -> 50.822492 | Z13: =IF(ISBLANK($H13),NA(),IFERROR(SUM($H13:$H$177),NA())) -> #N/A | AA13: =IF(ISBLANK($I13),NA(),IFERROR(SUM($I13:$I$177),NA())) -> #N/A | AB13: =IF(ISBLANK($J13),NA(),IFERROR(SUM($J13:$J$177),NA())) -> #N/A | AC13: =IFERROR(AA13+AB13,"") | AD13: =IFERROR(Z13/AC13*100,NA()) -> #N/A | AE13: =IFERROR(AA13/AC13*100,NA()) -> #N/A
A14: 1861 | B14: 1845.785 | C14: 2678.775 | D14: 1924.65 | E14: 2225.877 | F14: 2814.954 | G14: 1471.184 | N14: =IF(ISBLANK($B14),NA(),IFERROR(SUM($B14:$B$177),NA())) -> 1295382.1 | O14: =IF(ISBLANK($C14),NA(),IFERROR(SUM($C14:$C$177),NA())) -> 1753782.6 | P14: =IF(ISBLANK($D14),NA(),IFERROR(SUM($D14:$D$177),NA())) -> 1803227.8 | Q14: =IFERROR(O14+P14,"") -> 3557010.4 | R14: =IFERROR(N14/Q14*100,NA()) -> 36.417719 | S14: =IFERROR(O14/Q14*100,NA()) -> 49.304962 | T14: =IF(ISBLANK($E14),NA(),IFERROR(SUM($E14:$E$177),NA())) -> 1231568.4 | U14: =IF(ISBLANK($F14),NA(),IFERROR(SUM($F14:$F$177),NA())) -> 1590706.7 | V14: =IF(ISBLANK($G14),NA(),IFERROR(SUM($G14:$G$177),NA())) -> 1540424.8 | W14: =IFERROR(U14+V14,"") -> 3131131.5 | X14: =IFERROR(T14/W14*100,NA()) -> 39.333015 | Y14: =IFERROR(U14/W14*100,NA()) -> 50.802936 | Z14: =IF(ISBLANK($H14),NA(),IFERROR(SUM($H14:$H$177),NA())) -> #N/A | AA14: =IF(ISBLANK($I14),NA(),IFERROR(SUM($I14:$I$177),NA())) -> #N/A | AB14: =IF(ISBLANK($J14),NA(),IFERROR(SUM($J14:$J$177),NA())) -> #N/A | AC14: =IFERROR(AA14+AB14,"") | AD14: =IFERROR(Z14/AC14*100,NA()) -> #N/A | AE14: =IFERROR(AA14/AC14*100,NA()) -> #N/A
... A142: 1989 | B142: 13065.592 | C142: 19183.046 | D142: 17926.701 | E142: 13533.435 | F142: 19784.856 | G142: 18507.54 | N142: =IF(ISBLANK($B142),NA(),IFERROR(SUM($B142:$B$177),NA())) -> 482434 | O142: =IF(ISBLANK($C142),NA(),IFERROR(SUM($C142:$C$177),NA())) -> 638580.62 | P142: =IF(ISBLANK($D142),NA(),IFERROR(SUM($D142:$D$177),NA())) -> 1013330.3 | Q142: =IFERROR(O142+P142,"") -> 1651910.9 | R142: =IFERROR(N142/Q142*100,NA()) -> 29.204601 | S142: =IFERROR(O142/Q142*100,NA()) -> 38.657086 | T142: =IF(ISBLANK($E142),NA(),IFERROR(SUM($E142:$E$177),NA())) -> 439746.07 | U142: =IF(ISBLANK($F142),NA(),IFERROR(SUM($F142:$F$177),NA())) -> 533667.8 | V142: =IF(ISBLANK($G142),NA(),IFERROR(SUM($G142:$G$177),NA())) -> 827437.01 | W142: =IFERROR(U142+V142,"") -> 1361104.8 | X142: =IFERROR(T142/W142*100,NA()) -> 32.308024 | Y142: =IFERROR(U142/W142*100,NA()) -> 39.208428 | Z142: =IF(ISBLANK($H142),NA(),IFERROR(SUM($H142:$H$177),NA())) -> #N/A | AA142: =IF(ISBLANK($I142),NA(),IFERROR(SUM($I142:$I$177),NA())) -> #N/A | AB142: =IF(ISBLANK($J142),NA(),IFERROR(SUM($J142:$J$177),NA())) -> #N/A | AC142: =IFERROR(AA142+AB142,"") | AD142: =IFERROR(Z142/AC142*100,NA()) -> #N/A | AE142: =IFERROR(AA142/AC142*100,NA()) -> #N/A
A143: 1990 | B143: 13567.904 | C143: 19712.12 | D143: 17852.914 | E143: 12359.764 | F143: 17237.502 | G143: 15440.382 | H143: 12677.704 | I143: 17381.157 | J143: 15878.309 | N143: =IF(ISBLANK($B143),NA(),IFERROR(SUM($B143:$B$177),NA())) -> 469368.41 | O143: =IF(ISBLANK($C143),NA(),IFERROR(SUM($C143:$C$177),NA())) -> 619397.58 | P143: =IF(ISBLANK($D143),NA(),IFERROR(SUM($D143:$D$177),NA())) -> 995403.59 | Q143: =IFERROR(O143+P143,"") -> 1614801.2 | R143: =IFERROR(N143/Q143*100,NA()) -> 29.066638 | S143: =IFERROR(O143/Q143*100,NA()) -> 38.357514 | T143: =IF(ISBLANK($E143),NA(),IFERROR(SUM($E143:$E$177),NA())) -> 426212.63 | U143: =IF(ISBLANK($F143),NA(),IFERROR(SUM($F143:$F$177),NA())) -> 513882.94 | V143: =IF(ISBLANK($G143),NA(),IFERROR(SUM($G143:$G$177),NA())) -> 808929.47 | W143: =IFERROR(U143+V143,"") -> 1322812.4 | X143: =IFERROR(T143/W143*100,NA()) -> 32.220187 | Y143: =IFERROR(U143/W143*100,NA()) -> 38.847756 | Z143: =IF(ISBLANK($H143),NA(),IFERROR(SUM($H143:$H$177),NA())) -> 445567.69 | AA143: =IF(ISBLANK($I143),NA(),IFERROR(SUM($I143:$I$177),NA())) -> 540709.39 | AB143: =IF(ISBLANK($J143),NA(),IFERROR(SUM($J143:$J$177),NA())) -> 959906.41 | AC143: =IFERROR(AA143+AB143,"") -> 1500615.8 | AD143: =IFERROR(Z143/AC143*100,NA()) -> 29.692323 | AE143: =IFERROR(AA143/AC143*100,NA()) -> 36.0325
A144: 1991 | B144: 13491.061 | C144: 19277.761 | D144: 18603.04 | E144: 12198.771 | F144: 16499.663 | G144: 16181.271 | H144: 12564.093 | I144: 17090.047 | J144: 16159.589 | N144: =IF(ISBLANK($B144),NA(),IFERROR(SUM($B144:$B$177),NA())) -> 455800.5 | O144: =IF(ISBLANK($C144),NA(),IFERROR(SUM($C144:$C$177),NA())) -> 599685.46 | P144: =IF(ISBLANK($D144),NA(),IFERROR(SUM($D144:$D$177),NA())) -> 977550.67 | Q144: =IFERROR(O144+P144,"") -> 1577236.1 | R144: =IFERROR(N144/Q144*100,NA()) -> 28.898685 | S144: =IFERROR(O144/Q144*100,NA()) -> 38.021286 | T144: =IF(ISBLANK($E144),NA(),IFERROR(SUM($E144:$E$177),NA())) -> 413852.87 | U144: =IF(ISBLANK($F144),NA(),IFERROR(SUM($F144:$F$177),NA())) -> 496645.44 | V144: =IF(ISBLANK($G144),NA(),IFERROR(SUM($G144:$G$177),NA())) -> 793489.09 | W144: =IFERROR(U144+V144,"") -> 1290134.5 | X144: =IFERROR(T144/W144*100,NA()) -> 32.078272 | Y144: =IFERROR(U144/W144*100,NA()) -> 38.495632 | Z144: =IF(ISBLANK($H144),NA(),IFERROR(SUM($H144:$H$177),NA())) -> 432889.98 | AA144: =IF(ISBLANK($I144),NA(),IFERROR(SUM($I144:$I$177),NA())) -> 523328.23 | AB144: =IF(ISBLANK($J144),NA(),IFERROR(SUM($J144:$J$177),NA())) -> 944028.1 | AC144: =IFERROR(AA144+AB144,"") -> 1467356.3 | AD144: =IFERROR(Z144/AC144*100,NA()) -> 29.501354 | AE144: =IFERROR(AA144/AC144*100,NA()) -> 35.6647
A145: 1992 | B145: 13522.205 | C145: 18589.396 | D145: 18858.056 | E145: 12202.289 | F145: 15824.74 | G145: 16275.292 | H145: 12571.454 | I145: 16623.476 | J145: 16718.546 | N145: =IF(ISBLANK($B145),NA(),IFERROR(SUM($B145:$B$177),NA())) -> 442309.44 | O145: =IF(ISBLANK($C145),NA(),IFERROR(SUM($C145:$C$177),NA())) -> 580407.7 | P145: =IF(ISBLANK($D145),NA(),IFERROR(SUM($D145:$D$177),NA())) -> 958947.63 | Q145: =IFERROR(O145+P145,"") -> 1539355.3 | R145: =IFERROR(N145/Q145*100,NA()) -> 28.733421 | S145: =IFERROR(O145/Q145*100,NA()) -> 37.704595 | T145: =IF(ISBLANK($E145),NA(),IFERROR(SUM($E145:$E$177),NA())) -> 401654.1 | U145: =IF(ISBLANK($F145),NA(),IFERROR(SUM($F145:$F$177),NA())) -> 480145.78 | V145: =IF(ISBLANK($G145),NA(),IFERROR(SUM($G145:$G$177),NA())) -> 777307.82 | W145: =IFERROR(U145+V145,"") -> 1257453.6 | X145: =IFERROR(T145/W145*100,NA()) -> 31.941862 | Y145: =IFERROR(U145/W145*100,NA()) -> 38.183976 | Z145: =IF(ISBLANK($H145),NA(),IFERROR(SUM($H145:$H$177),NA())) -> 420325.89 | AA145: =IF(ISBLANK($I145),NA(),IFERROR(SUM($I145:$I$177),NA())) -> 506238.19 | AB145: =IF(ISBLANK($J145),NA(),IFERROR(SUM($J145:$J$177),NA())) -> 927868.51 | AC145: =IFERROR(AA145+AB145,"") -> 1434106.7 | AD145: =IFERROR(Z145/AC145*100,NA()) -> 29.309248 | AE145: =IFERROR(AA145/AC145*100,NA()) -> 35.299897
A146: 1993 | B146: 13522.06 | C146: 18278.926 | D146: 19139.017 | E146: 12223.611 | F146: 15433.86 | G146: 16683.197 | H146: 13038.341 | I146: 16492.651 | J146: 17492.782 | N146: =IF(ISBLANK($B146),NA(),IFERROR(SUM($B146:$B$177),NA())) -> 428787.24 | O146: =IF(ISBLANK($C146),NA(),IFERROR(SUM($C146:$C$177),NA())) -> 561818.3 | P146: =IF(ISBLANK($D146),NA(),IFERROR(SUM($D146:$D$177),NA())) -> 940089.58 | Q146: =IFERROR(O146+P146,"") -> 1501907.9 | R146: =IFERROR(N146/Q146*100,NA()) -> 28.549503 | S146: =IFERROR(O146/Q146*100,NA()) -> 37.406975 | T146: =IF(ISBLANK($E146),NA(),IFERROR(SUM($E146:$E$177),NA())) -> 389451.81 | U146: =IF(ISBLANK($F146),NA(),IFERROR(SUM($F146:$F$177),NA())) -> 464321.04 | V146: =IF(ISBLANK($G146),NA(),IFERROR(SUM($G146:$G$177),NA())) -> 761032.52 | W146: =IFERROR(U146+V146,"") -> 1225353.6 | X146: =IFERROR(T146/W146*100,NA()) -> 31.782811 | Y146: =IFERROR(U146/W146*100,NA()) -> 37.892822 | Z146: =IF(ISBLANK($H146),NA(),IFERROR(SUM($H146:$H$177),NA())) -> 407754.44 | AA146: =IF(ISBLANK($I146),NA(),IFERROR(SUM($I146:$I$177),NA())) -> 489614.71 | AB146: =IF(ISBLANK($J146),NA(),IFERROR(SUM($J146:$J$177),NA())) -> 911149.97 | AC146: =IFERROR(AA146+AB146,"") -> 1400764.7 | AD146: =IFERROR(Z146/AC146*100,NA()) -> 29.109417 | AE146: =IFERROR(AA146/AC146*100,NA()) -> 34.953388
A147: 1994 | B147: 13674.412 | C147: 17965.23 | D147: 20691.273 | E147: 12394.957 | F147: 14986.862 | G147: 14755.968 | H147: 13069.006 | I147: 16351.016 | J147: 17613.059 | N147: =IF(ISBLANK($B147),NA(),IFERROR(SUM($B147:$B$177),NA())) -> 415265.18 | O147: =IF(ISBLANK($C147),NA(),IFERROR(SUM($C147:$C$177),NA())) -> 543539.38 | P147: =IF(ISBLANK($D147),NA(),IFERROR(SUM($D147:$D$177),NA())) -> 920950.56 | Q147: =IFERROR(O147+P147,"") -> 1464489.9 | R147: =IFERROR(N147/Q147*100,NA()) -> 28.355618 | S147: =IFERROR(O147/Q147*100,NA()) -> 37.114586 | T147: =IF(ISBLANK($E147),NA(),IFERROR(SUM($E147:$E$177),NA())) -> 377228.2 | U147: =IF(ISBLANK($F147),NA(),IFERROR(SUM($F147:$F$177),NA())) -> 448887.18 | V147: =IF(ISBLANK($G147),NA(),IFERROR(SUM($G147:$G$177),NA())) -> 744349.33 | W147: =IFERROR(U147+V147,"") -> 1193236.5 | X147: =IFERROR(T147/W147*100,NA()) -> 31.613867 | Y147: =IFERROR(U147/W147*100,NA()) -> 37.619297 | Z147: =IF(ISBLANK($H147),NA(),IFERROR(SUM($H147:$H$177),NA())) -> 394716.1 | AA147: =IF(ISBLANK($I147),NA(),IFERROR(SUM($I147:$I$177),NA())) -> 473122.06 | AB147: =IF(ISBLANK($J147),NA(),IFERROR(SUM($J147:$J$177),NA())) -> 893657.19 | AC147: =IFERROR(AA147+AB147,"") -> 1366779.2 | AD147: =IFERROR(Z147/AC147*100,NA()) -> 28.879287 | AE147: =IFERROR(AA147/AC147*100,NA()) -> 34.615836
A148: 1995 | B148: 13839.908 | C148: 17977.053 | D148: 20947.26 | E148: 12565.604 | F148: 14976.334 | G148: 16035.243 | H148: 13287.949 | I148: 16518.199 | J148: 18504.829 | N148: =IF(ISBLANK($B148),NA(),IFERROR(SUM($B148:$B$177),NA())) -> 401590.76 | O148: =IF(ISBLANK($C148),NA(),IFERROR(SUM($C148:$C$177),NA())) -> 525574.15 | P148: =IF(ISBLANK($D148),NA(),IFERROR(SUM($D148:$D$177),NA())) -> 900259.29 | Q148: =IFERROR(O148+P148,"") -> 1425833.4 | R148: =IFERROR(N148/Q148*100,NA()) -> 28.165335 | S148: =IFERROR(O148/Q148*100,NA()) -> 36.860838 | T148: =IF(ISBLANK($E148),NA(),IFERROR(SUM($E148:$E$177),NA())) -> 364833.24 | U148: =IF(ISBLANK($F148),NA(),IFERROR(SUM($F148:$F$177),NA())) -> 433900.32 | V148: =IF(ISBLANK($G148),NA(),IFERROR(SUM($G148:$G$177),NA())) -> 729593.36 | W148: =IFERROR(U148+V148,"") -> 1163493.7 | X148: =IFERROR(T148/W148*100,NA()) -> 31.356702 | Y148: =IFERROR(U148/W148*100,NA()) -> 37.292881 | Z148: =IF(ISBLANK($H148),NA(),IFERROR(SUM($H148:$H$177),NA())) -> 381647.09 | AA148: =IF(ISBLANK($I148),NA(),IFERROR(SUM($I148:$I$177),NA())) -> 456771.04 | AB148: =IF(ISBLANK($J148),NA(),IFERROR(SUM($J148:$J$177),NA())) -> 876044.13 | AC148: =IFERROR(AA148+AB148,"") -> 1332815.2 | AD148: =IFERROR(Z148/AC148*100,NA()) -> 28.63466 | AE148: =IFERROR(AA148/AC148*100,NA()) -> 34.271147
A149: 1996 | B149: 14139.195 | C149: 18597.606 | D149: 21390.793 | E149: 12825.447 | F149: 15432.814 | G149: 15886.051 | H149: 13179.138 | I149: 16113.56 | J149: 18908.149 | N149: =IF(ISBLANK($B149),NA(),IFERROR(SUM($B149:$B$177),NA())) -> 387750.86 | O149: =IF(ISBLANK($C149),NA(),IFERROR(SUM($C149:$C$177),NA())) -> 507597.09 | P149: =IF(ISBLANK($D149),NA(),IFERROR(SUM($D149:$D$177),NA())) -> 879312.03 | Q149: =IFERROR(O149+P149,"") -> 1386909.1 | R149: =IFERROR(N149/Q149*100,NA()) -> 27.957914 | S149: =IFERROR(O149/Q149*100,NA()) -> 36.59916 | T149: =IF(ISBLANK($E149),NA(),IFERROR(SUM($E149:$E$177),NA())) -> 352267.64 | U149: =IF(ISBLANK($F149),NA(),IFERROR(SUM($F149:$F$177),NA())) -> 418923.98 | V149: =IF(ISBLANK($G149),NA(),IFERROR(SUM($G149:$G$177),NA())) -> 713558.11 | W149: =IFERROR(U149+V149,"") -> 1132482.1 | X149: =IFERROR(T149/W149*100,NA()) -> 31.105802 | Y149: =IFERROR(U149/W149*100,NA()) -> 36.991665 | Z149: =IF(ISBLANK($H149),NA(),IFERROR(SUM($H149:$H$177),NA())) -> 368359.14 | AA149: =IF(ISBLANK($I149),NA(),IFERROR(SUM($I149:$I$177),NA())) -> 440252.85 | AB149: =IF(ISBLANK($J149),NA(),IFERROR(SUM($J149:$J$177),NA())) -> 857539.3 | AC149: =IFERROR(AA149+AB149,"") -> 1297792.1 | AD149: =IFERROR(Z149/AC149*100,NA()) -> 28.383524 | AE149: =IFERROR(AA149/AC149*100,NA()) -> 33.923217
A150: 1997 | B150: 14059.181 | C150: 17971.185 | D150: 23539.389 | E150: 12841.267 | F150: 15041.124 | G150: 15774.951 | H150: 13241.811 | I150: 15891.883 | J150: 18297.174 | N150: =IF(ISBLANK($B150),NA(),IFERROR(SUM($B150:$B$177),NA())) -> 373611.66 | O150: =IF(ISBLANK($C150),NA(),IFERROR(SUM($C150:$C$177),NA())) -> 488999.49 | P150: =IF(ISBLANK($D150),NA(),IFERROR(SUM($D150:$D$177),NA())) -> 857921.23 | Q150: =IFERROR(O150+P150,"") -> 1346920.7 | R150: =IFERROR(N150/Q150*100,NA()) -> 27.738207 | S150: =IFERROR(O150/Q150*100,NA()) -> 36.304994 | T150: =IF(ISBLANK($E150),NA(),IFERROR(SUM($E150:$E$177),NA())) -> 339442.19 | U150: =IF(ISBLANK($F150),NA(),IFERROR(SUM($F150:$F$177),NA())) -> 403491.17 | V150: =IF(ISBLANK($G150),NA(),IFERROR(SUM($G150:$G$177),NA())) -> 697672.06 | W150: =IFERROR(U150+V150,"") -> 1101163.2 | X150: =IFERROR(T150/W150*100,NA()) -> 30.825783 | Y150: =IFERROR(U150/W150*100,NA()) -> 36.642267 | Z150: =IF(ISBLANK($H150),NA(),IFERROR(SUM($H150:$H$177),NA())) -> 355180 | AA150: =IF(ISBLANK($I150),NA(),IFERROR(SUM($I150:$I$177),NA())) -> 424139.29 | AB150: =IF(ISBLANK($J150),NA(),IFERROR(SUM($J150:$J$177),NA())) -> 838631.15 | AC150: =IFERROR(AA150+AB150,"") -> 1262770.4 | AD150: =IFERROR(Z150/AC150*100,NA()) -> 28.127045 | AE150: =IFERROR(AA150/AC150*100,NA()) -> 33.587996
A151: 1998 | B151: 14144.731 | C151: 17979.267 | D151: 22144.786 | E151: 12865.704 | F151: 15244.956 | G151: 16165.741 | H151: 13862.612 | I151: 15990.967 | J151: 19706.054 | N151: =IF(ISBLANK($B151),NA(),IFERROR(SUM($B151:$B$177),NA())) -> 359552.48 | O151: =IF(ISBLANK($C151),NA(),IFERROR(SUM($C151:$C$177),NA())) -> 471028.3 | P151: =IF(ISBLANK($D151),NA(),IFERROR(SUM($D151:$D$177),NA())) -> 834381.85 | Q151: =IFERROR(O151+P151,"") -> 1305410.1 | R151: =IFERROR(N151/Q151*100,NA()) -> 27.543258 | S151: =IFERROR(O151/Q151*100,NA()) -> 36.082782 | T151: =IF(ISBLANK($E151),NA(),IFERROR(SUM($E151:$E$177),NA())) -> 326600.92 | U151: =IF(ISBLANK($F151),NA(),IFERROR(SUM($F151:$F$177),NA())) -> 388450.05 | V151: =IF(ISBLANK($G151),NA(),IFERROR(SUM($G151:$G$177),NA())) -> 681897.11 | W151: =IFERROR(U151+V151,"") -> 1070347.2 | X151: =IFERROR(T151/W151*100,NA()) -> 30.513551 | Y151: =IFERROR(U151/W151*100,NA()) -> 36.291968 | Z151: =IF(ISBLANK($H151),NA(),IFERROR(SUM($H151:$H$177),NA())) -> 341938.19 | AA151: =IF(ISBLANK($I151),NA(),IFERROR(SUM($I151:$I$177),NA())) -> 408247.4 | AB151: =IF(ISBLANK($J151),NA(),IFERROR(SUM($J151:$J$177),NA())) -> 820333.97 | AC151: =IFERROR(AA151+AB151,"") -> 1228581.4 | AD151: =IFERROR(Z151/AC151*100,NA()) -> 27.831953 | AE151: =IFERROR(AA151/AC151*100,NA()) -> 33.229171
A152: 1999 | B152: 14247.845 | C152: 18043.091 | D152: 22401.091 | E152: 12956.491 | F152: 14902.096 | G152: 16551.744 | H152: 13778.123 | I152: 16395.072 | J152: 19888.217 | N152: =IF(ISBLANK($B152),NA(),IFERROR(SUM($B152:$B$177),NA())) -> 345407.75 | O152: =IF(ISBLANK($C152),NA(),IFERROR(SUM($C152:$C$177),NA())) -> 453049.03 | P152: =IF(ISBLANK($D152),NA(),IFERROR(SUM($D152:$D$177),NA())) -> 812237.06 | Q152: =IFERROR(O152+P152,"") -> 1265286.1 | R152: =IFERROR(N152/Q152*100,NA()) -> 27.298786 | S152: =IFERROR(O152/Q152*100,NA()) -> 35.806055 | T152: =IF(ISBLANK($E152),NA(),IFERROR(SUM($E152:$E$177),NA())) -> 313735.22 | U152: =IF(ISBLANK($F152),NA(),IFERROR(SUM($F152:$F$177),NA())) -> 373205.09 | V152: =IF(ISBLANK($G152),NA(),IFERROR(SUM($G152:$G$177),NA())) -> 665731.37 | W152: =IFERROR(U152+V152,"") -> 1038936.5 | X152: =IFERROR(T152/W152*100,NA()) -> 30.197729 | Y152: =IFERROR(U152/W152*100,NA()) -> 35.92184 | Z152: =IF(ISBLANK($H152),NA(),IFERROR(SUM($H152:$H$177),NA())) -> 328075.58 | AA152: =IF(ISBLANK($I152),NA(),IFERROR(SUM($I152:$I$177),NA())) -> 392256.43 | AB152: =IF(ISBLANK($J152),NA(),IFERROR(SUM($J152:$J$177),NA())) -> 800627.92 | AC152: =IFERROR(AA152+AB152,"") -> 1192884.4 | AD152: =IFERROR(Z152/AC152*100,NA()) -> 27.502715 | AE152: =IFERROR(AA152/AC152*100,NA()) -> 32.883023
A153: 2000 | B153: 14590.567 | C153: 18264.278 | D153: 22515.535 | E153: 13262.195 | F153: 15297.981 | G153: 16364.483 | H153: 14301.141 | I153: 17278.166 | J153: 21094.417 | N153: =IF(ISBLANK($B153),NA(),IFERROR(SUM($B153:$B$177),NA())) -> 331159.9 | O153: =IF(ISBLANK($C153),NA(),IFERROR(SUM($C153:$C$177),NA())) -> 435005.94 | P153: =IF(ISBLANK($D153),NA(),IFERROR(SUM($D153:$D$177),NA())) -> 789835.97 | Q153: =IFERROR(O153+P153,"") -> 1224841.9 | R153: =IFERROR(N153/Q153*100,NA()) -> 27.036951 | S153: =IFERROR(O153/Q153*100,NA()) -> 35.515273 | T153: =IF(ISBLANK($E153),NA(),IFERROR(SUM($E153:$E$177),NA())) -> 300778.73 | U153: =IF(ISBLANK($F153),NA(),IFERROR(SUM($F153:$F$177),NA())) -> 358302.99 | V153: =IF(ISBLANK($G153),NA(),IFERROR(SUM($G153:$G$177),NA())) -> 649179.63 | W153: =IFERROR(U153+V153,"") -> 1007482.6 | X153: =IFERROR(T153/W153*100,NA()) -> 29.854483 | Y153: =IFERROR(U153/W153*100,NA()) -> 35.564186 | Z153: =IF(ISBLANK($H153),NA(),IFERROR(SUM($H153:$H$177),NA())) -> 314297.46 | AA153: =IF(ISBLANK($I153),NA(),IFERROR(SUM($I153:$I$177),NA())) -> 375861.36 | AB153: =IF(ISBLANK($J153),NA(),IFERROR(SUM($J153:$J$177),NA())) -> 780739.7 | AC153: =IFERROR(AA153+AB153,"") -> 1156601.1 | AD153: =IFERROR(Z153/AC153*100,NA()) -> 27.174232 | AE153: =IFERROR(AA153/AC153*100,NA()) -> 32.497062
A154: 2001 | B154: 14331.77 | C154: 18038.996 | D154: 22204.716 | E154: 13092.569 | F154: 15079.125 | G154: 16773.487 | H154: 14158.627 | I154: 16597.361 | J154: 21366.234 | N154: =IF(ISBLANK($B154),NA(),IFERROR(SUM($B154:$B$177),NA())) -> 316569.34 | O154: =IF(ISBLANK($C154),NA(),IFERROR(SUM($C154:$C$177),NA())) -> 416741.67 | P154: =IF(ISBLANK($D154),NA(),IFERROR(SUM($D154:$D$177),NA())) -> 767320.43 | Q154: =IFERROR(O154+P154,"") -> 1184062.1 | R154: =IFERROR(N154/Q154*100,NA()) -> 26.735873 | S154: =IFERROR(O154/Q154*100,NA()) -> 35.19593 | T154: =IF(ISBLANK($E154),NA(),IFERROR(SUM($E154:$E$177),NA())) -> 287516.53 | U154: =IF(ISBLANK($F154),NA(),IFERROR(SUM($F154:$F$177),NA())) -> 343005.01 | V154: =IF(ISBLANK($G154),NA(),IFERROR(SUM($G154:$G$177),NA())) -> 632815.15 | W154: =IFERROR(U154+V154,"") -> 975820.16 | X154: =IFERROR(T154/W154*100,NA()) -> 29.46409 | Y154: =IFERROR(U154/W154*100,NA()) -> 35.150433 | Z154: =IF(ISBLANK($H154),NA(),IFERROR(SUM($H154:$H$177),NA())) -> 299996.32 | AA154: =IF(ISBLANK($I154),NA(),IFERROR(SUM($I154:$I$177),NA())) -> 358583.2 | AB154: =IF(ISBLANK($J154),NA(),IFERROR(SUM($J154:$J$177),NA())) -> 759645.29 | AC154: =IFERROR(AA154+AB154,"") -> 1118228.5 | AD154: =IFERROR(Z154/AC154*100,NA()) -> 26.827819 | AE154: =IFERROR(AA154/AC154*100,NA()) -> 32.067078
... A177: 2024 | B177: 11369.645 | C177: 15810.797 | D177: 38602.845 | E177: 8641.151 | F177: 11449.105 | G177: 24074.701 | H177: 10627.385 | I177: 13166.136 | J177: 39545.381 | N177: =IF(ISBLANK($B177),NA(),IFERROR(SUM($B177:$B$177),NA())) -> 11369.645 | O177: =IF(ISBLANK($C177),NA(),IFERROR(SUM($C177:$C$177),NA())) -> 15810.797 | P177: =IF(ISBLANK($D177),NA(),IFERROR(SUM($D177:$D$177),NA())) -> 38602.845 | Q177: =IFERROR(O177+P177,"") -> 54413.642 | R177: =IFERROR(N177/Q177*100,NA()) -> 20.894843 | S177: =IFERROR(O177/Q177*100,NA()) -> 29.056678 | T177: =IF(ISBLANK($E177),NA(),IFERROR(SUM($E177:$E$177),NA())) -> 8641.151 | U177: =IF(ISBLANK($F177),NA(),IFERROR(SUM($F177:$F$177),NA())) -> 11449.105 | V177: =IF(ISBLANK($G177),NA(),IFERROR(SUM($G177:$G$177),NA())) -> 24074.701 | W177: =IFERROR(U177+V177,"") -> 35523.806 | X177: =IFERROR(T177/W177*100,NA()) -> 24.324958 | Y177: =IFERROR(U177/W177*100,NA()) -> 32.229387 | Z177: =IF(ISBLANK($H177),NA(),IFERROR(SUM($H177:$H$177),NA())) -> 10627.385 | AA177: =IF(ISBLANK($I177),NA(),IFERROR(SUM($I177:$I$177),NA())) -> 13166.136 | AB177: =IF(ISBLANK($J177),NA(),IFERROR(SUM($J177:$J$177),NA())) -> 39545.381 | AC177: =IFERROR(AA177+AB177,"") -> 52711.517 | AD177: =IFERROR(Z177/AC177*100,NA()) -> 20.16141 | AE177: =IFERROR(AA177/AC177*100,NA()) -> 24.977722

Sheet GHG incl LULUCF

Sheet data_ghg_incLUC
A1: Cumulative GHG emissions including LULUCF to 2024, different start points
A2: Year | B2: AII_Min | C2: AII_Max | D2: AI_Min | E2: AI_Max | F2: Pure_AII | G2: Overlap | H2: AI_Gap | I2: pct_annex2_OWID | J2: pct_annex2_PRIMAP | K2: pct_annex2_EDGAR | M2: pct_annex1_OWID | N2: pct_annex1_PRIMAP | O2: pct_annex1_EDGAR | Q2: Pure_AI | R2: Annex II GMST | S2: Annex I GMST
A3: =vals_ghg_incLUC!$A3 -> 1850 | B3: =IFERROR(_xlfn.AGGREGATE(5,6,I3:L3),"") -> 36.435552 | C3: =IFERROR(_xlfn.AGGREGATE(4,6,I3:L3),"") -> 39.454285 | D3: =IFERROR(_xlfn.AGGREGATE(5,6,M3:P3),"") -> 49.389956 | E3: =IFERROR(_xlfn.AGGREGATE(4,6,M3:P3),"") -> 50.956621 | F3: =IFERROR(MIN(C3,D3)-B3,"") -> 3.0187333 | G3: =IFERROR(MAX(0,C3-D3),"") -> 0 | H3: =IFERROR(MAX(0,D3-C3),"") -> 9.9356706 | I3: =vals_ghg_incLUC!$R3 -> 36.435552 | J3: =vals_ghg_incLUC!$X3 -> 39.454285 | K3: =vals_ghg_incLUC!$AD3 -> #N/A | M3: =vals_ghg_incLUC!$S3 -> 49.389956 | N3: =vals_ghg_incLUC!$Y3 -> 50.956621 | O3: =vals_ghg_incLUC!$AE3 -> #N/A | Q3: =IFERROR(MAX(0,$E3-MAX($C3,$D3)),"") -> 1.5666652 | R3: 34.289 | S3: 46.369
A4: =vals_ghg_incLUC!$A4 -> 1851 | B4: =IFERROR(_xlfn.AGGREGATE(5,6,I4:L4),"") -> 36.43593 | C4: =IFERROR(_xlfn.AGGREGATE(4,6,I4:L4),"") -> 39.45187 | D4: =IFERROR(_xlfn.AGGREGATE(5,6,M4:P4),"") -> 49.384257 | E4: =IFERROR(_xlfn.AGGREGATE(4,6,M4:P4),"") -> 50.95095 | F4: =IFERROR(MIN(C4,D4)-B4,"") -> 3.0159397 | G4: =IFERROR(MAX(0,C4-D4),"") -> 0 | H4: =IFERROR(MAX(0,D4-C4),"") -> 9.9323868 | I4: =vals_ghg_incLUC!$R4 -> 36.43593 | J4: =vals_ghg_incLUC!$X4 -> 39.45187 | K4: =vals_ghg_incLUC!$AD4 -> #N/A | M4: =vals_ghg_incLUC!$S4 -> 49.384257 | N4: =vals_ghg_incLUC!$Y4 -> 50.95095 | O4: =vals_ghg_incLUC!$AE4 -> #N/A | Q4: =IFERROR(MAX(0,$E4-MAX($C4,$D4)),"") -> 1.5666933 | R4: 34.289 | S4: 46.369
A5: =vals_ghg_incLUC!$A5 -> 1852 | B5: =IFERROR(_xlfn.AGGREGATE(5,6,I5:L5),"") -> 36.436122 | C5: =IFERROR(_xlfn.AGGREGATE(4,6,I5:L5),"") -> 39.448873 | D5: =IFERROR(_xlfn.AGGREGATE(5,6,M5:P5),"") -> 49.378731 | E5: =IFERROR(_xlfn.AGGREGATE(4,6,M5:P5),"") -> 50.944532 | F5: =IFERROR(MIN(C5,D5)-B5,"") -> 3.0127504 | G5: =IFERROR(MAX(0,C5-D5),"") -> 0 | H5: =IFERROR(MAX(0,D5-C5),"") -> 9.9298581 | I5: =vals_ghg_incLUC!$R5 -> 36.436122 | J5: =vals_ghg_incLUC!$X5 -> 39.448873 | K5: =vals_ghg_incLUC!$AD5 -> #N/A | M5: =vals_ghg_incLUC!$S5 -> 49.378731 | N5: =vals_ghg_incLUC!$Y5 -> 50.944532 | O5: =vals_ghg_incLUC!$AE5 -> #N/A | Q5: =IFERROR(MAX(0,$E5-MAX($C5,$D5)),"") -> 1.5658014 | R5: 34.283 | S5: 46.356
A6: =vals_ghg_incLUC!$A6 -> 1853 | B6: =IFERROR(_xlfn.AGGREGATE(5,6,I6:L6),"") -> 36.43661 | C6: =IFERROR(_xlfn.AGGREGATE(4,6,I6:L6),"") -> 39.440696 | D6: =IFERROR(_xlfn.AGGREGATE(5,6,M6:P6),"") -> 49.372795 | E6: =IFERROR(_xlfn.AGGREGATE(4,6,M6:P6),"") -> 50.933605 | F6: =IFERROR(MIN(C6,D6)-B6,"") -> 3.004086 | G6: =IFERROR(MAX(0,C6-D6),"") -> 0 | H6: =IFERROR(MAX(0,D6-C6),"") -> 9.932099 | I6: =vals_ghg_incLUC!$R6 -> 36.43661 | J6: =vals_ghg_incLUC!$X6 -> 39.440696 | K6: =vals_ghg_incLUC!$AD6 -> #N/A | M6: =vals_ghg_incLUC!$S6 -> 49.372795 | N6: =vals_ghg_incLUC!$Y6 -> 50.933605 | O6: =vals_ghg_incLUC!$AE6 -> #N/A | Q6: =IFERROR(MAX(0,$E6-MAX($C6,$D6)),"") -> 1.5608094 | R6: 34.278 | S6: 46.342
A7: =vals_ghg_incLUC!$A7 -> 1854 | B7: =IFERROR(_xlfn.AGGREGATE(5,6,I7:L7),"") -> 36.436022 | C7: =IFERROR(_xlfn.AGGREGATE(4,6,I7:L7),"") -> 39.431261 | D7: =IFERROR(_xlfn.AGGREGATE(5,6,M7:P7),"") -> 49.366575 | E7: =IFERROR(_xlfn.AGGREGATE(4,6,M7:P7),"") -> 50.921346 | F7: =IFERROR(MIN(C7,D7)-B7,"") -> 2.9952392 | G7: =IFERROR(MAX(0,C7-D7),"") -> 0 | H7: =IFERROR(MAX(0,D7-C7),"") -> 9.9353139 | I7: =vals_ghg_incLUC!$R7 -> 36.436022 | J7: =vals_ghg_incLUC!$X7 -> 39.431261 | K7: =vals_ghg_incLUC!$AD7 -> #N/A | M7: =vals_ghg_incLUC!$S7 -> 49.366575 | N7: =vals_ghg_incLUC!$Y7 -> 50.921346 | O7: =vals_ghg_incLUC!$AE7 -> #N/A | Q7: =IFERROR(MAX(0,$E7-MAX($C7,$D7)),"") -> 1.5547703 | R7: 34.271 | S7: 46.328
A8: =vals_ghg_incLUC!$A8 -> 1855 | B8: =IFERROR(_xlfn.AGGREGATE(5,6,I8:L8),"") -> 36.434369 | C8: =IFERROR(_xlfn.AGGREGATE(4,6,I8:L8),"") -> 39.419936 | D8: =IFERROR(_xlfn.AGGREGATE(5,6,M8:P8),"") -> 49.358844 | E8: =IFERROR(_xlfn.AGGREGATE(4,6,M8:P8),"") -> 50.907227 | F8: =IFERROR(MIN(C8,D8)-B8,"") -> 2.9855671 | G8: =IFERROR(MAX(0,C8-D8),"") -> 0 | H8: =IFERROR(MAX(0,D8-C8),"") -> 9.9389081 | I8: =vals_ghg_incLUC!$R8 -> 36.434369 | J8: =vals_ghg_incLUC!$X8 -> 39.419936 | K8: =vals_ghg_incLUC!$AD8 -> #N/A | M8: =vals_ghg_incLUC!$S8 -> 49.358844 | N8: =vals_ghg_incLUC!$Y8 -> 50.907227 | O8: =vals_ghg_incLUC!$AE8 -> #N/A | Q8: =IFERROR(MAX(0,$E8-MAX($C8,$D8)),"") -> 1.5483834 | R8: 34.262 | S8: 46.311
A9: =vals_ghg_incLUC!$A9 -> 1856 | B9: =IFERROR(_xlfn.AGGREGATE(5,6,I9:L9),"") -> 36.432817 | C9: =IFERROR(_xlfn.AGGREGATE(4,6,I9:L9),"") -> 39.407491 | D9: =IFERROR(_xlfn.AGGREGATE(5,6,M9:P9),"") -> 49.351258 | E9: =IFERROR(_xlfn.AGGREGATE(4,6,M9:P9),"") -> 50.891853 | F9: =IFERROR(MIN(C9,D9)-B9,"") -> 2.9746737 | G9: =IFERROR(MAX(0,C9-D9),"") -> 0 | H9: =IFERROR(MAX(0,D9-C9),"") -> 9.943767 | I9: =vals_ghg_incLUC!$R9 -> 36.432817 | J9: =vals_ghg_incLUC!$X9 -> 39.407491 | K9: =vals_ghg_incLUC!$AD9 -> #N/A | M9: =vals_ghg_incLUC!$S9 -> 49.351258 | N9: =vals_ghg_incLUC!$Y9 -> 50.891853 | O9: =vals_ghg_incLUC!$AE9 -> #N/A | Q9: =IFERROR(MAX(0,$E9-MAX($C9,$D9)),"") -> 1.5405948 | R9: 34.254 | S9: 46.295
A10: =vals_ghg_incLUC!$A10 -> 1857 | B10: =IFERROR(_xlfn.AGGREGATE(5,6,I10:L10),"") -> 36.430832 | C10: =IFERROR(_xlfn.AGGREGATE(4,6,I10:L10),"") -> 39.394055 | D10: =IFERROR(_xlfn.AGGREGATE(5,6,M10:P10),"") -> 49.343162 | E10: =IFERROR(_xlfn.AGGREGATE(4,6,M10:P10),"") -> 50.875525 | F10: =IFERROR(MIN(C10,D10)-B10,"") -> 2.9632229 | G10: =IFERROR(MAX(0,C10-D10),"") -> 0 | H10: =IFERROR(MAX(0,D10-C10),"") -> 9.9491065 | I10: =vals_ghg_incLUC!$R10 -> 36.430832 | J10: =vals_ghg_incLUC!$X10 -> 39.394055 | K10: =vals_ghg_incLUC!$AD10 -> #N/A | M10: =vals_ghg_incLUC!$S10 -> 49.343162 | N10: =vals_ghg_incLUC!$Y10 -> 50.875525 | O10: =vals_ghg_incLUC!$AE10 -> #N/A | Q10: =IFERROR(MAX(0,$E10-MAX($C10,$D10)),"") -> 1.5323628 | R10: 34.245 | S10: 46.279
A11: =vals_ghg_incLUC!$A11 -> 1858 | B11: =IFERROR(_xlfn.AGGREGATE(5,6,I11:L11),"") -> 36.428717 | C11: =IFERROR(_xlfn.AGGREGATE(4,6,I11:L11),"") -> 39.379994 | D11: =IFERROR(_xlfn.AGGREGATE(5,6,M11:P11),"") -> 49.334769 | E11: =IFERROR(_xlfn.AGGREGATE(4,6,M11:P11),"") -> 50.85855 | F11: =IFERROR(MIN(C11,D11)-B11,"") -> 2.9512767 | G11: =IFERROR(MAX(0,C11-D11),"") -> 0 | H11: =IFERROR(MAX(0,D11-C11),"") -> 9.9547759 | I11: =vals_ghg_incLUC!$R11 -> 36.428717 | J11: =vals_ghg_incLUC!$X11 -> 39.379994 | K11: =vals_ghg_incLUC!$AD11 -> #N/A | M11: =vals_ghg_incLUC!$S11 -> 49.334769 | N11: =vals_ghg_incLUC!$Y11 -> 50.85855 | O11: =vals_ghg_incLUC!$AE11 -> #N/A | Q11: =IFERROR(MAX(0,$E11-MAX($C11,$D11)),"") -> 1.5237808 | R11: 34.235 | S11: 46.261
A12: =vals_ghg_incLUC!$A12 -> 1859 | B12: =IFERROR(_xlfn.AGGREGATE(5,6,I12:L12),"") -> 36.426063 | C12: =IFERROR(_xlfn.AGGREGATE(4,6,I12:L12),"") -> 39.365343 | D12: =IFERROR(_xlfn.AGGREGATE(5,6,M12:P12),"") -> 49.325824 | E12: =IFERROR(_xlfn.AGGREGATE(4,6,M12:P12),"") -> 50.840951 | F12: =IFERROR(MIN(C12,D12)-B12,"") -> 2.9392803 | G12: =IFERROR(MAX(0,C12-D12),"") -> 0 | H12: =IFERROR(MAX(0,D12-C12),"") -> 9.9604814 | I12: =vals_ghg_incLUC!$R12 -> 36.426063 | J12: =vals_ghg_incLUC!$X12 -> 39.365343 | K12: =vals_ghg_incLUC!$AD12 -> #N/A | M12: =vals_ghg_incLUC!$S12 -> 49.325824 | N12: =vals_ghg_incLUC!$Y12 -> 50.840951 | O12: =vals_ghg_incLUC!$AE12 -> #N/A | Q12: =IFERROR(MAX(0,$E12-MAX($C12,$D12)),"") -> 1.5151261 | R12: 34.226 | S12: 46.244
A13: =vals_ghg_incLUC!$A13 -> 1860 | B13: =IFERROR(_xlfn.AGGREGATE(5,6,I13:L13),"") -> 36.422693 | C13: =IFERROR(_xlfn.AGGREGATE(4,6,I13:L13),"") -> 39.349766 | D13: =IFERROR(_xlfn.AGGREGATE(5,6,M13:P13),"") -> 49.316172 | E13: =IFERROR(_xlfn.AGGREGATE(4,6,M13:P13),"") -> 50.822492 | F13: =IFERROR(MIN(C13,D13)-B13,"") -> 2.9270729 | G13: =IFERROR(MAX(0,C13-D13),"") -> 0 | H13: =IFERROR(MAX(0,D13-C13),"") -> 9.9664063 | I13: =vals_ghg_incLUC!$R13 -> 36.422693 | J13: =vals_ghg_incLUC!$X13 -> 39.349766 | K13: =vals_ghg_incLUC!$AD13 -> #N/A | M13: =vals_ghg_incLUC!$S13 -> 49.316172 | N13: =vals_ghg_incLUC!$Y13 -> 50.822492 | O13: =vals_ghg_incLUC!$AE13 -> #N/A | Q13: =IFERROR(MAX(0,$E13-MAX($C13,$D13)),"") -> 1.50632 | R13: 34.215 | S13: 46.225
A14: =vals_ghg_incLUC!$A14 -> 1861 | B14: =IFERROR(_xlfn.AGGREGATE(5,6,I14:L14),"") -> 36.417719 | C14: =IFERROR(_xlfn.AGGREGATE(4,6,I14:L14),"") -> 39.333015 | D14: =IFERROR(_xlfn.AGGREGATE(5,6,M14:P14),"") -> 49.304962 | E14: =IFERROR(_xlfn.AGGREGATE(4,6,M14:P14),"") -> 50.802936 | F14: =IFERROR(MIN(C14,D14)-B14,"") -> 2.9152967 | G14: =IFERROR(MAX(0,C14-D14),"") -> 0 | H14: =IFERROR(MAX(0,D14-C14),"") -> 9.9719465 | I14: =vals_ghg_incLUC!$R14 -> 36.417719 | J14: =vals_ghg_incLUC!$X14 -> 39.333015 | K14: =vals_ghg_incLUC!$AD14 -> #N/A | M14: =vals_ghg_incLUC!$S14 -> 49.304962 | N14: =vals_ghg_incLUC!$Y14 -> 50.802936 | O14: =vals_ghg_incLUC!$AE14 -> #N/A | Q14: =IFERROR(MAX(0,$E14-MAX($C14,$D14)),"") -> 1.497974 | R14: 34.203 | S14: 46.205
... A177: =vals_ghg_incLUC!$A177 -> 2024 | B177: =IFERROR(_xlfn.AGGREGATE(5,6,I177:L177),"") -> 20.16141 | C177: =IFERROR(_xlfn.AGGREGATE(4,6,I177:L177),"") -> 24.324958 | D177: =IFERROR(_xlfn.AGGREGATE(5,6,M177:P177),"") -> 24.977722 | E177: =IFERROR(_xlfn.AGGREGATE(4,6,M177:P177),"") -> 32.229387 | F177: =IFERROR(MIN(C177,D177)-B177,"") -> 4.1635484 | G177: =IFERROR(MAX(0,C177-D177),"") -> 0 | H177: =IFERROR(MAX(0,D177-C177),"") -> 0.65276335 | I177: =vals_ghg_incLUC!$R177 -> 20.894843 | J177: =vals_ghg_incLUC!$X177 -> 24.324958 | K177: =vals_ghg_incLUC!$AD177 -> 20.16141 | M177: =vals_ghg_incLUC!$S177 -> 29.056678 | N177: =vals_ghg_incLUC!$Y177 -> 32.229387 | O177: =vals_ghg_incLUC!$AE177 -> 24.977722 | Q177: =IFERROR(MAX(0,$E177-MAX($C177,$D177)),"") -> 7.2516656 | R177: 17.709 | S177: 25.975

Sheet vals_ghg_excLUC
A2: Year | B2: annex2_OWID | C2: annex1_OWID | D2: non_annex1_OWID | E2: annex2_PRIMAP | F2: annex1_PRIMAP | G2: non_annex1_PRIMAP | H2: annex2_EDGAR | I2: annex1_EDGAR | J2: non_annex1_EDGAR | K2: annex2_ClimateWatch | L2: annex1_ClimateWatch | M2: non_annex1_ClimateWatch | N2: cum_annex2_OWID | O2: cum_annex1_OWID | P2: cum_non_ann1_OWID | Q2: cum_world_OWID | R2: pct_annex2_OWID | S2: pct_annex1_OWID | T2: cum_annex2_PRIMAP | U2: cum_annex1_PRIMAP | V2: cum_non_ann1_PRIMAP | W2: cum_world_PRIMAP | X2: pct_annex2_PRIMAP | Y2: pct_annex1_PRIMAP | Z2: cum_annex2_EDGAR | AA2: cum_annex1_EDGAR | AB2: cum_non_ann1_EDGAR | AC2: cum_world_EDGAR | AD2: pct_annex2_EDGAR | AE2: pct_annex1_EDGAR | AF2: cum_annex2_ClimateWatch | AG2: cum_annex1_ClimateWatch | AH2: cum_non_ann1_ClimateWatch | AI2: cum_world_ClimateWatch | AJ2: pct_annex2_ClimateWatch | AK2: pct_annex1_ClimateWatch
A3: 1850 | B3: 375.324 | C3: 451.719 | D3: 230.605 | E3: 608.538 | F3: 805.61 | G3: 757.79 | N3: =IF(ISBLANK($B3),NA(),IFERROR(SUM($B3:$B$177),NA())) -> 1011066.5 | O3: =IF(ISBLANK($C3),NA(),IFERROR(SUM($C3:$C$177),NA())) -> 1309544.7 | P3: =IF(ISBLANK($D3),NA(),IFERROR(SUM($D3:$D$177),NA())) -> 894998.05 | Q3: =IFERROR(O3+P3,"") -> 2204542.7 | R3: =IFERROR(N3/Q3*100,NA()) -> 45.862869 | S3: =IFERROR(O3/Q3*100,NA()) -> 59.4021 | T3: =IF(ISBLANK($E3),NA(),IFERROR(SUM($E3:$E$177),NA())) -> 1175341.4 | U3: =IF(ISBLANK($F3),NA(),IFERROR(SUM($F3:$F$177),NA())) -> 1536110 | V3: =IF(ISBLANK($G3),NA(),IFERROR(SUM($G3:$G$177),NA())) -> 1199590 | W3: =IFERROR(U3+V3,"") -> 2735700.1 | X3: =IFERROR(T3/W3*100,NA()) -> 42.963096 | Y3: =IFERROR(U3/W3*100,NA()) -> 56.150528 | Z3: =IF(ISBLANK($H3),NA(),IFERROR(SUM($H3:$H$177),NA())) -> #N/A | AA3: =IF(ISBLANK($I3),NA(),IFERROR(SUM($I3:$I$177),NA())) -> #N/A | AB3: =IF(ISBLANK($J3),NA(),IFERROR(SUM($J3:$J$177),NA())) -> #N/A | AC3: =IFERROR(AA3+AB3,"") | AD3: =IFERROR(Z3/AC3*100,NA()) -> #N/A | AE3: =IFERROR(AA3/AC3*100,NA()) -> #N/A | AF3: =IF(ISBLANK($K3),NA(),IFERROR(SUM($K3:$K$177),NA())) -> #N/A | AG3: =IF(ISBLANK($L3),NA(),IFERROR(SUM($L3:$L$177),NA())) -> #N/A | AH3: =IF(ISBLANK($M3),NA(),IFERROR(SUM($M3:$M$177),NA())) -> #N/A | AI3: =IFERROR(AG3+AH3,"") | AJ3: =IFERROR(AF3/AI3*100,NA()) -> #N/A | AK3: =IFERROR(AG3/AI3*100,NA()) -> #N/A
A4: 1851 | B4: 377.222 | C4: 454.879 | D4: 230.577 | E4: 614.065 | F4: 813.995 | G4: 759.213 | N4: =IF(ISBLANK($B4),NA(),IFERROR(SUM($B4:$B$177),NA())) -> 1010691.2 | O4: =IF(ISBLANK($C4),NA(),IFERROR(SUM($C4:$C$177),NA())) -> 1309092.9 | P4: =IF(ISBLANK($D4),NA(),IFERROR(SUM($D4:$D$177),NA())) -> 894767.44 | Q4: =IFERROR(O4+P4,"") -> 2203860.4 | R4: =IFERROR(N4/Q4*100,NA()) -> 45.860038 | S4: =IFERROR(O4/Q4*100,NA()) -> 59.399994 | T4: =IF(ISBLANK($E4),NA(),IFERROR(SUM($E4:$E$177),NA())) -> 1174732.9 | U4: =IF(ISBLANK($F4),NA(),IFERROR(SUM($F4:$F$177),NA())) -> 1535304.4 | V4: =IF(ISBLANK($G4),NA(),IFERROR(SUM($G4:$G$177),NA())) -> 1198832.2 | W4: =IFERROR(U4+V4,"") -> 2734136.7 | X4: =IFERROR(T4/W4*100,NA()) -> 42.965406 | Y4: =IFERROR(U4/W4*100,NA()) -> 56.15317 | Z4: =IF(ISBLANK($H4),NA(),IFERROR(SUM($H4:$H$177),NA())) -> #N/A | AA4: =IF(ISBLANK($I4),NA(),IFERROR(SUM($I4:$I$177),NA())) -> #N/A | AB4: =IF(ISBLANK($J4),NA(),IFERROR(SUM($J4:$J$177),NA())) -> #N/A | AC4: =IFERROR(AA4+AB4,"") | AD4: =IFERROR(Z4/AC4*100,NA()) -> #N/A | AE4: =IFERROR(AA4/AC4*100,NA()) -> #N/A | AF4: =IF(ISBLANK($K4),NA(),IFERROR(SUM($K4:$K$177),NA())) -> #N/A | AG4: =IF(ISBLANK($L4),NA(),IFERROR(SUM($L4:$L$177),NA())) -> #N/A | AH4: =IF(ISBLANK($M4),NA(),IFERROR(SUM($M4:$M$177),NA())) -> #N/A | AI4: =IFERROR(AG4+AH4,"") | AJ4: =IFERROR(AF4/AI4*100,NA()) -> #N/A | AK4: =IFERROR(AG4/AI4*100,NA()) -> #N/A
A5: 1852 | B5: 387.491 | C5: 466.759 | D5: 230.704 | E5: 627.68 | F5: 830.761 | G5: 760.709 | N5: =IF(ISBLANK($B5),NA(),IFERROR(SUM($B5:$B$177),NA())) -> 1010314 | O5: =IF(ISBLANK($C5),NA(),IFERROR(SUM($C5:$C$177),NA())) -> 1308638.1 | P5: =IF(ISBLANK($D5),NA(),IFERROR(SUM($D5:$D$177),NA())) -> 894536.86 | Q5: =IFERROR(O5+P5,"") -> 2203174.9 | R5: =IFERROR(N5/Q5*100,NA()) -> 45.857184 | S5: =IFERROR(O5/Q5*100,NA()) -> 59.397829 | T5: =IF(ISBLANK($E5),NA(),IFERROR(SUM($E5:$E$177),NA())) -> 1174118.8 | U5: =IF(ISBLANK($F5),NA(),IFERROR(SUM($F5:$F$177),NA())) -> 1534490.4 | V5: =IF(ISBLANK($G5),NA(),IFERROR(SUM($G5:$G$177),NA())) -> 1198073 | W5: =IFERROR(U5+V5,"") -> 2732563.4 | X5: =IFERROR(T5/W5*100,NA()) -> 42.96767 | Y5: =IFERROR(U5/W5*100,NA()) -> 56.15571 | Z5: =IF(ISBLANK($H5),NA(),IFERROR(SUM($H5:$H$177),NA())) -> #N/A | AA5: =IF(ISBLANK($I5),NA(),IFERROR(SUM($I5:$I$177),NA())) -> #N/A | AB5: =IF(ISBLANK($J5),NA(),IFERROR(SUM($J5:$J$177),NA())) -> #N/A | AC5: =IFERROR(AA5+AB5,"") | AD5: =IFERROR(Z5/AC5*100,NA()) -> #N/A | AE5: =IFERROR(AA5/AC5*100,NA()) -> #N/A | AF5: =IF(ISBLANK($K5),NA(),IFERROR(SUM($K5:$K$177),NA())) -> #N/A | AG5: =IF(ISBLANK($L5),NA(),IFERROR(SUM($L5:$L$177),NA())) -> #N/A | AH5: =IF(ISBLANK($M5),NA(),IFERROR(SUM($M5:$M$177),NA())) -> #N/A | AI5: =IFERROR(AG5+AH5,"") | AJ5: =IFERROR(AF5/AI5*100,NA()) -> #N/A | AK5: =IFERROR(AG5/AI5*100,NA()) -> #N/A
A6: 1853 | B6: 400.152 | C6: 480.441 | D6: 230.707 | E6: 643.593 | F6: 849.23 | G6: 762.197 | N6: =IF(ISBLANK($B6),NA(),IFERROR(SUM($B6:$B$177),NA())) -> 1009926.5 | O6: =IF(ISBLANK($C6),NA(),IFERROR(SUM($C6:$C$177),NA())) -> 1308171.3 | P6: =IF(ISBLANK($D6),NA(),IFERROR(SUM($D6:$D$177),NA())) -> 894306.16 | Q6: =IFERROR(O6+P6,"") -> 2202477.5 | R6: =IFERROR(N6/Q6*100,NA()) -> 45.854112 | S6: =IFERROR(O6/Q6*100,NA()) -> 59.395446 | T6: =IF(ISBLANK($E6),NA(),IFERROR(SUM($E6:$E$177),NA())) -> 1173491.2 | U6: =IF(ISBLANK($F6),NA(),IFERROR(SUM($F6:$F$177),NA())) -> 1533659.6 | V6: =IF(ISBLANK($G6),NA(),IFERROR(SUM($G6:$G$177),NA())) -> 1197312.3 | W6: =IFERROR(U6+V6,"") -> 2730972 | X6: =IFERROR(T6/W6*100,NA()) -> 42.969726 | Y6: =IFERROR(U6/W6*100,NA()) -> 56.158015 | Z6: =IF(ISBLANK($H6),NA(),IFERROR(SUM($H6:$H$177),NA())) -> #N/A | AA6: =IF(ISBLANK($I6),NA(),IFERROR(SUM($I6:$I$177),NA())) -> #N/A | AB6: =IF(ISBLANK($J6),NA(),IFERROR(SUM($J6:$J$177),NA())) -> #N/A | AC6: =IFERROR(AA6+AB6,"") | AD6: =IFERROR(Z6/AC6*100,NA()) -> #N/A | AE6: =IFERROR(AA6/AC6*100,NA()) -> #N/A | AF6: =IF(ISBLANK($K6),NA(),IFERROR(SUM($K6:$K$177),NA())) -> #N/A | AG6: =IF(ISBLANK($L6),NA(),IFERROR(SUM($L6:$L$177),NA())) -> #N/A | AH6: =IF(ISBLANK($M6),NA(),IFERROR(SUM($M6:$M$177),NA())) -> #N/A | AI6: =IFERROR(AG6+AH6,"") | AJ6: =IFERROR(AF6/AI6*100,NA()) -> #N/A | AK6: =IFERROR(AG6/AI6*100,NA()) -> #N/A
A7: 1854 | B7: 445.605 | C7: 527.311 | D7: 230.666 | E7: 692.777 | F7: 901.346 | G7: 763.664 | N7: =IF(ISBLANK($B7),NA(),IFERROR(SUM($B7:$B$177),NA())) -> 1009526.3 | O7: =IF(ISBLANK($C7),NA(),IFERROR(SUM($C7:$C$177),NA())) -> 1307690.9 | P7: =IF(ISBLANK($D7),NA(),IFERROR(SUM($D7:$D$177),NA())) -> 894075.45 | Q7: =IFERROR(O7+P7,"") -> 2201766.3 | R7: =IFERROR(N7/Q7*100,NA()) -> 45.850748 | S7: =IFERROR(O7/Q7*100,NA()) -> 59.392809 | T7: =IF(ISBLANK($E7),NA(),IFERROR(SUM($E7:$E$177),NA())) -> 1172847.6 | U7: =IF(ISBLANK($F7),NA(),IFERROR(SUM($F7:$F$177),NA())) -> 1532810.4 | V7: =IF(ISBLANK($G7),NA(),IFERROR(SUM($G7:$G$177),NA())) -> 1196550.1 | W7: =IFERROR(U7+V7,"") -> 2729360.5 | X7: =IFERROR(T7/W7*100,NA()) -> 42.971515 | Y7: =IFERROR(U7/W7*100,NA()) -> 56.160056 | Z7: =IF(ISBLANK($H7),NA(),IFERROR(SUM($H7:$H$177),NA())) -> #N/A | AA7: =IF(ISBLANK($I7),NA(),IFERROR(SUM($I7:$I$177),NA())) -> #N/A | AB7: =IF(ISBLANK($J7),NA(),IFERROR(SUM($J7:$J$177),NA())) -> #N/A | AC7: =IFERROR(AA7+AB7,"") | AD7: =IFERROR(Z7/AC7*100,NA()) -> #N/A | AE7: =IFERROR(AA7/AC7*100,NA()) -> #N/A | AF7: =IF(ISBLANK($K7),NA(),IFERROR(SUM($K7:$K$177),NA())) -> #N/A | AG7: =IF(ISBLANK($L7),NA(),IFERROR(SUM($L7:$L$177),NA())) -> #N/A | AH7: =IF(ISBLANK($M7),NA(),IFERROR(SUM($M7:$M$177),NA())) -> #N/A | AI7: =IFERROR(AG7+AH7,"") | AJ7: =IFERROR(AF7/AI7*100,NA()) -> #N/A | AK7: =IFERROR(AG7/AI7*100,NA()) -> #N/A
A8: 1855 | B8: 451.437 | C8: 535.244 | D8: 230.934 | E8: 701.781 | F8: 913.68 | G8: 765.098 | N8: =IF(ISBLANK($B8),NA(),IFERROR(SUM($B8:$B$177),NA())) -> 1009080.7 | O8: =IF(ISBLANK($C8),NA(),IFERROR(SUM($C8:$C$177),NA())) -> 1307163.6 | P8: =IF(ISBLANK($D8),NA(),IFERROR(SUM($D8:$D$177),NA())) -> 893844.79 | Q8: =IFERROR(O8+P8,"") -> 2201008.3 | R8: =IFERROR(N8/Q8*100,NA()) -> 45.846293 | S8: =IFERROR(O8/Q8*100,NA()) -> 59.389305 | T8: =IF(ISBLANK($E8),NA(),IFERROR(SUM($E8:$E$177),NA())) -> 1172154.8 | U8: =IF(ISBLANK($F8),NA(),IFERROR(SUM($F8:$F$177),NA())) -> 1531909.1 | V8: =IF(ISBLANK($G8),NA(),IFERROR(SUM($G8:$G$177),NA())) -> 1195786.5 | W8: =IFERROR(U8+V8,"") -> 2727695.5 | X8: =IFERROR(T8/W8*100,NA()) -> 42.972347 | Y8: =IFERROR(U8/W8*100,NA()) -> 56.161293 | Z8: =IF(ISBLANK($H8),NA(),IFERROR(SUM($H8:$H$177),NA())) -> #N/A | AA8: =IF(ISBLANK($I8),NA(),IFERROR(SUM($I8:$I$177),NA())) -> #N/A | AB8: =IF(ISBLANK($J8),NA(),IFERROR(SUM($J8:$J$177),NA())) -> #N/A | AC8: =IFERROR(AA8+AB8,"") | AD8: =IFERROR(Z8/AC8*100,NA()) -> #N/A | AE8: =IFERROR(AA8/AC8*100,NA()) -> #N/A | AF8: =IF(ISBLANK($K8),NA(),IFERROR(SUM($K8:$K$177),NA())) -> #N/A | AG8: =IF(ISBLANK($L8),NA(),IFERROR(SUM($L8:$L$177),NA())) -> #N/A | AH8: =IF(ISBLANK($M8),NA(),IFERROR(SUM($M8:$M$177),NA())) -> #N/A | AI8: =IFERROR(AG8+AH8,"") | AJ8: =IFERROR(AF8/AI8*100,NA()) -> #N/A | AK8: =IFERROR(AG8/AI8*100,NA()) -> #N/A
A9: 1856 | B9: 472.505 | C9: 557.571 | D9: 231.735 | E9: 725.99 | F9: 940.886 | G9: 766.465 | N9: =IF(ISBLANK($B9),NA(),IFERROR(SUM($B9:$B$177),NA())) -> 1008629.3 | O9: =IF(ISBLANK($C9),NA(),IFERROR(SUM($C9:$C$177),NA())) -> 1306628.3 | P9: =IF(ISBLANK($D9),NA(),IFERROR(SUM($D9:$D$177),NA())) -> 893613.85 | Q9: =IFERROR(O9+P9,"") -> 2200242.2 | R9: =IFERROR(N9/Q9*100,NA()) -> 45.84174 | S9: =IFERROR(O9/Q9*100,NA()) -> 59.385659 | T9: =IF(ISBLANK($E9),NA(),IFERROR(SUM($E9:$E$177),NA())) -> 1171453 | U9: =IF(ISBLANK($F9),NA(),IFERROR(SUM($F9:$F$177),NA())) -> 1530995.4 | V9: =IF(ISBLANK($G9),NA(),IFERROR(SUM($G9:$G$177),NA())) -> 1195021.4 | W9: =IFERROR(U9+V9,"") -> 2726016.8 | X9: =IFERROR(T9/W9*100,NA()) -> 42.973067 | Y9: =IFERROR(U9/W9*100,NA()) -> 56.162362 | Z9: =IF(ISBLANK($H9),NA(),IFERROR(SUM($H9:$H$177),NA())) -> #N/A | AA9: =IF(ISBLANK($I9),NA(),IFERROR(SUM($I9:$I$177),NA())) -> #N/A | AB9: =IF(ISBLANK($J9),NA(),IFERROR(SUM($J9:$J$177),NA())) -> #N/A | AC9: =IFERROR(AA9+AB9,"") | AD9: =IFERROR(Z9/AC9*100,NA()) -> #N/A | AE9: =IFERROR(AA9/AC9*100,NA()) -> #N/A | AF9: =IF(ISBLANK($K9),NA(),IFERROR(SUM($K9:$K$177),NA())) -> #N/A | AG9: =IF(ISBLANK($L9),NA(),IFERROR(SUM($L9:$L$177),NA())) -> #N/A | AH9: =IF(ISBLANK($M9),NA(),IFERROR(SUM($M9:$M$177),NA())) -> #N/A | AI9: =IFERROR(AG9+AH9,"") | AJ9: =IFERROR(AF9/AI9*100,NA()) -> #N/A | AK9: =IFERROR(AG9/AI9*100,NA()) -> #N/A
A10: 1857 | B10: 476.111 | C10: 562.515 | D10: 232.112 | E10: 732.441 | F10: 950.099 | G10: 767.81 | N10: =IF(ISBLANK($B10),NA(),IFERROR(SUM($B10:$B$177),NA())) -> 1008156.8 | O10: =IF(ISBLANK($C10),NA(),IFERROR(SUM($C10:$C$177),NA())) -> 1306070.7 | P10: =IF(ISBLANK($D10),NA(),IFERROR(SUM($D10:$D$177),NA())) -> 893382.12 | Q10: =IFERROR(O10+P10,"") -> 2199452.9 | R10: =IFERROR(N10/Q10*100,NA()) -> 45.836708 | S10: =IFERROR(O10/Q10*100,NA()) -> 59.38162 | T10: =IF(ISBLANK($E10),NA(),IFERROR(SUM($E10:$E$177),NA())) -> 1170727 | U10: =IF(ISBLANK($F10),NA(),IFERROR(SUM($F10:$F$177),NA())) -> 1530054.5 | V10: =IF(ISBLANK($G10),NA(),IFERROR(SUM($G10:$G$177),NA())) -> 1194254.9 | W10: =IFERROR(U10+V10,"") -> 2724309.4 | X10: =IFERROR(T10/W10*100,NA()) -> 42.97335 | Y10: =IFERROR(U10/W10*100,NA()) -> 56.163022 | Z10: =IF(ISBLANK($H10),NA(),IFERROR(SUM($H10:$H$177),NA())) -> #N/A | AA10: =IF(ISBLANK($I10),NA(),IFERROR(SUM($I10:$I$177),NA())) -> #N/A | AB10: =IF(ISBLANK($J10),NA(),IFERROR(SUM($J10:$J$177),NA())) -> #N/A | AC10: =IFERROR(AA10+AB10,"") | AD10: =IFERROR(Z10/AC10*100,NA()) -> #N/A | AE10: =IFERROR(AA10/AC10*100,NA()) -> #N/A | AF10: =IF(ISBLANK($K10),NA(),IFERROR(SUM($K10:$K$177),NA())) -> #N/A | AG10: =IF(ISBLANK($L10),NA(),IFERROR(SUM($L10:$L$177),NA())) -> #N/A | AH10: =IF(ISBLANK($M10),NA(),IFERROR(SUM($M10:$M$177),NA())) -> #N/A | AI10: =IFERROR(AG10+AH10,"") | AJ10: =IFERROR(AF10/AI10*100,NA()) -> #N/A | AK10: =IFERROR(AG10/AI10*100,NA()) -> #N/A
A11: 1858 | B11: 479.735 | C11: 568.363 | D11: 232.806 | E11: 738.925 | F11: 959.834 | G11: 769.603 | N11: =IF(ISBLANK($B11),NA(),IFERROR(SUM($B11:$B$177),NA())) -> 1007680.7 | O11: =IF(ISBLANK($C11),NA(),IFERROR(SUM($C11:$C$177),NA())) -> 1305508.2 | P11: =IF(ISBLANK($D11),NA(),IFERROR(SUM($D11:$D$177),NA())) -> 893150.01 | Q11: =IFERROR(O11+P11,"") -> 2198658.2 | R11: =IFERROR(N11/Q11*100,NA()) -> 45.83162 | S11: =IFERROR(O11/Q11*100,NA()) -> 59.377497 | T11: =IF(ISBLANK($E11),NA(),IFERROR(SUM($E11:$E$177),NA())) -> 1169994.6 | U11: =IF(ISBLANK($F11),NA(),IFERROR(SUM($F11:$F$177),NA())) -> 1529104.4 | V11: =IF(ISBLANK($G11),NA(),IFERROR(SUM($G11:$G$177),NA())) -> 1193487.1 | W11: =IFERROR(U11+V11,"") -> 2722591.5 | X11: =IFERROR(T11/W11*100,NA()) -> 42.973563 | Y11: =IFERROR(U11/W11*100,NA()) -> 56.163564 | Z11: =IF(ISBLANK($H11),NA(),IFERROR(SUM($H11:$H$177),NA())) -> #N/A | AA11: =IF(ISBLANK($I11),NA(),IFERROR(SUM($I11:$I$177),NA())) -> #N/A | AB11: =IF(ISBLANK($J11),NA(),IFERROR(SUM($J11:$J$177),NA())) -> #N/A | AC11: =IFERROR(AA11+AB11,"") | AD11: =IFERROR(Z11/AC11*100,NA()) -> #N/A | AE11: =IFERROR(AA11/AC11*100,NA()) -> #N/A | AF11: =IF(ISBLANK($K11),NA(),IFERROR(SUM($K11:$K$177),NA())) -> #N/A | AG11: =IF(ISBLANK($L11),NA(),IFERROR(SUM($L11:$L$177),NA())) -> #N/A | AH11: =IF(ISBLANK($M11),NA(),IFERROR(SUM($M11:$M$177),NA())) -> #N/A | AI11: =IFERROR(AG11+AH11,"") | AJ11: =IFERROR(AF11/AI11*100,NA()) -> #N/A | AK11: =IFERROR(AG11/AI11*100,NA()) -> #N/A
A12: 1859 | B12: 501.616 | C12: 590.795 | D12: 232.95 | E12: 762.946 | F12: 985.666 | G12: 771.134 | N12: =IF(ISBLANK($B12),NA(),IFERROR(SUM($B12:$B$177),NA())) -> 1007200.9 | O12: =IF(ISBLANK($C12),NA(),IFERROR(SUM($C12:$C$177),NA())) -> 1304939.9 | P12: =IF(ISBLANK($D12),NA(),IFERROR(SUM($D12:$D$177),NA())) -> 892917.2 | Q12: =IFERROR(O12+P12,"") -> 2197857.1 | R12: =IFERROR(N12/Q12*100,NA()) -> 45.826499 | S12: =IFERROR(O12/Q12*100,NA()) -> 59.373282 | T12: =IF(ISBLANK($E12),NA(),IFERROR(SUM($E12:$E$177),NA())) -> 1169255.7 | U12: =IF(ISBLANK($F12),NA(),IFERROR(SUM($F12:$F$177),NA())) -> 1528144.6 | V12: =IF(ISBLANK($G12),NA(),IFERROR(SUM($G12:$G$177),NA())) -> 1192717.5 | W12: =IFERROR(U12+V12,"") -> 2720862.1 | X12: =IFERROR(T12/W12*100,NA()) -> 42.97372 | Y12: =IFERROR(U12/W12*100,NA()) -> 56.163985 | Z12: =IF(ISBLANK($H12),NA(),IFERROR(SUM($H12:$H$177),NA())) -> #N/A | AA12: =IF(ISBLANK($I12),NA(),IFERROR(SUM($I12:$I$177),NA())) -> #N/A | AB12: =IF(ISBLANK($J12),NA(),IFERROR(SUM($J12:$J$177),NA())) -> #N/A | AC12: =IFERROR(AA12+AB12,"") | AD12: =IFERROR(Z12/AC12*100,NA()) -> #N/A | AE12: =IFERROR(AA12/AC12*100,NA()) -> #N/A | AF12: =IF(ISBLANK($K12),NA(),IFERROR(SUM($K12:$K$177),NA())) -> #N/A | AG12: =IF(ISBLANK($L12),NA(),IFERROR(SUM($L12:$L$177),NA())) -> #N/A | AH12: =IF(ISBLANK($M12),NA(),IFERROR(SUM($M12:$M$177),NA())) -> #N/A | AI12: =IFERROR(AG12+AH12,"") | AJ12: =IFERROR(AF12/AI12*100,NA()) -> #N/A | AK12: =IFERROR(AG12/AI12*100,NA()) -> #N/A
A13: 1860 | B13: 536.458 | C13: 627.41 | D13: 233.314 | E13: 800.308 | F13: 1026.084 | G13: 772.319 | N13: =IF(ISBLANK($B13),NA(),IFERROR(SUM($B13:$B$177),NA())) -> 1006699.3 | O13: =IF(ISBLANK($C13),NA(),IFERROR(SUM($C13:$C$177),NA())) -> 1304349.1 | P13: =IF(ISBLANK($D13),NA(),IFERROR(SUM($D13:$D$177),NA())) -> 892684.25 | Q13: =IFERROR(O13+P13,"") -> 2197033.3 | R13: =IFERROR(N13/Q13*100,NA()) -> 45.820849 | S13: =IFERROR(O13/Q13*100,NA()) -> 59.368652 | T13: =IF(ISBLANK($E13),NA(),IFERROR(SUM($E13:$E$177),NA())) -> 1168492.7 | U13: =IF(ISBLANK($F13),NA(),IFERROR(SUM($F13:$F$177),NA())) -> 1527158.9 | V13: =IF(ISBLANK($G13),NA(),IFERROR(SUM($G13:$G$177),NA())) -> 1191946.4 | W13: =IFERROR(U13+V13,"") -> 2719105.3 | X13: =IFERROR(T13/W13*100,NA()) -> 42.973427 | Y13: =IFERROR(U13/W13*100,NA()) -> 56.164023 | Z13: =IF(ISBLANK($H13),NA(),IFERROR(SUM($H13:$H$177),NA())) -> #N/A | AA13: =IF(ISBLANK($I13),NA(),IFERROR(SUM($I13:$I$177),NA())) -> #N/A | AB13: =IF(ISBLANK($J13),NA(),IFERROR(SUM($J13:$J$177),NA())) -> #N/A | AC13: =IFERROR(AA13+AB13,"") | AD13: =IFERROR(Z13/AC13*100,NA()) -> #N/A | AE13: =IFERROR(AA13/AC13*100,NA()) -> #N/A | AF13: =IF(ISBLANK($K13),NA(),IFERROR(SUM($K13:$K$177),NA())) -> #N/A | AG13: =IF(ISBLANK($L13),NA(),IFERROR(SUM($L13:$L$177),NA())) -> #N/A | AH13: =IF(ISBLANK($M13),NA(),IFERROR(SUM($M13:$M$177),NA())) -> #N/A | AI13: =IFERROR(AG13+AH13,"") | AJ13: =IFERROR(AF13/AI13*100,NA()) -> #N/A | AK13: =IFERROR(AG13/AI13*100,NA()) -> #N/A
