Workbook

Sheet vals_ghg_incLUC
A2: Year | B2: annex2_OWID | C2: annex1_OWID | D2: non_annex1_OWID | E2: annex2_PRIMAP | F2: annex1_PRIMAP | G2: non_annex1_PRIMAP | N2: cum_annex2_OWID | O2: cum_annex1_OWID | P2: cum_non_ann1_OWID | Q2: cum_world_OWID | R2: pct_annex2_OWID | S2: pct_annex1_OWID | T2: cum_annex2_PRIMAP | U2: cum_annex1_PRIMAP | V2: cum_non_ann1_PRIMAP | W2: cum_world_PRIMAP | X2: pct_annex2_PRIMAP | Y2: pct_annex1_PRIMAP
A3: 1850 | B3: 1550.641 | C3: 2325.845 | D3: 1967.466 | E3: 1549.27 | F3: 2081.865 | G3: 1650.774 | N3: =IFERROR(SUM($B$3:$B3),"") -> 1550.641 | O3: =IFERROR(SUM($C$3:$C3),"") -> 2325.845 | P3: =IFERROR(SUM($D$3:$D3),"") -> 1967.466 | Q3: =IFERROR(O3+P3,"") -> 4293.311 | R3: =IFERROR(N3/Q3*100,NA()) -> 36.117602 | S3: =IFERROR(O3/Q3*100,NA()) -> 54.17369 | T3: =IFERROR(SUM($E$3:$E3),"") -> 1549.27 | U3: =IFERROR(SUM($F$3:$F3),"") -> 2081.865 | V3: =IFERROR(SUM($G$3:$G3),"") -> 1650.774 | W3: =IFERROR(U3+V3,"") -> 3732.639 | X3: =IFERROR(T3/W3*100,NA()) -> 41.506023 | Y3: =IFERROR(U3/W3*100,NA()) -> 55.774614
A4: 1851 | B4: 1599.614 | C4: 2376.348 | D4: 2032.821 | E4: 1560.063 | F4: 2095.452 | G4: 1618.228 | N4: =IFERROR(SUM($B$3:$B4),"") -> 3150.255 | O4: =IFERROR(SUM($C$3:$C4),"") -> 4702.193 | P4: =IFERROR(SUM($D$3:$D4),"") -> 4000.287 | Q4: =IFERROR(O4+P4,"") -> 8702.48 | R4: =IFERROR(N4/Q4*100,NA()) -> 36.199509 | S4: =IFERROR(O4/Q4*100,NA()) -> 54.032793 | T4: =IFERROR(SUM($E$3:$E4),"") -> 3109.333 | U4: =IFERROR(SUM($F$3:$F4),"") -> 4177.317 | V4: =IFERROR(SUM($G$3:$G4),"") -> 3269.002 | W4: =IFERROR(U4+V4,"") -> 7446.319 | X4: =IFERROR(T4/W4*100,NA()) -> 41.756645 | Y4: =IFERROR(U4/W4*100,NA()) -> 56.099087
A5: 1852 | B5: 1630.719 | C5: 2447.128 | D5: 2076.583 | E5: 1811.682 | F5: 2351.276 | G5: 1585.489 | N5: =IFERROR(SUM($B$3:$B5),"") -> 4780.974 | O5: =IFERROR(SUM($C$3:$C5),"") -> 7149.321 | P5: =IFERROR(SUM($D$3:$D5),"") -> 6076.87 | Q5: =IFERROR(O5+P5,"") -> 13226.191 | R5: =IFERROR(N5/Q5*100,NA()) -> 36.147777 | S5: =IFERROR(O5/Q5*100,NA()) -> 54.05427 | T5: =IFERROR(SUM($E$3:$E5),"") -> 4921.015 | U5: =IFERROR(SUM($F$3:$F5),"") -> 6528.593 | V5: =IFERROR(SUM($G$3:$G5),"") -> 4854.491 | W5: =IFERROR(U5+V5,"") -> 11383.084 | X5: =IFERROR(T5/W5*100,NA()) -> 43.230947 | Y5: =IFERROR(U5/W5*100,NA()) -> 57.353464
A6: 1853 | B6: 1683.136 | C6: 2475.421 | D6: 2085.978 | E6: 1856.217 | F6: 2399.478 | G6: 1550.994 | N6: =IFERROR(SUM($B$3:$B6),"") -> 6464.11 | O6: =IFERROR(SUM($C$3:$C6),"") -> 9624.742 | P6: =IFERROR(SUM($D$3:$D6),"") -> 8162.848 | Q6: =IFERROR(O6+P6,"") -> 17787.59 | R6: =IFERROR(N6/Q6*100,NA()) -> 36.340561 | S6: =IFERROR(O6/Q6*100,NA()) -> 54.109309 | T6: =IFERROR(SUM($E$3:$E6),"") -> 6777.232 | U6: =IFERROR(SUM($F$3:$F6),"") -> 8928.071 | V6: =IFERROR(SUM($G$3:$G6),"") -> 6405.485 | W6: =IFERROR(U6+V6,"") -> 15333.556 | X6: =IFERROR(T6/W6*100,NA()) -> 44.198697 | Y6: =IFERROR(U6/W6*100,NA()) -> 58.225704
A7: 1854 | B7: 1755.03 | C7: 2574.758 | D7: 2079.231 | E7: 1933.391 | F7: 2480.753 | G7: 1516.01 | N7: =IFERROR(SUM($B$3:$B7),"") -> 8219.14 | O7: =IFERROR(SUM($C$3:$C7),"") -> 12199.5 | P7: =IFERROR(SUM($D$3:$D7),"") -> 10242.079 | Q7: =IFERROR(O7+P7,"") -> 22441.579 | R7: =IFERROR(N7/Q7*100,NA()) -> 36.624606 | S7: =IFERROR(O7/Q7*100,NA()) -> 54.361148 | T7: =IFERROR(SUM($E$3:$E7),"") -> 8710.623 | U7: =IFERROR(SUM($F$3:$F7),"") -> 11408.824 | V7: =IFERROR(SUM($G$3:$G7),"") -> 7921.495 | W7: =IFERROR(U7+V7,"") -> 19330.319 | X7: =IFERROR(T7/W7*100,NA()) -> 45.061972 | Y7: =IFERROR(U7/W7*100,NA()) -> 59.020361
A8: 1855 | B8: 1775.259 | C8: 2601.394 | D8: 2118.618 | E8: 1969.323 | F8: 2521.239 | G8: 1479.527 | N8: =IFERROR(SUM($B$3:$B8),"") -> 9994.399 | O8: =IFERROR(SUM($C$3:$C8),"") -> 14800.894 | P8: =IFERROR(SUM($D$3:$D8),"") -> 12360.697 | Q8: =IFERROR(O8+P8,"") -> 27161.591 | R8: =IFERROR(N8/Q8*100,NA()) -> 36.796074 | S8: =IFERROR(O8/Q8*100,NA()) -> 54.491999 | T8: =IFERROR(SUM($E$3:$E8),"") -> 10679.946 | U8: =IFERROR(SUM($F$3:$F8),"") -> 13930.063 | V8: =IFERROR(SUM($G$3:$G8),"") -> 9401.022 | W8: =IFERROR(U8+V8,"") -> 23331.085 | X8: =IFERROR(T8/W8*100,NA()) -> 45.775608 | Y8: =IFERROR(U8/W8*100,NA()) -> 59.706023
A9: 1856 | B9: 1806.851 | C9: 2640.92 | D9: 2123.642 | E9: 2018.929 | F9: 2575.095 | G9: 1474.922 | N9: =IFERROR(SUM($B$3:$B9),"") -> 11801.25 | O9: =IFERROR(SUM($C$3:$C9),"") -> 17441.814 | P9: =IFERROR(SUM($D$3:$D9),"") -> 14484.339 | Q9: =IFERROR(O9+P9,"") -> 31926.153 | R9: =IFERROR(N9/Q9*100,NA()) -> 36.964209 | S9: =IFERROR(O9/Q9*100,NA()) -> 54.631743 | T9: =IFERROR(SUM($E$3:$E9),"") -> 12698.875 | U9: =IFERROR(SUM($F$3:$F9),"") -> 16505.158 | V9: =IFERROR(SUM($G$3:$G9),"") -> 10875.944 | W9: =IFERROR(U9+V9,"") -> 27381.102 | X9: =IFERROR(T9/W9*100,NA()) -> 46.378247 | Y9: =IFERROR(U9/W9*100,NA()) -> 60.279378
A10: 1857 | B10: 1832.535 | C10: 2679.446 | D10: 2143.342 | E10: 2049.892 | F10: 2610.066 | G10: 1471.382 | N10: =IFERROR(SUM($B$3:$B10),"") -> 13633.785 | O10: =IFERROR(SUM($C$3:$C10),"") -> 20121.26 | P10: =IFERROR(SUM($D$3:$D10),"") -> 16627.681 | Q10: =IFERROR(O10+P10,"") -> 36748.941 | R10: =IFERROR(N10/Q10*100,NA()) -> 37.099804 | S10: =IFERROR(O10/Q10*100,NA()) -> 54.753306 | T10: =IFERROR(SUM($E$3:$E10),"") -> 14748.767 | U10: =IFERROR(SUM($F$3:$F10),"") -> 19115.224 | V10: =IFERROR(SUM($G$3:$G10),"") -> 12347.326 | W10: =IFERROR(U10+V10,"") -> 31462.55 | X10: =IFERROR(T10/W10*100,NA()) -> 46.877214 | Y10: =IFERROR(U10/W10*100,NA()) -> 60.755482
A11: 1858 | B11: 1863.287 | C11: 2714.254 | D11: 2140.78 | E11: 2079.509 | F11: 2644.17 | G11: 1468.466 | N11: =IFERROR(SUM($B$3:$B11),"") -> 15497.072 | O11: =IFERROR(SUM($C$3:$C11),"") -> 22835.514 | P11: =IFERROR(SUM($D$3:$D11),"") -> 18768.461 | Q11: =IFERROR(O11+P11,"") -> 41603.975 | R11: =IFERROR(N11/Q11*100,NA()) -> 37.249018 | S11: =IFERROR(O11/Q11*100,NA()) -> 54.887818 | T11: =IFERROR(SUM($E$3:$E11),"") -> 16828.276 | U11: =IFERROR(SUM($F$3:$F11),"") -> 21759.394 | V11: =IFERROR(SUM($G$3:$G11),"") -> 13815.792 | W11: =IFERROR(U11+V11,"") -> 35575.186 | X11: =IFERROR(T11/W11*100,NA()) -> 47.30341 | Y11: =IFERROR(U11/W11*100,NA()) -> 61.164526
A12: 1859 | B12: 1914.287 | C12: 2773.463 | D12: 2152.288 | E12: 2125.918 | F12: 2693.616 | G12: 1466.165 | N12: =IFERROR(SUM($B$3:$B12),"") -> 17411.359 | O12: =IFERROR(SUM($C$3:$C12),"") -> 25608.977 | P12: =IFERROR(SUM($D$3:$D12),"") -> 20920.749 | Q12: =IFERROR(O12+P12,"") -> 46529.726 | R12: =IFERROR(N12/Q12*100,NA()) -> 37.419861 | S12: =IFERROR(O12/Q12*100,NA()) -> 55.037885 | T12: =IFERROR(SUM($E$3:$E12),"") -> 18954.194 | U12: =IFERROR(SUM($F$3:$F12),"") -> 24453.01 | V12: =IFERROR(SUM($G$3:$G12),"") -> 15281.957 | W12: =IFERROR(U12+V12,"") -> 39734.967 | X12: =IFERROR(T12/W12*100,NA()) -> 47.701547 | Y12: =IFERROR(U12/W12*100,NA()) -> 61.54028
A13: 1860 | B13: 1891.387 | C13: 2720.11 | D13: 1986.999 | E13: 2184.927 | F13: 2756.895 | G13: 1462.833 | N13: =IFERROR(SUM($B$3:$B13),"") -> 19302.746 | O13: =IFERROR(SUM($C$3:$C13),"") -> 28329.087 | P13: =IFERROR(SUM($D$3:$D13),"") -> 22907.748 | Q13: =IFERROR(O13+P13,"") -> 51236.835 | R13: =IFERROR(N13/Q13*100,NA()) -> 37.673572 | S13: =IFERROR(O13/Q13*100,NA()) -> 55.29047 | T13: =IFERROR(SUM($E$3:$E13),"") -> 21139.121 | U13: =IFERROR(SUM($F$3:$F13),"") -> 27209.905 | V13: =IFERROR(SUM($G$3:$G13),"") -> 16744.79 | W13: =IFERROR(U13+V13,"") -> 43954.695 | X13: =IFERROR(T13/W13*100,NA()) -> 48.092976 | Y13: =IFERROR(U13/W13*100,NA()) -> 61.904434
A14: 1861 | B14: 1845.785 | C14: 2678.775 | D14: 1924.65 | E14: 2225.877 | F14: 2814.954 | G14: 1471.184 | N14: =IFERROR(SUM($B$3:$B14),"") -> 21148.531 | O14: =IFERROR(SUM($C$3:$C14),"") -> 31007.862 | P14: =IFERROR(SUM($D$3:$D14),"") -> 24832.398 | Q14: =IFERROR(O14+P14,"") -> 55840.26 | R14: =IFERROR(N14/Q14*100,NA()) -> 37.873267 | S14: =IFERROR(O14/Q14*100,NA()) -> 55.52958 | T14: =IFERROR(SUM($E$3:$E14),"") -> 23364.998 | U14: =IFERROR(SUM($F$3:$F14),"") -> 30024.859 | V14: =IFERROR(SUM($G$3:$G14),"") -> 18215.974 | W14: =IFERROR(U14+V14,"") -> 48240.833 | X14: =IFERROR(T14/W14*100,NA()) -> 48.434068 | Y14: =IFERROR(U14/W14*100,NA()) -> 62.239512
... A177: 2024 | B177: 11369.645 | C177: 15810.797 | D177: 38602.845 | E177: 8641.151 | F177: 11449.105 | G177: 24074.701 | N177: =IFERROR(SUM($B$3:$B177),"") -> 1314684.8 | O177: =IFERROR(SUM($C$3:$C177),"") -> 1782111.7 | P177: =IFERROR(SUM($D$3:$D177),"") -> 1826135.5 | Q177: =IFERROR(O177+P177,"") -> 3608247.3 | R177: =IFERROR(N177/Q177*100,NA()) -> 36.435552 | S177: =IFERROR(O177/Q177*100,NA()) -> 49.389956 | T177: =IFERROR(SUM($E$3:$E177),"") -> 1252707.5 | U177: =IFERROR(SUM($F$3:$F177),"") -> 1617916.6 | V177: =IFERROR(SUM($G$3:$G177),"") -> 1557169.5 | W177: =IFERROR(U177+V177,"") -> 3175086.2 | X177: =IFERROR(T177/W177*100,NA()) -> 39.454285 | Y177: =IFERROR(U177/W177*100,NA()) -> 50.956621

Sheet GHG incl LULUCF

Sheet data_ghg_incLUC
A1: Cumulative GHG emissions including LULUCF since 1850, different end points
A2: Year | B2: AII_Min | C2: AII_Max | D2: AI_Min | E2: AI_Max | F2: Pure_AII | G2: Overlap | H2: AI_Gap | I2: pct_annex2_OWID | J2: pct_annex2_PRIMAP | M2: pct_annex1_OWID | N2: pct_annex1_PRIMAP | Q2: Pure_AI | R2: Annex II GMST | S2: Annex I GMST
A3: =vals_ghg_incLUC!$A3 -> 1850 | B3: =IFERROR(_xlfn.AGGREGATE(5,6,I3:L3),"") -> 36.117602 | C3: =IFERROR(_xlfn.AGGREGATE(4,6,I3:L3),"") -> 41.506023 | D3: =IFERROR(_xlfn.AGGREGATE(5,6,M3:P3),"") -> 54.17369 | E3: =IFERROR(_xlfn.AGGREGATE(4,6,M3:P3),"") -> 55.774614 | F3: =IFERROR(MIN(C3,D3)-B3,"") -> 5.3884205 | G3: =IFERROR(MAX(0,C3-D3),"") -> 0 | H3: =IFERROR(MAX(0,D3-C3),"") -> 12.667667 | I3: =vals_ghg_incLUC!$R3 -> 36.117602 | J3: =vals_ghg_incLUC!$X3 -> 41.506023 | M3: =vals_ghg_incLUC!$S3 -> 54.17369 | N3: =vals_ghg_incLUC!$Y3 -> 55.774614 | Q3: =IFERROR(MAX(0,$E3-MAX($C3,$D3)),"") -> 1.600924
A4: =vals_ghg_incLUC!$A4 -> 1851 | B4: =IFERROR(_xlfn.AGGREGATE(5,6,I4:L4),"") -> 36.199509 | C4: =IFERROR(_xlfn.AGGREGATE(4,6,I4:L4),"") -> 41.756645 | D4: =IFERROR(_xlfn.AGGREGATE(5,6,M4:P4),"") -> 54.032793 | E4: =IFERROR(_xlfn.AGGREGATE(4,6,M4:P4),"") -> 56.099087 | F4: =IFERROR(MIN(C4,D4)-B4,"") -> 5.5571365 | G4: =IFERROR(MAX(0,C4-D4),"") -> 0 | H4: =IFERROR(MAX(0,D4-C4),"") -> 12.276148 | I4: =vals_ghg_incLUC!$R4 -> 36.199509 | J4: =vals_ghg_incLUC!$X4 -> 41.756645 | M4: =vals_ghg_incLUC!$S4 -> 54.032793 | N4: =vals_ghg_incLUC!$Y4 -> 56.099087 | Q4: =IFERROR(MAX(0,$E4-MAX($C4,$D4)),"") -> 2.0662944 | R4: 39.592 | S4: 58.146
A5: =vals_ghg_incLUC!$A5 -> 1852 | B5: =IFERROR(_xlfn.AGGREGATE(5,6,I5:L5),"") -> 36.147777 | C5: =IFERROR(_xlfn.AGGREGATE(4,6,I5:L5),"") -> 43.230947 | D5: =IFERROR(_xlfn.AGGREGATE(5,6,M5:P5),"") -> 54.05427 | E5: =IFERROR(_xlfn.AGGREGATE(4,6,M5:P5),"") -> 57.353464 | F5: =IFERROR(MIN(C5,D5)-B5,"") -> 7.0831701 | G5: =IFERROR(MAX(0,C5-D5),"") -> 0 | H5: =IFERROR(MAX(0,D5-C5),"") -> 10.823323 | I5: =vals_ghg_incLUC!$R5 -> 36.147777 | J5: =vals_ghg_incLUC!$X5 -> 43.230947 | M5: =vals_ghg_incLUC!$S5 -> 54.05427 | N5: =vals_ghg_incLUC!$Y5 -> 57.353464 | Q5: =IFERROR(MAX(0,$E5-MAX($C5,$D5)),"") -> 3.2991941 | R5: 39.462 | S5: 58.249
A6: =vals_ghg_incLUC!$A6 -> 1853 | B6: =IFERROR(_xlfn.AGGREGATE(5,6,I6:L6),"") -> 36.340561 | C6: =IFERROR(_xlfn.AGGREGATE(4,6,I6:L6),"") -> 44.198697 | D6: =IFERROR(_xlfn.AGGREGATE(5,6,M6:P6),"") -> 54.109309 | E6: =IFERROR(_xlfn.AGGREGATE(4,6,M6:P6),"") -> 58.225704 | F6: =IFERROR(MIN(C6,D6)-B6,"") -> 7.8581363 | G6: =IFERROR(MAX(0,C6-D6),"") -> 0 | H6: =IFERROR(MAX(0,D6-C6),"") -> 9.9106115 | I6: =vals_ghg_incLUC!$R6 -> 36.340561 | J6: =vals_ghg_incLUC!$X6 -> 44.198697 | M6: =vals_ghg_incLUC!$S6 -> 54.109309 | N6: =vals_ghg_incLUC!$Y6 -> 58.225704 | Q6: =IFERROR(MAX(0,$E6-MAX($C6,$D6)),"") -> 4.1163957 | R6: 39.752 | S6: 58.376
A7: =vals_ghg_incLUC!$A7 -> 1854 | B7: =IFERROR(_xlfn.AGGREGATE(5,6,I7:L7),"") -> 36.624606 | C7: =IFERROR(_xlfn.AGGREGATE(4,6,I7:L7),"") -> 45.061972 | D7: =IFERROR(_xlfn.AGGREGATE(5,6,M7:P7),"") -> 54.361148 | E7: =IFERROR(_xlfn.AGGREGATE(4,6,M7:P7),"") -> 59.020361 | F7: =IFERROR(MIN(C7,D7)-B7,"") -> 8.4373658 | G7: =IFERROR(MAX(0,C7-D7),"") -> 0 | H7: =IFERROR(MAX(0,D7-C7),"") -> 9.2991758 | I7: =vals_ghg_incLUC!$R7 -> 36.624606 | J7: =vals_ghg_incLUC!$X7 -> 45.061972 | M7: =vals_ghg_incLUC!$S7 -> 54.361148 | N7: =vals_ghg_incLUC!$Y7 -> 59.020361 | Q7: =IFERROR(MAX(0,$E7-MAX($C7,$D7)),"") -> 4.6592126 | R7: 40.186 | S7: 58.776
A8: =vals_ghg_incLUC!$A8 -> 1855 | B8: =IFERROR(_xlfn.AGGREGATE(5,6,I8:L8),"") -> 36.796074 | C8: =IFERROR(_xlfn.AGGREGATE(4,6,I8:L8),"") -> 45.775608 | D8: =IFERROR(_xlfn.AGGREGATE(5,6,M8:P8),"") -> 54.491999 | E8: =IFERROR(_xlfn.AGGREGATE(4,6,M8:P8),"") -> 59.706023 | F8: =IFERROR(MIN(C8,D8)-B8,"") -> 8.9795344 | G8: =IFERROR(MAX(0,C8-D8),"") -> 0 | H8: =IFERROR(MAX(0,D8-C8),"") -> 8.7163914 | I8: =vals_ghg_incLUC!$R8 -> 36.796074 | J8: =vals_ghg_incLUC!$X8 -> 45.775608 | M8: =vals_ghg_incLUC!$S8 -> 54.491999 | N8: =vals_ghg_incLUC!$Y8 -> 59.706023 | Q8: =IFERROR(MAX(0,$E8-MAX($C8,$D8)),"") -> 5.2140237 | R8: 40.424 | S8: 58.975
A9: =vals_ghg_incLUC!$A9 -> 1856 | B9: =IFERROR(_xlfn.AGGREGATE(5,6,I9:L9),"") -> 36.964209 | C9: =IFERROR(_xlfn.AGGREGATE(4,6,I9:L9),"") -> 46.378247 | D9: =IFERROR(_xlfn.AGGREGATE(5,6,M9:P9),"") -> 54.631743 | E9: =IFERROR(_xlfn.AGGREGATE(4,6,M9:P9),"") -> 60.279378 | F9: =IFERROR(MIN(C9,D9)-B9,"") -> 9.4140373 | G9: =IFERROR(MAX(0,C9-D9),"") -> 0 | H9: =IFERROR(MAX(0,D9-C9),"") -> 8.2534969 | I9: =vals_ghg_incLUC!$R9 -> 36.964209 | J9: =vals_ghg_incLUC!$X9 -> 46.378247 | M9: =vals_ghg_incLUC!$S9 -> 54.631743 | N9: =vals_ghg_incLUC!$Y9 -> 60.279378 | Q9: =IFERROR(MAX(0,$E9-MAX($C9,$D9)),"") -> 5.6476346 | R9: 40.637 | S9: 59.168
A10: =vals_ghg_incLUC!$A10 -> 1857 | B10: =IFERROR(_xlfn.AGGREGATE(5,6,I10:L10),"") -> 37.099804 | C10: =IFERROR(_xlfn.AGGREGATE(4,6,I10:L10),"") -> 46.877214 | D10: =IFERROR(_xlfn.AGGREGATE(5,6,M10:P10),"") -> 54.753306 | E10: =IFERROR(_xlfn.AGGREGATE(4,6,M10:P10),"") -> 60.755482 | F10: =IFERROR(MIN(C10,D10)-B10,"") -> 9.7774106 | G10: =IFERROR(MAX(0,C10-D10),"") -> 0 | H10: =IFERROR(MAX(0,D10-C10),"") -> 7.8760913 | I10: =vals_ghg_incLUC!$R10 -> 37.099804 | J10: =vals_ghg_incLUC!$X10 -> 46.877214 | M10: =vals_ghg_incLUC!$S10 -> 54.753306 | N10: =vals_ghg_incLUC!$Y10 -> 60.755482 | Q10: =IFERROR(MAX(0,$E10-MAX($C10,$D10)),"") -> 6.0021766 | R10: 40.802 | S10: 59.33
A11: =vals_ghg_incLUC!$A11 -> 1858 | B11: =IFERROR(_xlfn.AGGREGATE(5,6,I11:L11),"") -> 37.249018 | C11: =IFERROR(_xlfn.AGGREGATE(4,6,I11:L11),"") -> 47.30341 | D11: =IFERROR(_xlfn.AGGREGATE(5,6,M11:P11),"") -> 54.887818 | E11: =IFERROR(_xlfn.AGGREGATE(4,6,M11:P11),"") -> 61.164526 | F11: =IFERROR(MIN(C11,D11)-B11,"") -> 10.054392 | G11: =IFERROR(MAX(0,C11-D11),"") -> 0 | H11: =IFERROR(MAX(0,D11-C11),"") -> 7.5844081 | I11: =vals_ghg_incLUC!$R11 -> 37.249018 | J11: =vals_ghg_incLUC!$X11 -> 47.30341 | M11: =vals_ghg_incLUC!$S11 -> 54.887818 | N11: =vals_ghg_incLUC!$Y11 -> 61.164526 | Q11: =IFERROR(MAX(0,$E11-MAX($C11,$D11)),"") -> 6.2767085 | R11: 40.973 | S11: 59.501
A12: =vals_ghg_incLUC!$A12 -> 1859 | B12: =IFERROR(_xlfn.AGGREGATE(5,6,I12:L12),"") -> 37.419861 | C12: =IFERROR(_xlfn.AGGREGATE(4,6,I12:L12),"") -> 47.701547 | D12: =IFERROR(_xlfn.AGGREGATE(5,6,M12:P12),"") -> 55.037885 | E12: =IFERROR(_xlfn.AGGREGATE(4,6,M12:P12),"") -> 61.54028 | F12: =IFERROR(MIN(C12,D12)-B12,"") -> 10.281686 | G12: =IFERROR(MAX(0,C12-D12),"") -> 0 | H12: =IFERROR(MAX(0,D12-C12),"") -> 7.3363377 | I12: =vals_ghg_incLUC!$R12 -> 37.419861 | J12: =vals_ghg_incLUC!$X12 -> 47.701547 | M12: =vals_ghg_incLUC!$S12 -> 55.037885 | N12: =vals_ghg_incLUC!$Y12 -> 61.54028 | Q12: =IFERROR(MAX(0,$E12-MAX($C12,$D12)),"") -> 6.5023953 | R12: 41.18 | S12: 59.695
A13: =vals_ghg_incLUC!$A13 -> 1860 | B13: =IFERROR(_xlfn.AGGREGATE(5,6,I13:L13),"") -> 37.673572 | C13: =IFERROR(_xlfn.AGGREGATE(4,6,I13:L13),"") -> 48.092976 | D13: =IFERROR(_xlfn.AGGREGATE(5,6,M13:P13),"") -> 55.29047 | E13: =IFERROR(_xlfn.AGGREGATE(4,6,M13:P13),"") -> 61.904434 | F13: =IFERROR(MIN(C13,D13)-B13,"") -> 10.419404 | G13: =IFERROR(MAX(0,C13-D13),"") -> 0 | H13: =IFERROR(MAX(0,D13-C13),"") -> 7.197494 | I13: =vals_ghg_incLUC!$R13 -> 37.673572 | J13: =vals_ghg_incLUC!$X13 -> 48.092976 | M13: =vals_ghg_incLUC!$S13 -> 55.29047 | N13: =vals_ghg_incLUC!$Y13 -> 61.904434 | Q13: =IFERROR(MAX(0,$E13-MAX($C13,$D13)),"") -> 6.6139634 | R13: 41.52 | S13: 60.044
A14: =vals_ghg_incLUC!$A14 -> 1861 | B14: =IFERROR(_xlfn.AGGREGATE(5,6,I14:L14),"") -> 37.873267 | C14: =IFERROR(_xlfn.AGGREGATE(4,6,I14:L14),"") -> 48.434068 | D14: =IFERROR(_xlfn.AGGREGATE(5,6,M14:P14),"") -> 55.52958 | E14: =IFERROR(_xlfn.AGGREGATE(4,6,M14:P14),"") -> 62.239512 | F14: =IFERROR(MIN(C14,D14)-B14,"") -> 10.560801 | G14: =IFERROR(MAX(0,C14-D14),"") -> 0 | H14: =IFERROR(MAX(0,D14-C14),"") -> 7.095512 | I14: =vals_ghg_incLUC!$R14 -> 37.873267 | J14: =vals_ghg_incLUC!$X14 -> 48.434068 | M14: =vals_ghg_incLUC!$S14 -> 55.52958 | N14: =vals_ghg_incLUC!$Y14 -> 62.239512 | Q14: =IFERROR(MAX(0,$E14-MAX($C14,$D14)),"") -> 6.7099316 | R14: 41.801 | S14: 60.385
A15: =vals_ghg_incLUC!$A15 -> 1862 | B15: =IFERROR(_xlfn.AGGREGATE(5,6,I15:L15),"") -> 38.094749 | C15: =IFERROR(_xlfn.AGGREGATE(4,6,I15:L15),"") -> 48.563022 | D15: =IFERROR(_xlfn.AGGREGATE(5,6,M15:P15),"") -> 55.792763 | E15: =IFERROR(_xlfn.AGGREGATE(4,6,M15:P15),"") -> 62.373435 | F15: =IFERROR(MIN(C15,D15)-B15,"") -> 10.468273 | G15: =IFERROR(MAX(0,C15-D15),"") -> 0 | H15: =IFERROR(MAX(0,D15-C15),"") -> 7.2297416 | I15: =vals_ghg_incLUC!$R15 -> 38.094749 | J15: =vals_ghg_incLUC!$X15 -> 48.563022 | M15: =vals_ghg_incLUC!$S15 -> 55.792763 | N15: =vals_ghg_incLUC!$Y15 -> 62.373435 | Q15: =IFERROR(MAX(0,$E15-MAX($C15,$D15)),"") -> 6.5806719 | R15: 42.097 | S15: 60.75
... A177: =vals_ghg_incLUC!$A177 -> 2024 | B177: =IFERROR(_xlfn.AGGREGATE(5,6,I177:L177),"") -> 36.435552 | C177: =IFERROR(_xlfn.AGGREGATE(4,6,I177:L177),"") -> 39.454285 | D177: =IFERROR(_xlfn.AGGREGATE(5,6,M177:P177),"") -> 49.389956 | E177: =IFERROR(_xlfn.AGGREGATE(4,6,M177:P177),"") -> 50.956621 | F177: =IFERROR(MIN(C177,D177)-B177,"") -> 3.0187333 | G177: =IFERROR(MAX(0,C177-D177),"") -> 0 | H177: =IFERROR(MAX(0,D177-C177),"") -> 9.9356706 | I177: =vals_ghg_incLUC!$R177 -> 36.435552 | J177: =vals_ghg_incLUC!$X177 -> 39.454285 | M177: =vals_ghg_incLUC!$S177 -> 49.389956 | N177: =vals_ghg_incLUC!$Y177 -> 50.956621 | Q177: =IFERROR(MAX(0,$E177-MAX($C177,$D177)),"") -> 1.5666652 | R177: 34.289 | S177: 46.369

Sheet vals_ghg_excLUC
A2: Year | B2: annex2_OWID | C2: annex1_OWID | D2: non_annex1_OWID | E2: annex2_PRIMAP | F2: annex1_PRIMAP | G2: non_annex1_PRIMAP | N2: cum_annex2_OWID | O2: cum_annex1_OWID | P2: cum_non_ann1_OWID | Q2: cum_world_OWID | R2: pct_annex2_OWID | S2: pct_annex1_OWID | T2: cum_annex2_PRIMAP | U2: cum_annex1_PRIMAP | V2: cum_non_ann1_PRIMAP | W2: cum_world_PRIMAP | X2: pct_annex2_PRIMAP | Y2: pct_annex1_PRIMAP
A3: 1850 | B3: 375.324 | C3: 451.719 | D3: 230.605 | E3: 608.538 | F3: 805.61 | G3: 757.79 | N3: =IFERROR(SUM($B$3:$B3),"") -> 375.324 | O3: =IFERROR(SUM($C$3:$C3),"") -> 451.719 | P3: =IFERROR(SUM($D$3:$D3),"") -> 230.605 | Q3: =IFERROR(O3+P3,"") -> 682.324 | R3: =IFERROR(N3/Q3*100,NA()) -> 55.006712 | S3: =IFERROR(O3/Q3*100,NA()) -> 66.203006 | T3: =IFERROR(SUM($E$3:$E3),"") -> 608.538 | U3: =IFERROR(SUM($F$3:$F3),"") -> 805.61 | V3: =IFERROR(SUM($G$3:$G3),"") -> 757.79 | W3: =IFERROR(U3+V3,"") -> 1563.4 | X3: =IFERROR(T3/W3*100,NA()) -> 38.924012 | Y3: =IFERROR(U3/W3*100,NA()) -> 51.529359
A4: 1851 | B4: 377.222 | C4: 454.879 | D4: 230.577 | E4: 614.065 | F4: 813.995 | G4: 759.213 | N4: =IFERROR(SUM($B$3:$B4),"") -> 752.546 | O4: =IFERROR(SUM($C$3:$C4),"") -> 906.598 | P4: =IFERROR(SUM($D$3:$D4),"") -> 461.182 | Q4: =IFERROR(O4+P4,"") -> 1367.78 | R4: =IFERROR(N4/Q4*100,NA()) -> 55.019521 | S4: =IFERROR(O4/Q4*100,NA()) -> 66.282443 | T4: =IFERROR(SUM($E$3:$E4),"") -> 1222.603 | U4: =IFERROR(SUM($F$3:$F4),"") -> 1619.605 | V4: =IFERROR(SUM($G$3:$G4),"") -> 1517.003 | W4: =IFERROR(U4+V4,"") -> 3136.608 | X4: =IFERROR(T4/W4*100,NA()) -> 38.978508 | Y4: =IFERROR(U4/W4*100,NA()) -> 51.635557
A5: 1852 | B5: 387.491 | C5: 466.759 | D5: 230.704 | E5: 627.68 | F5: 830.761 | G5: 760.709 | N5: =IFERROR(SUM($B$3:$B5),"") -> 1140.037 | O5: =IFERROR(SUM($C$3:$C5),"") -> 1373.357 | P5: =IFERROR(SUM($D$3:$D5),"") -> 691.886 | Q5: =IFERROR(O5+P5,"") -> 2065.243 | R5: =IFERROR(N5/Q5*100,NA()) -> 55.201107 | S5: =IFERROR(O5/Q5*100,NA()) -> 66.498567 | T5: =IFERROR(SUM($E$3:$E5),"") -> 1850.283 | U5: =IFERROR(SUM($F$3:$F5),"") -> 2450.366 | V5: =IFERROR(SUM($G$3:$G5),"") -> 2277.712 | W5: =IFERROR(U5+V5,"") -> 4728.078 | X5: =IFERROR(T5/W5*100,NA()) -> 39.133936 | Y5: =IFERROR(U5/W5*100,NA()) -> 51.825837
A6: 1853 | B6: 400.152 | C6: 480.441 | D6: 230.707 | E6: 643.593 | F6: 849.23 | G6: 762.197 | N6: =IFERROR(SUM($B$3:$B6),"") -> 1540.189 | O6: =IFERROR(SUM($C$3:$C6),"") -> 1853.798 | P6: =IFERROR(SUM($D$3:$D6),"") -> 922.593 | Q6: =IFERROR(O6+P6,"") -> 2776.391 | R6: =IFERROR(N6/Q6*100,NA()) -> 55.474499 | S6: =IFERROR(O6/Q6*100,NA()) -> 66.770062 | T6: =IFERROR(SUM($E$3:$E6),"") -> 2493.876 | U6: =IFERROR(SUM($F$3:$F6),"") -> 3299.596 | V6: =IFERROR(SUM($G$3:$G6),"") -> 3039.909 | W6: =IFERROR(U6+V6,"") -> 6339.505 | X6: =IFERROR(T6/W6*100,NA()) -> 39.338655 | Y6: =IFERROR(U6/W6*100,NA()) -> 52.048165
A7: 1854 | B7: 445.605 | C7: 527.311 | D7: 230.666 | E7: 692.777 | F7: 901.346 | G7: 763.664 | N7: =IFERROR(SUM($B$3:$B7),"") -> 1985.794 | O7: =IFERROR(SUM($C$3:$C7),"") -> 2381.109 | P7: =IFERROR(SUM($D$3:$D7),"") -> 1153.259 | Q7: =IFERROR(O7+P7,"") -> 3534.368 | R7: =IFERROR(N7/Q7*100,NA()) -> 56.185264 | S7: =IFERROR(O7/Q7*100,NA()) -> 67.370149 | T7: =IFERROR(SUM($E$3:$E7),"") -> 3186.653 | U7: =IFERROR(SUM($F$3:$F7),"") -> 4200.942 | V7: =IFERROR(SUM($G$3:$G7),"") -> 3803.573 | W7: =IFERROR(U7+V7,"") -> 8004.515 | X7: =IFERROR(T7/W7*100,NA()) -> 39.810694 | Y7: =IFERROR(U7/W7*100,NA()) -> 52.482155
A8: 1855 | B8: 451.437 | C8: 535.244 | D8: 230.934 | E8: 701.781 | F8: 913.68 | G8: 765.098 | N8: =IFERROR(SUM($B$3:$B8),"") -> 2437.231 | O8: =IFERROR(SUM($C$3:$C8),"") -> 2916.353 | P8: =IFERROR(SUM($D$3:$D8),"") -> 1384.193 | Q8: =IFERROR(O8+P8,"") -> 4300.546 | R8: =IFERROR(N8/Q8*100,NA()) -> 56.672595 | S8: =IFERROR(O8/Q8*100,NA()) -> 67.813552 | T8: =IFERROR(SUM($E$3:$E8),"") -> 3888.434 | U8: =IFERROR(SUM($F$3:$F8),"") -> 5114.622 | V8: =IFERROR(SUM($G$3:$G8),"") -> 4568.671 | W8: =IFERROR(U8+V8,"") -> 9683.293 | X8: =IFERROR(T8/W8*100,NA()) -> 40.156112 | Y8: =IFERROR(U8/W8*100,NA()) -> 52.819036
A9: 1856 | B9: 472.505 | C9: 557.571 | D9: 231.735 | E9: 725.99 | F9: 940.886 | G9: 766.465 | N9: =IFERROR(SUM($B$3:$B9),"") -> 2909.736 | O9: =IFERROR(SUM($C$3:$C9),"") -> 3473.924 | P9: =IFERROR(SUM($D$3:$D9),"") -> 1615.928 | Q9: =IFERROR(O9+P9,"") -> 5089.852 | R9: =IFERROR(N9/Q9*100,NA()) -> 57.167399 | S9: =IFERROR(O9/Q9*100,NA()) -> 68.251965 | T9: =IFERROR(SUM($E$3:$E9),"") -> 4614.424 | U9: =IFERROR(SUM($F$3:$F9),"") -> 6055.508 | V9: =IFERROR(SUM($G$3:$G9),"") -> 5335.136 | W9: =IFERROR(U9+V9,"") -> 11390.644 | X9: =IFERROR(T9/W9*100,NA()) -> 40.510651 | Y9: =IFERROR(U9/W9*100,NA()) -> 53.162121
A10: 1857 | B10: 476.111 | C10: 562.515 | D10: 232.112 | E10: 732.441 | F10: 950.099 | G10: 767.81 | N10: =IFERROR(SUM($B$3:$B10),"") -> 3385.847 | O10: =IFERROR(SUM($C$3:$C10),"") -> 4036.439 | P10: =IFERROR(SUM($D$3:$D10),"") -> 1848.04 | Q10: =IFERROR(O10+P10,"") -> 5884.479 | R10: =IFERROR(N10/Q10*100,NA()) -> 57.538603 | S10: =IFERROR(O10/Q10*100,NA()) -> 68.594671 | T10: =IFERROR(SUM($E$3:$E10),"") -> 5346.865 | U10: =IFERROR(SUM($F$3:$F10),"") -> 7005.607 | V10: =IFERROR(SUM($G$3:$G10),"") -> 6102.946 | W10: =IFERROR(U10+V10,"") -> 13108.553 | X10: =IFERROR(T10/W10*100,NA()) -> 40.789132 | Y10: =IFERROR(U10/W10*100,NA()) -> 53.443023
A11: 1858 | B11: 479.735 | C11: 568.363 | D11: 232.806 | E11: 738.925 | F11: 959.834 | G11: 769.603 | N11: =IFERROR(SUM($B$3:$B11),"") -> 3865.582 | O11: =IFERROR(SUM($C$3:$C11),"") -> 4604.802 | P11: =IFERROR(SUM($D$3:$D11),"") -> 2080.846 | Q11: =IFERROR(O11+P11,"") -> 6685.648 | R11: =IFERROR(N11/Q11*100,NA()) -> 57.819107 | S11: =IFERROR(O11/Q11*100,NA()) -> 68.875926 | T11: =IFERROR(SUM($E$3:$E11),"") -> 6085.79 | U11: =IFERROR(SUM($F$3:$F11),"") -> 7965.441 | V11: =IFERROR(SUM($G$3:$G11),"") -> 6872.549 | W11: =IFERROR(U11+V11,"") -> 14837.99 | X11: =IFERROR(T11/W11*100,NA()) -> 41.014922 | Y11: =IFERROR(U11/W11*100,NA()) -> 53.682749
A12: 1859 | B12: 501.616 | C12: 590.795 | D12: 232.95 | E12: 762.946 | F12: 985.666 | G12: 771.134 | N12: =IFERROR(SUM($B$3:$B12),"") -> 4367.198 | O12: =IFERROR(SUM($C$3:$C12),"") -> 5195.597 | P12: =IFERROR(SUM($D$3:$D12),"") -> 2313.796 | Q12: =IFERROR(O12+P12,"") -> 7509.393 | R12: =IFERROR(N12/Q12*100,NA()) -> 58.156472 | S12: =IFERROR(O12/Q12*100,NA()) -> 69.187976 | T12: =IFERROR(SUM($E$3:$E12),"") -> 6848.736 | U12: =IFERROR(SUM($F$3:$F12),"") -> 8951.107 | V12: =IFERROR(SUM($G$3:$G12),"") -> 7643.683 | W12: =IFERROR(U12+V12,"") -> 16594.79 | X12: =IFERROR(T12/W12*100,NA()) -> 41.270399 | Y12: =IFERROR(U12/W12*100,NA()) -> 53.93926
A13: 1860 | B13: 536.458 | C13: 627.41 | D13: 233.314 | E13: 800.308 | F13: 1026.084 | G13: 772.319 | N13: =IFERROR(SUM($B$3:$B13),"") -> 4903.656 | O13: =IFERROR(SUM($C$3:$C13),"") -> 5823.007 | P13: =IFERROR(SUM($D$3:$D13),"") -> 2547.11 | Q13: =IFERROR(O13+P13,"") -> 8370.117 | R13: =IFERROR(N13/Q13*100,NA()) -> 58.585274 | S13: =IFERROR(O13/Q13*100,NA()) -> 69.569004 | T13: =IFERROR(SUM($E$3:$E13),"") -> 7649.044 | U13: =IFERROR(SUM($F$3:$F13),"") -> 9977.191 | V13: =IFERROR(SUM($G$3:$G13),"") -> 8416.002 | W13: =IFERROR(U13+V13,"") -> 18393.193 | X13: =IFERROR(T13/W13*100,NA()) -> 41.586276 | Y13: =IFERROR(U13/W13*100,NA()) -> 54.243931
A14: 1861 | B14: 555.284 | C14: 648.157 | D14: 233.668 | E14: 822.72 | F14: 1051.491 | G14: 774.237 | N14: =IFERROR(SUM($B$3:$B14),"") -> 5458.94 | O14: =IFERROR(SUM($C$3:$C14),"") -> 6471.164 | P14: =IFERROR(SUM($D$3:$D14),"") -> 2780.778 | Q14: =IFERROR(O14+P14,"") -> 9251.942 | R14: =IFERROR(N14/Q14*100,NA()) -> 59.00318 | S14: =IFERROR(O14/Q14*100,NA()) -> 69.943845 | T14: =IFERROR(SUM($E$3:$E14),"") -> 8471.764 | U14: =IFERROR(SUM($F$3:$F14),"") -> 11028.682 | V14: =IFERROR(SUM($G$3:$G14),"") -> 9190.239 | W14: =IFERROR(U14+V14,"") -> 20218.921 | X14: =IFERROR(T14/W14*100,NA()) -> 41.900179 | Y14: =IFERROR(U14/W14*100,NA()) -> 54.546343
... A177: 2024 | B177: 10139.766 | C177: 13930.996 | D177: 29763.416 | E177: 8641.151 | F177: 11449.105 | G177: 24074.701 | N177: =IFERROR(SUM($B$3:$B177),"") -> 1011066.5 | O177: =IFERROR(SUM($C$3:$C177),"") -> 1309544.7 | P177: =IFERROR(SUM($D$3:$D177),"") -> 894998.05 | Q177: =IFERROR(O177+P177,"") -> 2204542.7 | R177: =IFERROR(N177/Q177*100,NA()) -> 45.862869 | S177: =IFERROR(O177/Q177*100,NA()) -> 59.4021 | T177: =IFERROR(SUM($E$3:$E177),"") -> 1175341.4 | U177: =IFERROR(SUM($F$3:$F177),"") -> 1536110 | V177: =IFERROR(SUM($G$3:$G177),"") -> 1199590 | W177: =IFERROR(U177+V177,"") -> 2735700.1 | X177: =IFERROR(T177/W177*100,NA()) -> 42.963096 | Y177: =IFERROR(U177/W177*100,NA()) -> 56.150528

Sheet GHG excl LULUCF

Sheet data_ghg_excLUC
A1: Cumulative GHG emissions excluding LULUCF since 1850, different end points
A2: Year | B2: AII_Min | C2: AII_Max | D2: AI_Min | E2: AI_Max | F2: Pure_AII | G2: Overlap | H2: AI_Gap | I2: pct_annex2_OWID | J2: pct_annex2_PRIMAP | M2: pct_annex1_OWID | N2: pct_annex1_PRIMAP | Q2: Pure_AI | R2: Annex II GMST | S2: Annex I GMST
A3: =vals_ghg_excLUC!$A3 -> 1850 | B3: =IFERROR(_xlfn.AGGREGATE(5,6,I3:L3),"") -> 38.924012 | C3: =IFERROR(_xlfn.AGGREGATE(4,6,I3:L3),"") -> 55.006712 | D3: =IFERROR(_xlfn.AGGREGATE(5,6,M3:P3),"") -> 51.529359 | E3: =IFERROR(_xlfn.AGGREGATE(4,6,M3:P3),"") -> 66.203006 | F3: =IFERROR(MIN(C3,D3)-B3,"") -> 12.605347 | G3: =IFERROR(MAX(0,C3-D3),"") -> 3.4773533 | H3: =IFERROR(MAX(0,D3-C3),"") -> 0 | I3: =vals_ghg_excLUC!$R3 -> 55.006712 | J3: =vals_ghg_excLUC!$X3 -> 38.924012 | M3: =vals_ghg_excLUC!$S3 -> 66.203006 | N3: =vals_ghg_excLUC!$Y3 -> 51.529359 | Q3: =IFERROR(MAX(0,$E3-MAX($C3,$D3)),"") -> 11.196294
A4: =vals_ghg_excLUC!$A4 -> 1851 | B4: =IFERROR(_xlfn.AGGREGATE(5,6,I4:L4),"") -> 38.978508 | C4: =IFERROR(_xlfn.AGGREGATE(4,6,I4:L4),"") -> 55.019521 | D4: =IFERROR(_xlfn.AGGREGATE(5,6,M4:P4),"") -> 51.635557 | E4: =IFERROR(_xlfn.AGGREGATE(4,6,M4:P4),"") -> 66.282443 | F4: =IFERROR(MIN(C4,D4)-B4,"") -> 12.657049 | G4: =IFERROR(MAX(0,C4-D4),"") -> 3.3839641 | H4: =IFERROR(MAX(0,D4-C4),"") -> 0 | I4: =vals_ghg_excLUC!$R4 -> 55.019521 | J4: =vals_ghg_excLUC!$X4 -> 38.978508 | M4: =vals_ghg_excLUC!$S4 -> 66.282443 | N4: =vals_ghg_excLUC!$Y4 -> 51.635557 | Q4: =IFERROR(MAX(0,$E4-MAX($C4,$D4)),"") -> 11.262922 | R4: 68.613 | S4: 80.698
A5: =vals_ghg_excLUC!$A5 -> 1852 | B5: =IFERROR(_xlfn.AGGREGATE(5,6,I5:L5),"") -> 39.133936 | C5: =IFERROR(_xlfn.AGGREGATE(4,6,I5:L5),"") -> 55.201107 | D5: =IFERROR(_xlfn.AGGREGATE(5,6,M5:P5),"") -> 51.825837 | E5: =IFERROR(_xlfn.AGGREGATE(4,6,M5:P5),"") -> 66.498567 | F5: =IFERROR(MIN(C5,D5)-B5,"") -> 12.691901 | G5: =IFERROR(MAX(0,C5-D5),"") -> 3.37527 | H5: =IFERROR(MAX(0,D5-C5),"") -> 0 | I5: =vals_ghg_excLUC!$R5 -> 55.201107 | J5: =vals_ghg_excLUC!$X5 -> 39.133936 | M5: =vals_ghg_excLUC!$S5 -> 66.498567 | N5: =vals_ghg_excLUC!$Y5 -> 51.825837 | Q5: =IFERROR(MAX(0,$E5-MAX($C5,$D5)),"") -> 11.29746 | R5: 68.953 | S5: 81.052
A6: =vals_ghg_excLUC!$A6 -> 1853 | B6: =IFERROR(_xlfn.AGGREGATE(5,6,I6:L6),"") -> 39.338655 | C6: =IFERROR(_xlfn.AGGREGATE(4,6,I6:L6),"") -> 55.474499 | D6: =IFERROR(_xlfn.AGGREGATE(5,6,M6:P6),"") -> 52.048165 | E6: =IFERROR(_xlfn.AGGREGATE(4,6,M6:P6),"") -> 66.770062 | F6: =IFERROR(MIN(C6,D6)-B6,"") -> 12.70951 | G6: =IFERROR(MAX(0,C6-D6),"") -> 3.4263344 | H6: =IFERROR(MAX(0,D6-C6),"") -> 0 | I6: =vals_ghg_excLUC!$R6 -> 55.474499 | J6: =vals_ghg_excLUC!$X6 -> 39.338655 | M6: =vals_ghg_excLUC!$S6 -> 66.770062 | N6: =vals_ghg_excLUC!$Y6 -> 52.048165 | Q6: =IFERROR(MAX(0,$E6-MAX($C6,$D6)),"") -> 11.295563 | R6: 69.393 | S6: 81.446
A7: =vals_ghg_excLUC!$A7 -> 1854 | B7: =IFERROR(_xlfn.AGGREGATE(5,6,I7:L7),"") -> 39.810694 | C7: =IFERROR(_xlfn.AGGREGATE(4,6,I7:L7),"") -> 56.185264 | D7: =IFERROR(_xlfn.AGGREGATE(5,6,M7:P7),"") -> 52.482155 | E7: =IFERROR(_xlfn.AGGREGATE(4,6,M7:P7),"") -> 67.370149 | F7: =IFERROR(MIN(C7,D7)-B7,"") -> 12.671461 | G7: =IFERROR(MAX(0,C7-D7),"") -> 3.7031089 | H7: =IFERROR(MAX(0,D7-C7),"") -> 0 | I7: =vals_ghg_excLUC!$R7 -> 56.185264 | J7: =vals_ghg_excLUC!$X7 -> 39.810694 | M7: =vals_ghg_excLUC!$S7 -> 67.370149 | N7: =vals_ghg_excLUC!$Y7 -> 52.482155 | Q7: =IFERROR(MAX(0,$E7-MAX($C7,$D7)),"") -> 11.184885 | R7: 70.389 | S7: 82.179
A8: =vals_ghg_excLUC!$A8 -> 1855 | B8: =IFERROR(_xlfn.AGGREGATE(5,6,I8:L8),"") -> 40.156112 | C8: =IFERROR(_xlfn.AGGREGATE(4,6,I8:L8),"") -> 56.672595 | D8: =IFERROR(_xlfn.AGGREGATE(5,6,M8:P8),"") -> 52.819036 | E8: =IFERROR(_xlfn.AGGREGATE(4,6,M8:P8),"") -> 67.813552 | F8: =IFERROR(MIN(C8,D8)-B8,"") -> 12.662924 | G8: =IFERROR(MAX(0,C8-D8),"") -> 3.8535588 | H8: =IFERROR(MAX(0,D8-C8),"") -> 0 | I8: =vals_ghg_excLUC!$R8 -> 56.672595 | J8: =vals_ghg_excLUC!$X8 -> 40.156112 | M8: =vals_ghg_excLUC!$S8 -> 67.813552 | N8: =vals_ghg_excLUC!$Y8 -> 52.819036 | Q8: =IFERROR(MAX(0,$E8-MAX($C8,$D8)),"") -> 11.140957 | R8: 71.014 | S8: 82.698
A9: =vals_ghg_excLUC!$A9 -> 1856 | B9: =IFERROR(_xlfn.AGGREGATE(5,6,I9:L9),"") -> 40.510651 | C9: =IFERROR(_xlfn.AGGREGATE(4,6,I9:L9),"") -> 57.167399 | D9: =IFERROR(_xlfn.AGGREGATE(5,6,M9:P9),"") -> 53.162121 | E9: =IFERROR(_xlfn.AGGREGATE(4,6,M9:P9),"") -> 68.251965 | F9: =IFERROR(MIN(C9,D9)-B9,"") -> 12.651471 | G9: =IFERROR(MAX(0,C9-D9),"") -> 4.0052775 | H9: =IFERROR(MAX(0,D9-C9),"") -> 0 | I9: =vals_ghg_excLUC!$R9 -> 57.167399 | J9: =vals_ghg_excLUC!$X9 -> 40.510651 | M9: =vals_ghg_excLUC!$S9 -> 68.251965 | N9: =vals_ghg_excLUC!$Y9 -> 53.162121 | Q9: =IFERROR(MAX(0,$E9-MAX($C9,$D9)),"") -> 11.084566 | R9: 71.563 | S9: 83.153
A10: =vals_ghg_excLUC!$A10 -> 1857 | B10: =IFERROR(_xlfn.AGGREGATE(5,6,I10:L10),"") -> 40.789132 | C10: =IFERROR(_xlfn.AGGREGATE(4,6,I10:L10),"") -> 57.538603 | D10: =IFERROR(_xlfn.AGGREGATE(5,6,M10:P10),"") -> 53.443023 | E10: =IFERROR(_xlfn.AGGREGATE(4,6,M10:P10),"") -> 68.594671 | F10: =IFERROR(MIN(C10,D10)-B10,"") -> 12.653891 | G10: =IFERROR(MAX(0,C10-D10),"") -> 4.0955798 | H10: =IFERROR(MAX(0,D10-C10),"") -> 0 | I10: =vals_ghg_excLUC!$R10 -> 57.538603 | J10: =vals_ghg_excLUC!$X10 -> 40.789132 | M10: =vals_ghg_excLUC!$S10 -> 68.594671 | N10: =vals_ghg_excLUC!$Y10 -> 53.443023 | Q10: =IFERROR(MAX(0,$E10-MAX($C10,$D10)),"") -> 11.056068 | R10: 71.979 | S10: 83.522
A11: =vals_ghg_excLUC!$A11 -> 1858 | B11: =IFERROR(_xlfn.AGGREGATE(5,6,I11:L11),"") -> 41.014922 | C11: =IFERROR(_xlfn.AGGREGATE(4,6,I11:L11),"") -> 57.819107 | D11: =IFERROR(_xlfn.AGGREGATE(5,6,M11:P11),"") -> 53.682749 | E11: =IFERROR(_xlfn.AGGREGATE(4,6,M11:P11),"") -> 68.875926 | F11: =IFERROR(MIN(C11,D11)-B11,"") -> 12.667828 | G11: =IFERROR(MAX(0,C11-D11),"") -> 4.136358 | H11: =IFERROR(MAX(0,D11-C11),"") -> 0 | I11: =vals_ghg_excLUC!$R11 -> 57.819107 | J11: =vals_ghg_excLUC!$X11 -> 41.014922 | M11: =vals_ghg_excLUC!$S11 -> 68.875926 | N11: =vals_ghg_excLUC!$Y11 -> 53.682749 | Q11: =IFERROR(MAX(0,$E11-MAX($C11,$D11)),"") -> 11.056819 | R11: 72.269 | S11: 83.821
A12: =vals_ghg_excLUC!$A12 -> 1859 | B12: =IFERROR(_xlfn.AGGREGATE(5,6,I12:L12),"") -> 41.270399 | C12: =IFERROR(_xlfn.AGGREGATE(4,6,I12:L12),"") -> 58.156472 | D12: =IFERROR(_xlfn.AGGREGATE(5,6,M12:P12),"") -> 53.93926 | E12: =IFERROR(_xlfn.AGGREGATE(4,6,M12:P12),"") -> 69.187976 | F12: =IFERROR(MIN(C12,D12)-B12,"") -> 12.668862 | G12: =IFERROR(MAX(0,C12-D12),"") -> 4.217211 | H12: =IFERROR(MAX(0,D12-C12),"") -> 0 | I12: =vals_ghg_excLUC!$R12 -> 58.156472 | J12: =vals_ghg_excLUC!$X12 -> 41.270399 | M12: =vals_ghg_excLUC!$S12 -> 69.187976 | N12: =vals_ghg_excLUC!$Y12 -> 53.93926 | Q12: =IFERROR(MAX(0,$E12-MAX($C12,$D12)),"") -> 11.031504 | R12: 72.65 | S12: 84.156
A13: =vals_ghg_excLUC!$A13 -> 1860 | B13: =IFERROR(_xlfn.AGGREGATE(5,6,I13:L13),"") -> 41.586276 | C13: =IFERROR(_xlfn.AGGREGATE(4,6,I13:L13),"") -> 58.585274 | D13: =IFERROR(_xlfn.AGGREGATE(5,6,M13:P13),"") -> 54.243931 | E13: =IFERROR(_xlfn.AGGREGATE(4,6,M13:P13),"") -> 69.569004 | F13: =IFERROR(MIN(C13,D13)-B13,"") -> 12.657655 | G13: =IFERROR(MAX(0,C13-D13),"") -> 4.3413428 | H13: =IFERROR(MAX(0,D13-C13),"") -> 0 | I13: =vals_ghg_excLUC!$R13 -> 58.585274 | J13: =vals_ghg_excLUC!$X13 -> 41.586276 | M13: =vals_ghg_excLUC!$S13 -> 69.569004 | N13: =vals_ghg_excLUC!$Y13 -> 54.243931 | Q13: =IFERROR(MAX(0,$E13-MAX($C13,$D13)),"") -> 10.983729 | R13: 73.131 | S13: 84.549
A14: =vals_ghg_excLUC!$A14 -> 1861 | B14: =IFERROR(_xlfn.AGGREGATE(5,6,I14:L14),"") -> 41.900179 | C14: =IFERROR(_xlfn.AGGREGATE(4,6,I14:L14),"") -> 59.00318 | D14: =IFERROR(_xlfn.AGGREGATE(5,6,M14:P14),"") -> 54.546343 | E14: =IFERROR(_xlfn.AGGREGATE(4,6,M14:P14),"") -> 69.943845 | F14: =IFERROR(MIN(C14,D14)-B14,"") -> 12.646164 | G14: =IFERROR(MAX(0,C14-D14),"") -> 4.4568371 | H14: =IFERROR(MAX(0,D14-C14),"") -> 0 | I14: =vals_ghg_excLUC!$R14 -> 59.00318 | J14: =vals_ghg_excLUC!$X14 -> 41.900179 | M14: =vals_ghg_excLUC!$S14 -> 69.943845 | N14: =vals_ghg_excLUC!$Y14 -> 54.546343 | Q14: =IFERROR(MAX(0,$E14-MAX($C14,$D14)),"") -> 10.940665 | R14: 73.562 | S14: 84.919
A15: =vals_ghg_excLUC!$A15 -> 1862 | B15: =IFERROR(_xlfn.AGGREGATE(5,6,I15:L15),"") -> 42.171697 | C15: =IFERROR(_xlfn.AGGREGATE(4,6,I15:L15),"") -> 59.351385 | D15: =IFERROR(_xlfn.AGGREGATE(5,6,M15:P15),"") -> 54.817831 | E15: =IFERROR(_xlfn.AGGREGATE(4,6,M15:P15),"") -> 70.274544 | F15: =IFERROR(MIN(C15,D15)-B15,"") -> 12.646134 | G15: =IFERROR(MAX(0,C15-D15),"") -> 4.5335542 | H15: =IFERROR(MAX(0,D15-C15),"") -> 0 | I15: =vals_ghg_excLUC!$R15 -> 59.351385 | J15: =vals_ghg_excLUC!$X15 -> 42.171697 | M15: =vals_ghg_excLUC!$S15 -> 70.274544 | N15: =vals_ghg_excLUC!$Y15 -> 54.817831 | Q15: =IFERROR(MAX(0,$E15-MAX($C15,$D15)),"") -> 10.923158 | R15: 73.882 | S15: 85.233
... A177: =vals_ghg_excLUC!$A177 -> 2024 | B177: =IFERROR(_xlfn.AGGREGATE(5,6,I177:L177),"") -> 42.963096 | C177: =IFERROR(_xlfn.AGGREGATE(4,6,I177:L177),"") -> 45.862869 | D177: =IFERROR(_xlfn.AGGREGATE(5,6,M177:P177),"") -> 56.150528 | E177: =IFERROR(_xlfn.AGGREGATE(4,6,M177:P177),"") -> 59.4021 | F177: =IFERROR(MIN(C177,D177)-B177,"") -> 2.8997722 | G177: =IFERROR(MAX(0,C177-D177),"") -> 0 | H177: =IFERROR(MAX(0,D177-C177),"") -> 10.287659 | I177: =vals_ghg_excLUC!$R177 -> 45.862869 | J177: =vals_ghg_excLUC!$X177 -> 42.963096 | M177: =vals_ghg_excLUC!$S177 -> 59.4021 | N177: =vals_ghg_excLUC!$Y177 -> 56.150528 | Q177: =IFERROR(MAX(0,$E177-MAX($C177,$D177)),"") -> 3.2515724 | R177: 42.798 | S177: 55.891

Sheet vals_co2_incLUC
A2: Year | B2: annex2_OWID | C2: annex1_OWID | D2: non_annex1_OWID | E2: annex2_PRIMAP | F2: annex1_PRIMAP | G2: non_annex1_PRIMAP | H2: annex2_GCP_BLUE | I2: annex1_GCP_BLUE | J2: non_annex1_GCP_BLUE | K2: annex2_GCP_OSCAR | L2: annex1_GCP_OSCAR | M2: non_annex1_GCP_OSCAR | N2: cum_annex2_OWID | O2: cum_annex1_OWID | P2: cum_non_ann1_OWID | Q2: cum_world_OWID | R2: pct_annex2_OWID | S2: pct_annex1_OWID | T2: cum_annex2_PRIMAP | U2: cum_annex1_PRIMAP | V2: cum_non_ann1_PRIMAP | W2: cum_world_PRIMAP | X2: pct_annex2_PRIMAP | Y2: pct_annex1_PRIMAP | Z2: cum_annex2_GCP_BLUE | AA2: cum_annex1_GCP_BLUE | AB2: cum_non_ann1_GCP_BLUE | AC2: cum_world_GCP_BLUE | AD2: pct_annex2_GCP_BLUE | AE2: pct_annex1_GCP_BLUE | AF2: cum_annex2_GCP_OSCAR | AG2: cum_annex1_GCP_OSCAR | AH2: cum_non_ann1_GCP_OSCAR | AI2: cum_world_GCP_OSCAR | AJ2: pct_annex2_GCP_OSCAR | AK2: pct_annex1_GCP_OSCAR
A3: 1850 | B3: 1290.936 | C3: 2094.882 | D3: 1537.861 | E3: 891.93 | F3: 1211.493 | G3: 823.429 | H3: 1290.936 | I3: 2094.882 | J3: 1537.861 | K3: 1053.273 | L3: 1399.061 | M3: 945.557 | N3: =IFERROR(SUM($B$3:$B3),"") -> 1290.936 | O3: =IFERROR(SUM($C$3:$C3),"") -> 2094.882 | P3: =IFERROR(SUM($D$3:$D3),"") -> 1537.861 | Q3: =IFERROR(O3+P3,"") -> 3632.743 | R3: =IFERROR(N3/Q3*100,NA()) -> 35.536122 | S3: =IFERROR(O3/Q3*100,NA()) -> 57.666672 | T3: =IFERROR(SUM($E$3:$E3),"") -> 891.93 | U3: =IFERROR(SUM($F$3:$F3),"") -> 1211.493 | V3: =IFERROR(SUM($G$3:$G3),"") -> 823.429 | W3: =IFERROR(U3+V3,"") -> 2034.922 | X3: =IFERROR(T3/W3*100,NA()) -> 43.831164 | Y3: =IFERROR(U3/W3*100,NA()) -> 59.535107 | Z3: =IFERROR(SUM($H$3:$H3),"") -> 1290.936 | AA3: =IFERROR(SUM($I$3:$I3),"") -> 2094.882 | AB3: =IFERROR(SUM($J$3:$J3),"") -> 1537.861 | AC3: =IFERROR(AA3+AB3,"") -> 3632.743 | AD3: =IFERROR(Z3/AC3*100,NA()) -> 35.536122 | AE3: =IFERROR(AA3/AC3*100,NA()) -> 57.666672 | AF3: =IFERROR(SUM($K$3:$K3),"") -> 1053.273 | AG3: =IFERROR(SUM($L$3:$L3),"") -> 1399.061 | AH3: =IFERROR(SUM($M$3:$M3),"") -> 945.557 | AI3: =IFERROR(AG3+AH3,"") -> 2344.618 | AJ3: =IFERROR(AF3/AI3*100,NA()) -> 44.923011 | AK3: =IFERROR(AG3/AI3*100,NA()) -> 59.67117
A4: 1851 | B4: 1347.784 | C4: 2157.601 | D4: 1626.338 | E4: 899.51 | F4: 1219.531 | G4: 789.239 | H4: 1347.784 | I4: 2157.601 | J4: 1626.338 | K4: 1086.404 | L4: 1423.289 | M4: 980.535 | N4: =IFERROR(SUM($B$3:$B4),"") -> 2638.72 | O4: =IFERROR(SUM($C$3:$C4),"") -> 4252.483 | P4: =IFERROR(SUM($D$3:$D4),"") -> 3164.199 | Q4: =IFERROR(O4+P4,"") -> 7416.682 | R4: =IFERROR(N4/Q4*100,NA()) -> 35.578174 | S4: =IFERROR(O4/Q4*100,NA()) -> 57.336731 | T4: =IFERROR(SUM($E$3:$E4),"") -> 1791.44 | U4: =IFERROR(SUM($F$3:$F4),"") -> 2431.024 | V4: =IFERROR(SUM($G$3:$G4),"") -> 1612.668 | W4: =IFERROR(U4+V4,"") -> 4043.692 | X4: =IFERROR(T4/W4*100,NA()) -> 44.302088 | Y4: =IFERROR(U4/W4*100,NA()) -> 60.118921 | Z4: =IFERROR(SUM($H$3:$H4),"") -> 2638.72 | AA4: =IFERROR(SUM($I$3:$I4),"") -> 4252.483 | AB4: =IFERROR(SUM($J$3:$J4),"") -> 3164.199 | AC4: =IFERROR(AA4+AB4,"") -> 7416.682 | AD4: =IFERROR(Z4/AC4*100,NA()) -> 35.578174 | AE4: =IFERROR(AA4/AC4*100,NA()) -> 57.336731 | AF4: =IFERROR(SUM($K$3:$K4),"") -> 2139.677 | AG4: =IFERROR(SUM($L$3:$L4),"") -> 2822.35 | AH4: =IFERROR(SUM($M$3:$M4),"") -> 1926.092 | AI4: =IFERROR(AG4+AH4,"") -> 4748.442 | AJ4: =IFERROR(AF4/AI4*100,NA()) -> 45.060611 | AK4: =IFERROR(AG4/AI4*100,NA()) -> 59.43739
A5: 1852 | B5: 1380.203 | C5: 2230.345 | D5: 1683.59 | E5: 1146.19 | F5: 1468.051 | G5: 754.79 | H5: 1380.203 | I5: 2230.345 | J5: 1683.59 | K5: 1103.114 | L5: 1471.461 | M5: 1004.504 | N5: =IFERROR(SUM($B$3:$B5),"") -> 4018.923 | O5: =IFERROR(SUM($C$3:$C5),"") -> 6482.828 | P5: =IFERROR(SUM($D$3:$D5),"") -> 4847.789 | Q5: =IFERROR(O5+P5,"") -> 11330.617 | R5: =IFERROR(N5/Q5*100,NA()) -> 35.469587 | S5: =IFERROR(O5/Q5*100,NA()) -> 57.215137 | T5: =IFERROR(SUM($E$3:$E5),"") -> 2937.63 | U5: =IFERROR(SUM($F$3:$F5),"") -> 3899.075 | V5: =IFERROR(SUM($G$3:$G5),"") -> 2367.458 | W5: =IFERROR(U5+V5,"") -> 6266.533 | X5: =IFERROR(T5/W5*100,NA()) -> 46.878074 | Y5: =IFERROR(U5/W5*100,NA()) -> 62.220609 | Z5: =IFERROR(SUM($H$3:$H5),"") -> 4018.923 | AA5: =IFERROR(SUM($I$3:$I5),"") -> 6482.828 | AB5: =IFERROR(SUM($J$3:$J5),"") -> 4847.789 | AC5: =IFERROR(AA5+AB5,"") -> 11330.617 | AD5: =IFERROR(Z5/AC5*100,NA()) -> 35.469587 | AE5: =IFERROR(AA5/AC5*100,NA()) -> 57.215137 | AF5: =IFERROR(SUM($K$3:$K5),"") -> 3242.791 | AG5: =IFERROR(SUM($L$3:$L5),"") -> 4293.811 | AH5: =IFERROR(SUM($M$3:$M5),"") -> 2930.596 | AI5: =IFERROR(AG5+AH5,"") -> 7224.407 | AJ5: =IFERROR(AF5/AI5*100,NA()) -> 44.886605 | AK5: =IFERROR(AG5/AI5*100,NA()) -> 59.434788
A6: 1853 | B6: 1433.029 | C6: 2259.173 | D6: 1710.368 | E6: 1184.999 | F6: 1508.209 | G6: 718.593 | H6: 1433.029 | I6: 2259.173 | J6: 1710.368 | K6: 1143.791 | L6: 1481.32 | M6: 1002.07 | N6: =IFERROR(SUM($B$3:$B6),"") -> 5451.952 | O6: =IFERROR(SUM($C$3:$C6),"") -> 8742.001 | P6: =IFERROR(SUM($D$3:$D6),"") -> 6558.157 | Q6: =IFERROR(O6+P6,"") -> 15300.158 | R6: =IFERROR(N6/Q6*100,NA()) -> 35.633305 | S6: =IFERROR(O6/Q6*100,NA()) -> 57.136671 | T6: =IFERROR(SUM($E$3:$E6),"") -> 4122.629 | U6: =IFERROR(SUM($F$3:$F6),"") -> 5407.284 | V6: =IFERROR(SUM($G$3:$G6),"") -> 3086.051 | W6: =IFERROR(U6+V6,"") -> 8493.335 | X6: =IFERROR(T6/W6*100,NA()) -> 48.539578 | Y6: =IFERROR(U6/W6*100,NA()) -> 63.665027 | Z6: =IFERROR(SUM($H$3:$H6),"") -> 5451.952 | AA6: =IFERROR(SUM($I$3:$I6),"") -> 8742.001 | AB6: =IFERROR(SUM($J$3:$J6),"") -> 6558.157 | AC6: =IFERROR(AA6+AB6,"") -> 15300.158 | AD6: =IFERROR(Z6/AC6*100,NA()) -> 35.633305 | AE6: =IFERROR(AA6/AC6*100,NA()) -> 57.136671 | AF6: =IFERROR(SUM($K$3:$K6),"") -> 4386.582 | AG6: =IFERROR(SUM($L$3:$L6),"") -> 5775.131 | AH6: =IFERROR(SUM($M$3:$M6),"") -> 3932.666 | AI6: =IFERROR(AG6+AH6,"") -> 9707.797 | AJ6: =IFERROR(AF6/AI6*100,NA()) -> 45.186174 | AK6: =IFERROR(AG6/AI6*100,NA()) -> 59.489614
A7: 1854 | B7: 1499.014 | C7: 2352.142 | D7: 1705.869 | E7: 1251.85 | F7: 1576.832 | G7: 681.931 | H7: 1499.014 | I7: 2352.142 | J7: 1705.869 | K7: 1200.051 | L7: 1558.938 | M7: 1006.056 | N7: =IFERROR(SUM($B$3:$B7),"") -> 6950.966 | O7: =IFERROR(SUM($C$3:$C7),"") -> 11094.143 | P7: =IFERROR(SUM($D$3:$D7),"") -> 8264.026 | Q7: =IFERROR(O7+P7,"") -> 19358.169 | R7: =IFERROR(N7/Q7*100,NA()) -> 35.907146 | S7: =IFERROR(O7/Q7*100,NA()) -> 57.309878 | T7: =IFERROR(SUM($E$3:$E7),"") -> 5374.479 | U7: =IFERROR(SUM($F$3:$F7),"") -> 6984.116 | V7: =IFERROR(SUM($G$3:$G7),"") -> 3767.982 | W7: =IFERROR(U7+V7,"") -> 10752.098 | X7: =IFERROR(T7/W7*100,NA()) -> 49.985398 | Y7: =IFERROR(U7/W7*100,NA()) -> 64.955844 | Z7: =IFERROR(SUM($H$3:$H7),"") -> 6950.966 | AA7: =IFERROR(SUM($I$3:$I7),"") -> 11094.143 | AB7: =IFERROR(SUM($J$3:$J7),"") -> 8264.026 | AC7: =IFERROR(AA7+AB7,"") -> 19358.169 | AD7: =IFERROR(Z7/AC7*100,NA()) -> 35.907146 | AE7: =IFERROR(AA7/AC7*100,NA()) -> 57.309878 | AF7: =IFERROR(SUM($K$3:$K7),"") -> 5586.633 | AG7: =IFERROR(SUM($L$3:$L7),"") -> 7334.069 | AH7: =IFERROR(SUM($M$3:$M7),"") -> 4938.722 | AI7: =IFERROR(AG7+AH7,"") -> 12272.791 | AJ7: =IFERROR(AF7/AI7*100,NA()) -> 45.520477 | AK7: =IFERROR(AG7/AI7*100,NA()) -> 59.75877
A8: 1855 | B8: 1518.949 | C8: 2377.324 | D8: 1754.3 | E8: 1283.286 | F8: 1610.443 | G8: 643.801 | H8: 1518.949 | I8: 2377.324 | J8: 1754.3 | K8: 1212.195 | L8: 1571.616 | M8: 1020.76 | N8: =IFERROR(SUM($B$3:$B8),"") -> 8469.915 | O8: =IFERROR(SUM($C$3:$C8),"") -> 13471.467 | P8: =IFERROR(SUM($D$3:$D8),"") -> 10018.326 | Q8: =IFERROR(O8+P8,"") -> 23489.793 | R8: =IFERROR(N8/Q8*100,NA()) -> 36.057853 | S8: =IFERROR(O8/Q8*100,NA()) -> 57.350301 | T8: =IFERROR(SUM($E$3:$E8),"") -> 6657.765 | U8: =IFERROR(SUM($F$3:$F8),"") -> 8594.559 | V8: =IFERROR(SUM($G$3:$G8),"") -> 4411.783 | W8: =IFERROR(U8+V8,"") -> 13006.342 | X8: =IFERROR(T8/W8*100,NA()) -> 51.188605 | Y8: =IFERROR(U8/W8*100,NA()) -> 66.079756 | Z8: =IFERROR(SUM($H$3:$H8),"") -> 8469.915 | AA8: =IFERROR(SUM($I$3:$I8),"") -> 13471.467 | AB8: =IFERROR(SUM($J$3:$J8),"") -> 10018.326 | AC8: =IFERROR(AA8+AB8,"") -> 23489.793 | AD8: =IFERROR(Z8/AC8*100,NA()) -> 36.057853 | AE8: =IFERROR(AA8/AC8*100,NA()) -> 57.350301 | AF8: =IFERROR(SUM($K$3:$K8),"") -> 6798.828 | AG8: =IFERROR(SUM($L$3:$L8),"") -> 8905.685 | AH8: =IFERROR(SUM($M$3:$M8),"") -> 5959.482 | AI8: =IFERROR(AG8+AH8,"") -> 14865.167 | AJ8: =IFERROR(AF8/AI8*100,NA()) -> 45.736641 | AK8: =IFERROR(AG8/AI8*100,NA()) -> 59.909754
A9: 1856 | B9: 1546.951 | C9: 2411.286 | D9: 1762.129 | E9: 1326.327 | F9: 1655.482 | G9: 637.612 | H9: 1546.95 | I9: 2411.286 | J9: 1762.129 | K9: 1234.154 | L9: 1595.778 | M9: 1034.424 | N9: =IFERROR(SUM($B$3:$B9),"") -> 10016.866 | O9: =IFERROR(SUM($C$3:$C9),"") -> 15882.753 | P9: =IFERROR(SUM($D$3:$D9),"") -> 11780.455 | Q9: =IFERROR(O9+P9,"") -> 27663.208 | R9: =IFERROR(N9/Q9*100,NA()) -> 36.210066 | S9: =IFERROR(O9/Q9*100,NA()) -> 57.414718 | T9: =IFERROR(SUM($E$3:$E9),"") -> 7984.092 | U9: =IFERROR(SUM($F$3:$F9),"") -> 10250.041 | V9: =IFERROR(SUM($G$3:$G9),"") -> 5049.395 | W9: =IFERROR(U9+V9,"") -> 15299.436 | X9: =IFERROR(T9/W9*100,NA()) -> 52.185532 | Y9: =IFERROR(U9/W9*100,NA()) -> 66.996202 | Z9: =IFERROR(SUM($H$3:$H9),"") -> 10016.865 | AA9: =IFERROR(SUM($I$3:$I9),"") -> 15882.753 | AB9: =IFERROR(SUM($J$3:$J9),"") -> 11780.455 | AC9: =IFERROR(AA9+AB9,"") -> 27663.208 | AD9: =IFERROR(Z9/AC9*100,NA()) -> 36.210063 | AE9: =IFERROR(AA9/AC9*100,NA()) -> 57.414718 | AF9: =IFERROR(SUM($K$3:$K9),"") -> 8032.982 | AG9: =IFERROR(SUM($L$3:$L9),"") -> 10501.463 | AH9: =IFERROR(SUM($M$3:$M9),"") -> 6993.906 | AI9: =IFERROR(AG9+AH9,"") -> 17495.369 | AJ9: =IFERROR(AF9/AI9*100,NA()) -> 45.914905 | AK9: =IFERROR(AG9/AI9*100,NA()) -> 60.024244
A10: 1857 | B10: 1571.184 | C10: 2446.174 | D10: 1776.948 | E10: 1353.469 | F10: 1684.382 | G10: 632.513 | H10: 1571.184 | I10: 2446.174 | J10: 1776.948 | K10: 1253.733 | L10: 1622.81 | M10: 1054.564 | N10: =IFERROR(SUM($B$3:$B10),"") -> 11588.05 | O10: =IFERROR(SUM($C$3:$C10),"") -> 18328.927 | P10: =IFERROR(SUM($D$3:$D10),"") -> 13557.403 | Q10: =IFERROR(O10+P10,"") -> 31886.33 | R10: =IFERROR(N10/Q10*100,NA()) -> 36.341749 | S10: =IFERROR(O10/Q10*100,NA()) -> 57.482084 | T10: =IFERROR(SUM($E$3:$E10),"") -> 9337.561 | U10: =IFERROR(SUM($F$3:$F10),"") -> 11934.423 | V10: =IFERROR(SUM($G$3:$G10),"") -> 5681.908 | W10: =IFERROR(U10+V10,"") -> 17616.331 | X10: =IFERROR(T10/W10*100,NA()) -> 53.005141 | Y10: =IFERROR(U10/W10*100,NA()) -> 67.74636 | Z10: =IFERROR(SUM($H$3:$H10),"") -> 11588.049 | AA10: =IFERROR(SUM($I$3:$I10),"") -> 18328.927 | AB10: =IFERROR(SUM($J$3:$J10),"") -> 13557.403 | AC10: =IFERROR(AA10+AB10,"") -> 31886.33 | AD10: =IFERROR(Z10/AC10*100,NA()) -> 36.341746 | AE10: =IFERROR(AA10/AC10*100,NA()) -> 57.482084 | AF10: =IFERROR(SUM($K$3:$K10),"") -> 9286.715 | AG10: =IFERROR(SUM($L$3:$L10),"") -> 12124.273 | AH10: =IFERROR(SUM($M$3:$M10),"") -> 8048.47 | AI10: =IFERROR(AG10+AH10,"") -> 20172.743 | AJ10: =IFERROR(AF10/AI10*100,NA()) -> 46.035956 | AK10: =IFERROR(AG10/AI10*100,NA()) -> 60.102253
A11: 1858 | B11: 1600.233 | C11: 2476.819 | D11: 1775.571 | E11: 1379.76 | F11: 1712.848 | G11: 628.012 | H11: 1600.233 | I11: 2476.819 | J11: 1775.571 | K11: 1279.577 | L11: 1647.578 | M11: 1043.049 | N11: =IFERROR(SUM($B$3:$B11),"") -> 13188.283 | O11: =IFERROR(SUM($C$3:$C11),"") -> 20805.746 | P11: =IFERROR(SUM($D$3:$D11),"") -> 15332.974 | Q11: =IFERROR(O11+P11,"") -> 36138.72 | R11: =IFERROR(N11/Q11*100,NA()) -> 36.493498 | S11: =IFERROR(O11/Q11*100,NA()) -> 57.571895 | T11: =IFERROR(SUM($E$3:$E11),"") -> 10717.321 | U11: =IFERROR(SUM($F$3:$F11),"") -> 13647.271 | V11: =IFERROR(SUM($G$3:$G11),"") -> 6309.92 | W11: =IFERROR(U11+V11,"") -> 19957.191 | X11: =IFERROR(T11/W11*100,NA()) -> 53.70155 | Y11: =IFERROR(U11/W11*100,NA()) -> 68.382725 | Z11: =IFERROR(SUM($H$3:$H11),"") -> 13188.282 | AA11: =IFERROR(SUM($I$3:$I11),"") -> 20805.746 | AB11: =IFERROR(SUM($J$3:$J11),"") -> 15332.974 | AC11: =IFERROR(AA11+AB11,"") -> 36138.72 | AD11: =IFERROR(Z11/AC11*100,NA()) -> 36.493495 | AE11: =IFERROR(AA11/AC11*100,NA()) -> 57.571895 | AF11: =IFERROR(SUM($K$3:$K11),"") -> 10566.292 | AG11: =IFERROR(SUM($L$3:$L11),"") -> 13771.851 | AH11: =IFERROR(SUM($M$3:$M11),"") -> 9091.519 | AI11: =IFERROR(AG11+AH11,"") -> 22863.37 | AJ11: =IFERROR(AF11/AI11*100,NA()) -> 46.214937 | AK11: =IFERROR(AG11/AI11*100,NA()) -> 60.235438
A12: 1859 | B12: 1645.326 | C12: 2527.726 | D12: 1787.971 | E12: 1419.536 | F12: 1753.622 | G12: 624.224 | H12: 1645.326 | I12: 2527.726 | J12: 1787.971 | K12: 1322.812 | L12: 1694.498 | M12: 1049.738 | N12: =IFERROR(SUM($B$3:$B12),"") -> 14833.609 | O12: =IFERROR(SUM($C$3:$C12),"") -> 23333.472 | P12: =IFERROR(SUM($D$3:$D12),"") -> 17120.945 | Q12: =IFERROR(O12+P12,"") -> 40454.417 | R12: =IFERROR(N12/Q12*100,NA()) -> 36.667465 | S12: =IFERROR(O12/Q12*100,NA()) -> 57.678429 | T12: =IFERROR(SUM($E$3:$E12),"") -> 12136.857 | U12: =IFERROR(SUM($F$3:$F12),"") -> 15400.893 | V12: =IFERROR(SUM($G$3:$G12),"") -> 6934.144 | W12: =IFERROR(U12+V12,"") -> 22335.037 | X12: =IFERROR(T12/W12*100,NA()) -> 54.339991 | Y12: =IFERROR(U12/W12*100,NA()) -> 68.953962 | Z12: =IFERROR(SUM($H$3:$H12),"") -> 14833.608 | AA12: =IFERROR(SUM($I$3:$I12),"") -> 23333.472 | AB12: =IFERROR(SUM($J$3:$J12),"") -> 17120.945 | AC12: =IFERROR(AA12+AB12,"") -> 40454.417 | AD12: =IFERROR(Z12/AC12*100,NA()) -> 36.667462 | AE12: =IFERROR(AA12/AC12*100,NA()) -> 57.678429 | AF12: =IFERROR(SUM($K$3:$K12),"") -> 11889.104 | AG12: =IFERROR(SUM($L$3:$L12),"") -> 15466.349 | AH12: =IFERROR(SUM($M$3:$M12),"") -> 10141.257 | AI12: =IFERROR(AG12+AH12,"") -> 25607.606 | AJ12: =IFERROR(AF12/AI12*100,NA()) -> 46.428018 | AK12: =IFERROR(AG12/AI12*100,NA()) -> 60.397481
A13: 1860 | B13: 1582.327 | C13: 2419.76 | D13: 1497.178 | E13: 1470.527 | F13: 1806.778 | G13: 619.519 | H13: 1582.327 | I13: 2419.761 | J13: 1497.178 | K13: 1362.587 | L13: 1713.343 | M13: 1027.021 | N13: =IFERROR(SUM($B$3:$B13),"") -> 16415.936 | O13: =IFERROR(SUM($C$3:$C13),"") -> 25753.232 | P13: =IFERROR(SUM($D$3:$D13),"") -> 18618.123 | Q13: =IFERROR(O13+P13,"") -> 44371.355 | R13: =IFERROR(N13/Q13*100,NA()) -> 36.996698 | S13: =IFERROR(O13/Q13*100,NA()) -> 58.04022 | T13: =IFERROR(SUM($E$3:$E13),"") -> 13607.384 | U13: =IFERROR(SUM($F$3:$F13),"") -> 17207.671 | V13: =IFERROR(SUM($G$3:$G13),"") -> 7553.663 | W13: =IFERROR(U13+V13,"") -> 24761.334 | X13: =IFERROR(T13/W13*100,NA()) -> 54.954164 | Y13: =IFERROR(U13/W13*100,NA()) -> 69.494119 | Z13: =IFERROR(SUM($H$3:$H13),"") -> 16415.935 | AA13: =IFERROR(SUM($I$3:$I13),"") -> 25753.233 | AB13: =IFERROR(SUM($J$3:$J13),"") -> 18618.123 | AC13: =IFERROR(AA13+AB13,"") -> 44371.356 | AD13: =IFERROR(Z13/AC13*100,NA()) -> 36.996694 | AE13: =IFERROR(AA13/AC13*100,NA()) -> 58.040221 | AF13: =IFERROR(SUM($K$3:$K13),"") -> 13251.691 | AG13: =IFERROR(SUM($L$3:$L13),"") -> 17179.692 | AH13: =IFERROR(SUM($M$3:$M13),"") -> 11168.278 | AI13: =IFERROR(AG13+AH13,"") -> 28347.97 | AJ13: =IFERROR(AF13/AI13*100,NA()) -> 46.746525 | AK13: =IFERROR(AG13/AI13*100,NA()) -> 60.6029
A14: 1861 | B14: 1522.367 | C14: 2358.99 | D14: 1386.92 | E14: 1506.66 | F14: 1858.106 | G14: 625.604 | H14: 1522.367 | I14: 2358.99 | J14: 1386.92 | K14: 1322.922 | L14: 1678 | M14: 989.235 | N14: =IFERROR(SUM($B$3:$B14),"") -> 17938.303 | O14: =IFERROR(SUM($C$3:$C14),"") -> 28112.222 | P14: =IFERROR(SUM($D$3:$D14),"") -> 20005.043 | Q14: =IFERROR(O14+P14,"") -> 48117.265 | R14: =IFERROR(N14/Q14*100,NA()) -> 37.280388 | S14: =IFERROR(O14/Q14*100,NA()) -> 58.424397 | T14: =IFERROR(SUM($E$3:$E14),"") -> 15114.044 | U14: =IFERROR(SUM($F$3:$F14),"") -> 19065.777 | V14: =IFERROR(SUM($G$3:$G14),"") -> 8179.267 | W14: =IFERROR(U14+V14,"") -> 27245.044 | X14: =IFERROR(T14/W14*100,NA()) -> 55.474471 | Y14: =IFERROR(U14/W14*100,NA()) -> 69.978881 | Z14: =IFERROR(SUM($H$3:$H14),"") -> 17938.302 | AA14: =IFERROR(SUM($I$3:$I14),"") -> 28112.223 | AB14: =IFERROR(SUM($J$3:$J14),"") -> 20005.043 | AC14: =IFERROR(AA14+AB14,"") -> 48117.266 | AD14: =IFERROR(Z14/AC14*100,NA()) -> 37.280385 | AE14: =IFERROR(AA14/AC14*100,NA()) -> 58.424398 | AF14: =IFERROR(SUM($K$3:$K14),"") -> 14574.613 | AG14: =IFERROR(SUM($L$3:$L14),"") -> 18857.692 | AH14: =IFERROR(SUM($M$3:$M14),"") -> 12157.513 | AI14: =IFERROR(AG14+AH14,"") -> 31015.205 | AJ14: =IFERROR(AF14/AI14*100,NA()) -> 46.991832 | AK14: =IFERROR(AG14/AI14*100,NA()) -> 60.801442
... A177: 2024 | B177: 9328.73 | C177: 12711.999 | D177: 29835.874 | E177: 8641.151 | F177: 11449.105 | G177: 24074.684 | H177: 9328.73 | I177: 12711.999 | J177: 29835.874 | K177: 9075.401 | L177: 12263.895 | M177: 29356.026 | N177: =IFERROR(SUM($B$3:$B177),"") -> 1078015.4 | O177: =IFERROR(SUM($C$3:$C177),"") -> 1463023.9 | P177: =IFERROR(SUM($D$3:$D177),"") -> 1393816.3 | Q177: =IFERROR(O177+P177,"") -> 2856840.2 | R177: =IFERROR(N177/Q177*100,NA()) -> 37.734536 | S177: =IFERROR(O177/Q177*100,NA()) -> 51.211261 | T177: =IFERROR(SUM($E$3:$E177),"") -> 951442.33 | U177: =IFERROR(SUM($F$3:$F177),"") -> 1207192.1 | V177: =IFERROR(SUM($G$3:$G177),"") -> 1042057.3 | W177: =IFERROR(U177+V177,"") -> 2249249.4 | X177: =IFERROR(T177/W177*100,NA()) -> 42.300436 | Y177: =IFERROR(U177/W177*100,NA()) -> 53.670886 | Z177: =IFERROR(SUM($H$3:$H177),"") -> 1078015.4 | AA177: =IFERROR(SUM($I$3:$I177),"") -> 1463023.9 | AB177: =IFERROR(SUM($J$3:$J177),"") -> 1393332.5 | AC177: =IFERROR(AA177+AB177,"") -> 2856356.4 | AD177: =IFERROR(Z177/AC177*100,NA()) -> 37.740928 | AE177: =IFERROR(AA177/AC177*100,NA()) -> 51.219936 | AF177: =IFERROR(SUM($K$3:$K177),"") -> 1034414.7 | AG177: =IFERROR(SUM($L$3:$L177),"") -> 1338460.6 | AH177: =IFERROR(SUM($M$3:$M177),"") -> 1235047.9 | AI177: =IFERROR(AG177+AH177,"") -> 2573508.5 | AJ177: =IFERROR(AF177/AI177*100,NA()) -> 40.194727 | AK177: =IFERROR(AG177/AI177*100,NA()) -> 52.009177

Sheet CO2 incl LULUCF

Sheet data_co2_incLUC
A1: Cumulative CO2 emissions including from LULUCF since 1850, different end points
A2: Year | B2: AII_Min | C2: AII_Max | D2: AI_Min | E2: AI_Max | F2: Pure_AII | G2: Overlap | H2: AI_Gap | I2: pct_annex2_OWID | J2: pct_annex2_PRIMAP | K2: pct_annex2_GCP_BLUE | L2: pct_annex2_GCP_OSCAR | M2: pct_annex1_OWID | N2: pct_annex1_PRIMAP | O2: pct_annex1_GCP_BLUE | P2: pct_annex1_GCP_OSCAR | Q2: Pure_AI | R2: Annex II GMST | S2: Annex I GMST
A3: =vals_co2_incLUC!$A3 -> 1850 | B3: =IFERROR(_xlfn.AGGREGATE(5,6,I3:L3),"") -> 35.536122 | C3: =IFERROR(_xlfn.AGGREGATE(4,6,I3:L3),"") -> 44.923011 | D3: =IFERROR(_xlfn.AGGREGATE(5,6,M3:P3),"") -> 57.666672 | E3: =IFERROR(_xlfn.AGGREGATE(4,6,M3:P3),"") -> 59.67117 | F3: =IFERROR(MIN(C3,D3)-B3,"") -> 9.3868885 | G3: =IFERROR(MAX(0,C3-D3),"") -> 0 | H3: =IFERROR(MAX(0,D3-C3),"") -> 12.743661 | I3: =vals_co2_incLUC!$R3 -> 35.536122 | J3: =vals_co2_incLUC!$X3 -> 43.831164 | K3: =vals_co2_incLUC!$AD3 -> 35.536122 | L3: =vals_co2_incLUC!$AJ3 -> 44.923011 | M3: =vals_co2_incLUC!$S3 -> 57.666672 | N3: =vals_co2_incLUC!$Y3 -> 59.535107 | O3: =vals_co2_incLUC!$AE3 -> 57.666672 | P3: =vals_co2_incLUC!$AK3 -> 59.67117 | Q3: =IFERROR(MAX(0,$E3-MAX($C3,$D3)),"") -> 2.0044981
A4: =vals_co2_incLUC!$A4 -> 1851 | B4: =IFERROR(_xlfn.AGGREGATE(5,6,I4:L4),"") -> 35.578174 | C4: =IFERROR(_xlfn.AGGREGATE(4,6,I4:L4),"") -> 45.060611 | D4: =IFERROR(_xlfn.AGGREGATE(5,6,M4:P4),"") -> 57.336731 | E4: =IFERROR(_xlfn.AGGREGATE(4,6,M4:P4),"") -> 60.118921 | F4: =IFERROR(MIN(C4,D4)-B4,"") -> 9.4824378 | G4: =IFERROR(MAX(0,C4-D4),"") -> 0 | H4: =IFERROR(MAX(0,D4-C4),"") -> 12.276119 | I4: =vals_co2_incLUC!$R4 -> 35.578174 | J4: =vals_co2_incLUC!$X4 -> 44.302088 | K4: =vals_co2_incLUC!$AD4 -> 35.578174 | L4: =vals_co2_incLUC!$AJ4 -> 45.060611 | M4: =vals_co2_incLUC!$S4 -> 57.336731 | N4: =vals_co2_incLUC!$Y4 -> 60.118921 | O4: =vals_co2_incLUC!$AE4 -> 57.336731 | P4: =vals_co2_incLUC!$AK4 -> 59.43739 | Q4: =IFERROR(MAX(0,$E4-MAX($C4,$D4)),"") -> 2.7821901 | R4: 39.363 | S4: 58.487
A5: =vals_co2_incLUC!$A5 -> 1852 | B5: =IFERROR(_xlfn.AGGREGATE(5,6,I5:L5),"") -> 35.469587 | C5: =IFERROR(_xlfn.AGGREGATE(4,6,I5:L5),"") -> 46.878074 | D5: =IFERROR(_xlfn.AGGREGATE(5,6,M5:P5),"") -> 57.215137 | E5: =IFERROR(_xlfn.AGGREGATE(4,6,M5:P5),"") -> 62.220609 | F5: =IFERROR(MIN(C5,D5)-B5,"") -> 11.408488 | G5: =IFERROR(MAX(0,C5-D5),"") -> 0 | H5: =IFERROR(MAX(0,D5-C5),"") -> 10.337062 | I5: =vals_co2_incLUC!$R5 -> 35.469587 | J5: =vals_co2_incLUC!$X5 -> 46.878074 | K5: =vals_co2_incLUC!$AD5 -> 35.469587 | L5: =vals_co2_incLUC!$AJ5 -> 44.886605 | M5: =vals_co2_incLUC!$S5 -> 57.215137 | N5: =vals_co2_incLUC!$Y5 -> 62.220609 | O5: =vals_co2_incLUC!$AE5 -> 57.215137 | P5: =vals_co2_incLUC!$AK5 -> 59.434788 | Q5: =IFERROR(MAX(0,$E5-MAX($C5,$D5)),"") -> 5.0054724 | R5: 39.115 | S5: 58.518
A6: =vals_co2_incLUC!$A6 -> 1853 | B6: =IFERROR(_xlfn.AGGREGATE(5,6,I6:L6),"") -> 35.633305 | C6: =IFERROR(_xlfn.AGGREGATE(4,6,I6:L6),"") -> 48.539578 | D6: =IFERROR(_xlfn.AGGREGATE(5,6,M6:P6),"") -> 57.136671 | E6: =IFERROR(_xlfn.AGGREGATE(4,6,M6:P6),"") -> 63.665027 | F6: =IFERROR(MIN(C6,D6)-B6,"") -> 12.906273 | G6: =IFERROR(MAX(0,C6-D6),"") -> 0 | H6: =IFERROR(MAX(0,D6-C6),"") -> 8.597093 | I6: =vals_co2_incLUC!$R6 -> 35.633305 | J6: =vals_co2_incLUC!$X6 -> 48.539578 | K6: =vals_co2_incLUC!$AD6 -> 35.633305 | L6: =vals_co2_incLUC!$AJ6 -> 45.186174 | M6: =vals_co2_incLUC!$S6 -> 57.136671 | N6: =vals_co2_incLUC!$Y6 -> 63.665027 | O6: =vals_co2_incLUC!$AE6 -> 57.136671 | P6: =vals_co2_incLUC!$AK6 -> 59.489614 | Q6: =IFERROR(MAX(0,$E6-MAX($C6,$D6)),"") -> 6.5283554 | R6: 39.42 | S6: 58.571
A7: =vals_co2_incLUC!$A7 -> 1854 | B7: =IFERROR(_xlfn.AGGREGATE(5,6,I7:L7),"") -> 35.907146 | C7: =IFERROR(_xlfn.AGGREGATE(4,6,I7:L7),"") -> 49.985398 | D7: =IFERROR(_xlfn.AGGREGATE(5,6,M7:P7),"") -> 57.309878 | E7: =IFERROR(_xlfn.AGGREGATE(4,6,M7:P7),"") -> 64.955844 | F7: =IFERROR(MIN(C7,D7)-B7,"") -> 14.078252 | G7: =IFERROR(MAX(0,C7-D7),"") -> 0 | H7: =IFERROR(MAX(0,D7-C7),"") -> 7.3244796 | I7: =vals_co2_incLUC!$R7 -> 35.907146 | J7: =vals_co2_incLUC!$X7 -> 49.985398 | K7: =vals_co2_incLUC!$AD7 -> 35.907146 | L7: =vals_co2_incLUC!$AJ7 -> 45.520477 | M7: =vals_co2_incLUC!$S7 -> 57.309878 | N7: =vals_co2_incLUC!$Y7 -> 64.955844 | O7: =vals_co2_incLUC!$AE7 -> 57.309878 | P7: =vals_co2_incLUC!$AK7 -> 59.75877 | Q7: =IFERROR(MAX(0,$E7-MAX($C7,$D7)),"") -> 7.6459662 | R7: 39.814 | S7: 58.922
A8: =vals_co2_incLUC!$A8 -> 1855 | B8: =IFERROR(_xlfn.AGGREGATE(5,6,I8:L8),"") -> 36.057853 | C8: =IFERROR(_xlfn.AGGREGATE(4,6,I8:L8),"") -> 51.188605 | D8: =IFERROR(_xlfn.AGGREGATE(5,6,M8:P8),"") -> 57.350301 | E8: =IFERROR(_xlfn.AGGREGATE(4,6,M8:P8),"") -> 66.079756 | F8: =IFERROR(MIN(C8,D8)-B8,"") -> 15.130752 | G8: =IFERROR(MAX(0,C8-D8),"") -> 0 | H8: =IFERROR(MAX(0,D8-C8),"") -> 6.1616963 | I8: =vals_co2_incLUC!$R8 -> 36.057853 | J8: =vals_co2_incLUC!$X8 -> 51.188605 | K8: =vals_co2_incLUC!$AD8 -> 36.057853 | L8: =vals_co2_incLUC!$AJ8 -> 45.736641 | M8: =vals_co2_incLUC!$S8 -> 57.350301 | N8: =vals_co2_incLUC!$Y8 -> 66.079756 | O8: =vals_co2_incLUC!$AE8 -> 57.350301 | P8: =vals_co2_incLUC!$AK8 -> 59.909754 | Q8: =IFERROR(MAX(0,$E8-MAX($C8,$D8)),"") -> 8.7294545 | R8: 40 | S8: 59.04
